Workbook
Name _: [1]도면자료제출일정!#REF!
Name __: [1]도면자료제출일정!#REF!
Name ____________sn0001: [2]도!#REF!
Name ___________A70000: '[3]4-3 보온 기본물량집계'!#REF!
Name ___________A70001: '[3]4-3 보온 기본물량집계'!#REF!
Name ___________o12111: '[4]#REF'!#REF!
Name ___________sn0001: [2]도!#REF!
Name __________A70000: '[3]4-3 보온 기본물량집계'!#REF!
Name __________A70001: '[3]4-3 보온 기본물량집계'!#REF!
Name __________o12111: '[4]#REF'!#REF!
Name __________sn0001: [2]도!#REF!
Name _________A70000: '[3]4-3 보온 기본물량집계'!#REF!
Name _________A70001: '[3]4-3 보온 기본물량집계'!#REF!
Name _________o12111: '[4]#REF'!#REF!
Name _________sn0001: [2]도!#REF!
Name ________A70000: '[3]4-3 보온 기본물량집계'!#REF!
Name ________A70001: '[3]4-3 보온 기본물량집계'!#REF!
Name ________LPB1: [5]부하계산서!#REF!
Name ________LPK1: [5]부하계산서!#REF!
Name ________LU1: '[6]부하(성남)'!#REF!
Name ________LU2: '[6]부하(성남)'!#REF!
Name ________LV01: '[6]부하(성남)'!#REF!
Name ________o12111: '[4]#REF'!#REF!
Name ________sn0001: [7]도!#REF!
Name ________UP1: [5]부하계산서!#REF!
Name ________UP2: [5]부하계산서!#REF!
Name _______A70000: '[3]4-3 보온 기본물량집계'!#REF!
Name _______A70001: '[3]4-3 보온 기본물량집계'!#REF!
Name _______NEW1: ROUND([0]!_______NEW1*0.0254,3)
Name _______o12111: '[4]#REF'!#REF!
Name _______sn0001: [2]도!#REF!
Name _______st1: "Group 41"
Name ______A1: BlankMacro1
Name ______A3: BlankMacro1
Name ______A70000: '[8]4-3 보온 기본물량집계'!#REF!
Name ______A70001: '[3]4-3 보온 기본물량집계'!#REF!
Name ______D1: '[9]BEND LOSS'!#REF!
Name ______D2: '[10]BEND LOSS'!#REF!
Name ______LPB1: [5]부하계산서!#REF!
Name ______LPK1: [5]부하계산서!#REF!
Name ______LU1: '[6]부하(성남)'!#REF!
Name ______LU2: '[6]부하(성남)'!#REF!
Name ______LV01: '[6]부하(성남)'!#REF!
Name ______NEW1: ROUND([0]!______NEW1*0.0254,3)
Name ______o12111: '[4]#REF'!#REF!
Name ______Q1: [11]Sheet5!#REF!
Name ______sn0001: [7]도!#REF!
Name ______st1: "Group 41"
Name ______t2: '[10]BEND LOSS'!#REF!
Name ______UP1: [5]부하계산서!#REF!
Name ______UP2: [5]부하계산서!#REF!
Name ______W2: '[10]BEND LOSS'!#REF!
Name ______W4: '[9]BEND LOSS'!#REF!
Name _____A1: BlankMacro1
Name _____A3: BlankMacro1
Name _____A70000: '[12]4-3 보온 기본물량집계'!#REF!
Name _____A70001: '[12]4-3 보온 기본물량집계'!#REF!
Name _____D1: '[9]BEND LOSS'!#REF!
Name _____D2: '[10]BEND LOSS'!#REF!
Name _____LPB1: [5]부하계산서!#REF!

Sheet VXXXXX

Sheet 제경비(설치비)내역서
B1: '26. 01. 01.부 시행 | Q1: 투자부서에서는 파란색 점선영역과 순공사비내역서 노란색 영역을 기입하여 구매부서로 구매의뢰시 첨부 (File Naming Rule : YYMMDD_부서명_제경비내역서 초안_투자명)
Q2: 산업안전보건관리비를 산출하여 구매부서로 구매의뢰시 첨부 (File Naming Rule : YYMMDD_부서명_제경비내역서 초안_투자명)
B3: ○ 계약건명 : | E3: (포항)3소결 청정 탈황설비 Conveyor류 성능복원 | Q3: 공급사에서 노란색셀에 Data를 제경비요율표 및 가이드라인 확인 후 입력
B4: 제 경 비(설치비) 내 역 서 | P4: 1. 산업안전보건관리비 계산산식 : 대상액 구분 가능여부와 현장 제작설비 여부에 따른 구분, 해당부분에만 숫자 1입력
B5: 구 분 | G5: 계산근거 | N5: 공사비 | P5: 2. 공사기간 : 해당 공사기간입력
B6: 사 업 명 : | P6: 3. 공사구분 : 해당 공사구분에만 숫자 1 입력 (ex) 기계,전기, 토목, 건축 등 복합공종인 경우 주공종 1개에만 숫자 1입력)
B7: 1. 도급 재료비 | P7: 4. 요율 : 제경비 요율표를 참조하여 해당 건설하도급대금지급보증비 요율과 건설기계대여금 지급보증비 요율 합해 %를 제외한 숫자 셋째짜리까지 기입
B8: 재료비 계 | N8: ='기계공사비 내역서 '!L26 -> 155509820 | P8: 5. 환경보전비 0.4% 고정(단, 전기,정보통신,소방공사는 0 입력)
B9: 2. 노무비 | V9: [간접노무비 요율표] | AD9: [간접노무비 요율표]
C10: 가) 직접노무비 | N10: ='기계공사비 내역서 '!L56 -> 3.8232057e+08 | P10: [산업안전보건관리비 계산산식] | V10: 금액/개월 | Y10: 토목,건축 | AA10: 기계,전기 | AD10: 토목,건축 | AH10: 기계,전기
C11: 나) 간접노무비 | G11: (직접노무비) × 간접노무비율 | P11: 대상액 구분가능 or 완제품설비 | Q11: 대상액 구분불가 or 현장제작설비 | Y11: 금액 | Z11: 기간 | AA11: 금액 | AB11: 기간 | AD11: 금액 | AE11: 요율 | AF11: 기간 | AG11: 요율 | AH11: 금액 | AI11: 요율 | AJ11: 기간 | AK11: 요율 | AM11: [건설기계대여지급보증비 요율표]
G12: =N10 -> 3.8232057e+08 | J12: × | K12: =Q35 -> 10.5 | L12: = | N12: =INT((G12)*K12/100) -> 40143660 | P12: 1 | V12: 5억원미만 / 6개월미만 | Y12: 0.15 | Z12: 0.13 | AA12: 0.12 | AB12: 0.1 | AD12: 0 | AE12: 15 | AF12: 0 | AG12: 13 | AH12: 0 | AI12: 12 | AJ12: 0 | AK12: 10 | AM12: 1. 발주자와 종합건설업자가 계약시 적용요율
P13: [공사기간] | V13: 5억원~20억원미만 / 6~18개월 | Y13: 0.14 | Z13: 0.14 | AA13: 0.11 | AB13: 0.11 | AD13: 500000000 | AE13: 14 | AF13: 6 | AG13: 14 | AH13: 500000000 | AI13: 11 | AJ13: 6 | AK13: 11 | AM13: 토목공사(토목·건축공사 포함) | AU13: 0.004
B14: 노무비 계 | N14: =SUM(N10,N12) -> 4.2246423e+08 | P14: 2 | Q14: 개월 | V14: 20억원이상 / 18개월이상 | Y14: 0.13 | Z14: 0.15 | AA14: 0.1 | AB14: 0.12 | AD14: 2000000000 | AE14: 13 | AF14: 18 | AG14: 15 | AH14: 2000000000 | AI14: 10 | AJ14: 18 | AK14: 12 | AM14: 건축공사 | AU14: 0.0007
B15: 3. 경비 | P15: [투자구분] | V15: [고용보험료 요율표] | AD15: [고용보험료 요율표] | AE15: 토건 | AG15: 건축 | AM15: 산업·환경설비공사 | AU15: 0.0016
B16: 경비 | N16: ='기계공사비 내역서 '!L69 -> 6.5086407e+08 | P16: 프로젝트성 | Q16: 정비성 | V16: 등 급 별 (추정금액) (단위 : 미만 ~ 이상) | AA16: 2024년도 | AD16: 금액 | AE16: 요율 | AF16: 등급 | AG16: 금액 | AH16: 요율 | AI16: 등급 | AM16: 조경공사 | AU16: 0.0018
C17: 가) 보험료 (산재보험) | G17: (직접노무비 ＋ 간접노무비) × 산재보험율 | Q17: 1 | V17: 1 등급 : | W17: 토목 1400억이상 | Y17: 건축 1200억 이상 | AA17: 0.0157 | AD17: 0 | AE17: 1.01 | AF17: 7 | AG17: 0 | AH17: 1.01 | AI17: 7 | AM17: 2. 발주자와 전문건설업자가 계약시 적용요율
G18: =N10 -> 3.8232057e+08 | H18: ＋ | I18: =N12 -> 40143660 | J18: × | K18: =Q36 -> 3.56 | L18: = | N18: =INT((G18+I18)*K18/100) -> 15039726 | P18: [공사구분 : 공사비] | V18: 2 등급 : | W18: 토목 1400억~900억 | Y18: 건축 1200억~900억 | AA18: 0.013 | AD18: 14000000000 | AE18: 1.02 | AF18: 6 | AG18: 13000000000 | AH18: 1.02 | AI18: 6 | AM18: A 그룹 : | AN18: 준설공사, 포장공사, 토공사, 비계·구조물해체공사 | AU18: 0.0068
F19: (고용보험) | G19: (직접노무비 ＋ 간접노무비) × 고용보험율 | P19: 토목 | Q19: 건축 | S19: 기계 | T19: 전기 | V19: 3 등급 : | W19: 토목 900억~570억 | Y19: 건축 800억~520억 | AA19: 0.0113 | AD19: 22000000000 | AE19: 1.03 | AF19: 5 | AG19: 21000000000 | AH19: 1.03 | AI19: 5 | AM19: B 그룹 : | AN19: 상·하수도설비공사, 수중공사, 보링·그라우팅공사 | AU19: 0.0051
G20: =N10 -> 3.8232057e+08 | H20: ＋ | I20: =N12 -> 40143660 | J20: × | K20: =Q37 -> 1.01 | L20: = | N20: =INT((G20+I20)*K20/100) -> 4266888 | S20: 1 | V20: 4 등급 : | W20: 토목 570억~370억 | Y20: 건축 520억~340억 | AA20: 0.01063 | AD20: 37000000000 | AE20: 1.06 | AF20: 4 | AG20: 34000000000 | AH20: 1.06 | AI20: 4 | AM20: C 그룹 : | AN20: 석공사, 시설물유지관리, 철근·콘크리트공사, 가스시설공사(1종) | AU20: 0.0032
F21: (국민연금) | G21: (직접노무비) × 국민연금율 | P21: [공사구분 : 공사비+설비비] | V21: 5 등급 : | W21: 토목 370억~220억 | Y21: 건축 340억~210억 | AA21: 0.0103 | AD21: 57000000000 | AE21: 1.13 | AF21: 3 | AG21: 52000000000 | AH21: 1.13 | AI21: 3 | AM21: D 그룹 : | AN21: 조경시설물설치, 조경식재, 도장공사, 철도궤도, 철강재설치공사 | AU21: 0.0016
G22: =N10 -> 3.8232057e+08 | J22: × | K22: =Q38 -> 4.75 | L22: = | N22: =INT((G22)*K22/100) -> 18160227 | P22: 토목 | Q22: 건축 | S22: 기계 | T22: 전기 | V22: 6 등급 : | W22: 토목 220억~140억 | Y22: 건축 210억~130억 | AA22: 0.0102 | AD22: 90000000000 | AE22: 1.3 | AF22: 2 | AG22: 80000000000 | AH22: 1.3 | AI22: 2 | AM22: E 그룹 : | AN22: A그룹～D그룹 이외의 공사 | AU22: 0.001
F23: (건강보험) | G23: (직접노무비) × 건강보험율 | S23: 1 | V23: 7 등급 : | W23: 토목 140억~ 7등급 미만 | Y23: 건축 130억~ 7등급 미만 | AA23: 0.0101 | AD23: 140000000000 | AE23: 1.57 | AF23: 1 | AG23: 120000000000 | AH23: 1.57 | AI23: 1
G24: =N10 -> 3.8232057e+08 | J24: × | K24: =Q39 -> 3.595 | L24: = | N24: =INT((G24)*K24/100) -> 13744424 | P24: [산업안전보건관리비 요율 구분] | AD24: [산업안전보건관리비 요율표] | AM24: [건설 하도급대금지급보증비 요율표]
F25: (요양보험) | G25: (국민건강보험료) × 노인장기요양보험율 | P25: 플랜트 공사 | Q25: 플랜트 外 공사 | V25: [산업안전보건관리비 요율표] | AD25: 건축공사 | AF25: 토목공사 | AM25: 공사규모 (추정가격) | AU25: 2018년도
G26: =N24 -> 13744424 | J26: × | K26: =Q40 -> 13.14 | L26: = | N26: =INT((G26)*K26/100) -> 1806017 | Q26: 1 | V26: 구분 | X26: 건축공사 요율/기초액 | Z26: 토목공사 요율/기초액 | AD26: 금액 | AE26: 요율 | AF26: 금액 | AG26: 요율 | AM26: 50억 미만 | AU26: 0.00081
P27: [공종별 추정비율 : 공급사에서 필히 현장조사 후 입찰 준비하시길 바랍니다] | V27: 2천만원 미만 | X27: 3.11 | Z27: 3.15 | AD27: 0 | AE27: 3.11 | AF27: 0 | AG27: 3.15 | AM27: 50억원～100억원 미만 | AU27: 0.0008
C28: 나) 산업안전보건관리비 | G28: =IF(P12=AE66,AF66,AF67) -> (도급재료비 ＋ 발주자재료비 ＋ 직접노무비) × 산업안전보건관리비율 ＋ 기초액 | N28: =IF(P12=AE70,AF70,AF71) -> (설비비 포함) | P28: 기계 : 10%, 전기 : 90% | V28: 2천만원~5억원 미만 | X28: 3.11 | Z28: 3.15 | AD28: 20000000 | AE28: 3.11 | AF28: 20000000 | AG28: 3.15 | AM28: 100억원～300억원 미만 | AU28: 0.00075
G29: =(N8+'[383]순공사비 내역서 '!L176)*P12+Q53*Q12*0.7 -> 156509820 | H29: ＋ | I29: =N10*P12 -> 3.8232057e+08 | J29: × | K29: =((IF((G29+I29)="","",VLOOKUP((G29+I29),AD27:AE31,2,1))*Q26+IF((G29+I29)="","",VLOOKUP((G29+I29),AF27:AG31,2,1))*P26)) -> 2.28 | L29: ＋ | M29: =SUMIF(Z27:Z31,K29,AA27:AA31)+SUMIF(X27:X31,K29,Y27:Y31)+SUMIF(AB27:AB31,K29,AC27:AC31) -> 4325000 | N29: =INT((G29+I29)*K29/100+M29) -> 16610332 | P29: [필수면허] | V29: 5억원~50억원 미만 | W29: G2(1.86%+5,349 천원) | X29: 2.28 | Y29: 4325000 | Z29: 2.53 | AA29: 3300000 | AD29: 500000000 | AE29: 2.28 | AF29: 500000000 | AG29: 2.53 | AM29: 300억원 이상 (최저가낙찰 대상공사) | AR29: - 토목및산업설비 | AU29: 0.00071
G30: =IF(P12=AE68,AF68,AF69) -> ((도급재료비 ＋ 직접노무비) × 산업안전보건관리비율 ＋ 기초액) x 1.2 | N30: =IF(P12=AE72,AF72,AF73) -> (설비비 제외) | P30: 기계공사, 전기공사 면허 | V30: 50억원 이상 | W30: G3(1.97%) | X30: 2.37 | Z30: 2.6 | AD30: 5000000000 | AE30: 2.37 | AF30: 5000000000 | AG30: 2.6 | AR30: - 건축 | AU30: 0.00068
G31: =N8*P12+Q53*Q12*0.7 -> 155509820 | H31: ＋ | I31: =N10*P12 -> 3.8232057e+08 | J31: × | K31: =((IF((G31+I31)="","",VLOOKUP((G31+I31),AF27:AG31,2,1))*P26+IF((G31+I31)="","",VLOOKUP((G31+I31),AD27:AE31,2,1))*Q26)) -> 2.28 | L31: ＋ | M31: =SUMIF(Z27:Z31,K31,AA27:AA31)+SUMIF(X27:X31,K31,Y27:Y31)+SUMIF(AB27:AB31,K31,AC27:AC31) -> 4325000 | N31: =INT((G31+I31)*K31/100+M31)*1.2 -> 19905038 | V31: 800억원 이상 | W31: G3(1.97%) | X31: 2.64 | Z31: 2.73 | AD31: 80000000000 | AE31: 2.64 | AF31: 80000000000 | AG31: 2.73 | AM31: 턴키(대안)공사 | AU31: 0.00084
B32: 산업안전보건관리비 적용 | N32: 20907508
P33: [요율]
C34: 다) 법정경비(퇴직공제비) | G34: (직접노무비) × 퇴직공제비율 | P34: 구분 | Q34: 요율 | S34: 비고
G35: =N10 -> 3.8232057e+08 | J35: × | K35: =Q42 -> 2.3 | L35: = | N35: =INT((G35)*K35/100) -> 8793373 | P35: 간접노무비 | Q35: =(IF((N8+N10+N16)="","",VLOOKUP((N8+N10+N16),AD12:AE14,2,1))*P20+IF((N8+N10+N16)="","",VLOOKUP((N8+N10+N16),AD12:AE14,2,1))*Q20+IF((N8+N10+N16)="","",VLOOKUP((N8+N10+N16),AH12:AI14,2,1))*S20+IF((N8+N10+N16)="","",VLOOKUP((N8+N10+N16),AH12:AI14,2,1))*T20+IF((P14)="","",VLOOKUP((P14),AF12:AG14,2,1))*P20+IF((P14)="","",VLOOKUP((P14),AF12:AG14,2,1))*Q20+IF((P14)="","",VLOOKUP((P14),AJ12:AK14,2,1))*S20+IF((P14)="","",VLOOKUP((P14),AJ12:AK14,2,1))*T20)/2 -> 10.5 | R35: %
P36: 산재보험 | Q36: 3.56 | R36: % | S36: 법정요율 | AF36: 설비비포함 | AG36: =IF(N32=N29,1,0) -> 0
C37: 라) 건설기계대여지급보증비 | G37: (도급재료비 ＋ 직접노무비 ＋ 산출경비 ) × 지급보증비율 | P37: 고용보험 | Q37: =IF((N8+N14+N16)="","",VLOOKUP((N8+N14+N16),AD17:AE23,2,1)) -> 1.01 | R37: % | S37: 법정요율 | AF37: 1.2배 | AG37: =IF(N32=N31,1,0) -> 0
G38: =N8 -> 155509820 | H38: ＋ | I38: =N10 -> 3.8232057e+08 | J38: ＋ | K38: =N16 -> 6.5086407e+08 | L38: × | M38: =Q43 -> 0.11 | N38: =INT((G38+I38+K38)*M38/100) -> 1307563 | P38: 국민연금 | Q38: 4.75 | R38: % | S38: 법정요율
P39: 건강보험 | Q39: 3.595 | R39: % | S39: 법정요율
C40: 마) 환경보전비 | G40: (도급재료비 ＋ 직접노무비 ＋ 산출경비 ) × 지급보증비율 | P40: 요양보험 | Q40: 13.14 | R40: % | S40: 법정요율 | AF40: =Q58 -> 0 | AG40: =IF(AF40>=80000000000,1,0) -> 0
...

Sheet 기계공사비 내역서 
B1: ○ 계약건명 : | E1: =#REF! -> #REF!
B2: ○ 시공사 :
B3: 순 공 사 비 내 역 서
B4: 구 분 | G4: 품명 | H4: 세부규격 | I4: 수량 | J4: 단위 | K4: 단 가 | L4: 금 액 | M4: 비 고
B5: 사 업 명 :
B6: 1. 도급 재료비
L7: =INT(J7*K7) -> 0
G8: 기계공사 | I8: 1 | J8: 식 | K8: 1.5550982e+08 | L8: =INT(I8*K8) -> 155509820
L9: =INT(I9*K9) -> 0
L10: =INT(I10*K10) -> 0 | U10: 2C 4mm² | V10: 16
L11: =INT(I11*K11) -> 0 | U11: 3C 2.5mm² | V11: 40
L12: =INT(I12*K12) -> 0
L13: =INT(I13*K13) -> 0
L14: =INT(I14*K14) -> 0
L15: =INT(I15*K15) -> 0
L16: =INT(I16*K16) -> 0
L17: =INT(I17*K17) -> 0
L18: =INT(I18*K18) -> 0
L20: =J20*K20 -> 0
L21: =J21*K21 -> 0
L22: =J22*K22 -> 0
L23: =J23*K23 -> 0
B26: 재료비 계 | L26: =SUM(L7:L25) -> 155509820
B27: 2. 직접노무비
G28: 기계공사 | I28: 1 | J28: 식 | K28: 3.8232057e+08 | L28: =K28*I28 -> 3.8232057e+08
L30: =K30*I30 -> 0
L31: =K31*I31 -> 0
L32: =K32*I32 -> 0
L34: =K34*I34 -> 0
L35: =K35*I35 -> 0
L36: =K36*I36 -> 0
L37: =J37*K37 -> 0
L38: =J38*K38 -> 0
L39: =J39*K39 -> 0
L40: =J40*K40 -> 0
L41: =J41*K41 -> 0
L42: =J42*K42 -> 0
L43: =J43*K43 -> 0
L44: =J44*K44 -> 0
L45: =J45*K45 -> 0
...

Sheet 제경비(철거비)내역서
B1: '26. 01. 01.부 시행 | Q1: 투자부서에서는 파란색 점선영역과 순공사비내역서 노란색 영역을 기입하여 구매부서로 구매의뢰시 첨부 (File Naming Rule : YYMMDD_부서명_제경비내역서 초안_투자명)
Q2: 산업안전보건관리비를 산출하여 구매부서로 구매의뢰시 첨부 (File Naming Rule : YYMMDD_부서명_제경비내역서 초안_투자명)
B3: ○ 계약건명 : | E3: =#REF! -> #REF! | Q3: 공급사에서 노란색셀에 Data를 제경비요율표 및 가이드라인 확인 후 입력
B4: 제 경 비(설치비) 내 역 서 | P4: 1. 산업안전보건관리비 계산산식 : 대상액 구분 가능여부와 현장 제작설비 여부에 따른 구분, 해당부분에만 숫자 1입력
B5: 구 분 | G5: 계산근거 | N5: 공사비 | P5: 2. 공사기간 : 해당 공사기간입력
B6: 사 업 명 : | P6: 3. 공사구분 : 해당 공사구분에만 숫자 1 입력 (ex) 기계,전기, 토목, 건축 등 복합공종인 경우 주공종 1개에만 숫자 1입력)
B7: 1. 도급 재료비 | P7: 4. 요율 : 제경비 요율표를 참조하여 해당 건설하도급대금지급보증비 요율과 건설기계대여금 지급보증비 요율 합해 %를 제외한 숫자 셋째짜리까지 기입
B8: 재료비 계 | N8: ='전기공사비 내역서'!L13 -> 9443700 | P8: 5. 환경보전비 0.4% 고정(단, 전기,정보통신,소방공사는 0 입력)
B9: 2. 노무비 | V9: [간접노무비 요율표] | AD9: [간접노무비 요율표]
C10: 가) 직접노무비 | N10: ='전기공사비 내역서'!L24 -> 24331500 | P10: [산업안전보건관리비 계산산식] | V10: 금액/개월 | Y10: 토목,건축 | AA10: 기계,전기 | AD10: 토목,건축 | AH10: 기계,전기
C11: 나) 간접노무비 | G11: (직접노무비) × 간접노무비율 | P11: 대상액 구분가능 or 완제품설비 | Q11: 대상액 구분불가 or 현장제작설비 | Y11: 금액 | Z11: 기간 | AA11: 금액 | AB11: 기간 | AD11: 금액 | AE11: 요율 | AF11: 기간 | AG11: 요율 | AH11: 금액 | AI11: 요율 | AJ11: 기간 | AK11: 요율 | AM11: [건설기계대여지급보증비 요율표]
G12: =N10 -> 24331500 | J12: × | K12: =Q35 -> 11 | L12: = | N12: =INT((G12)*K12/100) -> 2676465 | P12: 1 | V12: 5억원미만 / 6개월미만 | Y12: 0.15 | Z12: 0.13 | AA12: 0.12 | AB12: 0.1 | AD12: 0 | AE12: 15 | AF12: 0 | AG12: 13 | AH12: 0 | AI12: 12 | AJ12: 0 | AK12: 10 | AM12: 1. 발주자와 종합건설업자가 계약시 적용요율
P13: [공사기간] | V13: 5억원~20억원미만 / 6~18개월 | Y13: 0.14 | Z13: 0.14 | AA13: 0.11 | AB13: 0.11 | AD13: 500000000 | AE13: 14 | AF13: 6 | AG13: 14 | AH13: 500000000 | AI13: 11 | AJ13: 6 | AK13: 11 | AM13: 토목공사(토목·건축공사 포함) | AU13: 0.004
B14: 노무비 계 | N14: =SUM(N10,N12) -> 27007965 | P14: 1 | Q14: 개월 | V14: 20억원이상 / 18개월이상 | Y14: 0.13 | Z14: 0.15 | AA14: 0.1 | AB14: 0.12 | AD14: 2000000000 | AE14: 13 | AF14: 18 | AG14: 15 | AH14: 2000000000 | AI14: 10 | AJ14: 18 | AK14: 12 | AM14: 건축공사 | AU14: 0.0007
B15: 3. 경비 | P15: [투자구분] | V15: [고용보험료 요율표] | AD15: [고용보험료 요율표] | AE15: 토건 | AG15: 건축 | AM15: 산업·환경설비공사 | AU15: 0.0016
B16: 경비 | N16: ='전기공사비 내역서'!L34 -> 42319539 | P16: 프로젝트성 | Q16: 정비성 | V16: 등 급 별 (추정금액) (단위 : 미만 ~ 이상) | AA16: 2024년도 | AD16: 금액 | AE16: 요율 | AF16: 등급 | AG16: 금액 | AH16: 요율 | AI16: 등급 | AM16: 조경공사 | AU16: 0.0018
C17: 가) 보험료 (산재보험) | G17: (직접노무비 ＋ 간접노무비) × 산재보험율 | Q17: 1 | V17: 1 등급 : | W17: 토목 1400억이상 | Y17: 건축 1200억 이상 | AA17: 0.0157 | AD17: 0 | AE17: 1.01 | AF17: 7 | AG17: 0 | AH17: 1.01 | AI17: 7 | AM17: 2. 발주자와 전문건설업자가 계약시 적용요율
G18: =N10 -> 24331500 | H18: ＋ | I18: =N12 -> 2676465 | J18: × | K18: =Q36 -> 3.56 | L18: = | N18: =INT((G18+I18)*K18/100) -> 961483 | P18: [공사구분 : 공사비] | V18: 2 등급 : | W18: 토목 1400억~900억 | Y18: 건축 1200억~900억 | AA18: 0.013 | AD18: 14000000000 | AE18: 1.02 | AF18: 6 | AG18: 13000000000 | AH18: 1.02 | AI18: 6 | AM18: A 그룹 : | AN18: 준설공사, 포장공사, 토공사, 비계·구조물해체공사 | AU18: 0.0068
F19: (고용보험) | G19: (직접노무비 ＋ 간접노무비) × 고용보험율 | P19: 토목 | Q19: 건축 | S19: 기계 | T19: 전기 | V19: 3 등급 : | W19: 토목 900억~570억 | Y19: 건축 800억~520억 | AA19: 0.0113 | AD19: 22000000000 | AE19: 1.03 | AF19: 5 | AG19: 21000000000 | AH19: 1.03 | AI19: 5 | AM19: B 그룹 : | AN19: 상·하수도설비공사, 수중공사, 보링·그라우팅공사 | AU19: 0.0051
G20: =N10 -> 24331500 | H20: ＋ | I20: =N12 -> 2676465 | J20: × | K20: =Q37 -> 1.01 | L20: = | N20: =INT((G20+I20)*K20/100) -> 272780 | S20: 1 | V20: 4 등급 : | W20: 토목 570억~370억 | Y20: 건축 520억~340억 | AA20: 0.01063 | AD20: 37000000000 | AE20: 1.06 | AF20: 4 | AG20: 34000000000 | AH20: 1.06 | AI20: 4 | AM20: C 그룹 : | AN20: 석공사, 시설물유지관리, 철근·콘크리트공사, 가스시설공사(1종) | AU20: 0.0032
F21: (국민연금) | G21: (직접노무비) × 국민연금율 | P21: [공사구분 : 공사비+설비비] | V21: 5 등급 : | W21: 토목 370억~220억 | Y21: 건축 340억~210억 | AA21: 0.0103 | AD21: 57000000000 | AE21: 1.13 | AF21: 3 | AG21: 52000000000 | AH21: 1.13 | AI21: 3 | AM21: D 그룹 : | AN21: 조경시설물설치, 조경식재, 도장공사, 철도궤도, 철강재설치공사 | AU21: 0.0016
G22: =N10 -> 24331500 | J22: × | K22: =Q38 -> 4.75 | L22: = | N22: =INT((G22)*K22/100) -> 1155746 | P22: 토목 | Q22: 건축 | S22: 기계 | T22: 전기 | V22: 6 등급 : | W22: 토목 220억~140억 | Y22: 건축 210억~130억 | AA22: 0.0102 | AD22: 90000000000 | AE22: 1.3 | AF22: 2 | AG22: 80000000000 | AH22: 1.3 | AI22: 2 | AM22: E 그룹 : | AN22: A그룹～D그룹 이외의 공사 | AU22: 0.001
F23: (건강보험) | G23: (직접노무비) × 건강보험율 | S23: 1 | V23: 7 등급 : | W23: 토목 140억~ 7등급 미만 | Y23: 건축 130억~ 7등급 미만 | AA23: 0.0101 | AD23: 140000000000 | AE23: 1.57 | AF23: 1 | AG23: 120000000000 | AH23: 1.57 | AI23: 1
G24: =N10 -> 24331500 | J24: × | K24: =Q39 -> 3.595 | L24: = | N24: =INT((G24)*K24/100) -> 874717 | P24: [산업안전보건관리비 요율 구분] | AD24: [산업안전보건관리비 요율표] | AM24: [건설 하도급대금지급보증비 요율표]
F25: (요양보험) | G25: (국민건강보험료) × 노인장기요양보험율 | P25: 플랜트 공사 | Q25: 플랜트 外 공사 | V25: [산업안전보건관리비 요율표] | AD25: 건축공사 | AF25: 토목공사 | AM25: 공사규모 (추정가격) | AU25: 2018년도
G26: =N24 -> 874717 | J26: × | K26: =Q40 -> 13.14 | L26: = | N26: =INT((G26)*K26/100) -> 114937 | Q26: 1 | V26: 구분 | X26: 건축공사 요율/기초액 | Z26: 토목공사 요율/기초액 | AD26: 금액 | AE26: 요율 | AF26: 금액 | AG26: 요율 | AM26: 50억 미만 | AU26: 0.00081
P27: [공종별 추정비율 : 공급사에서 필히 현장조사 후 입찰 준비하시길 바랍니다] | V27: 2천만원 미만 | X27: 3.11 | Z27: 3.15 | AD27: 0 | AE27: 3.11 | AF27: 0 | AG27: 3.15 | AM27: 50억원～100억원 미만 | AU27: 0.0008
C28: 나) 산업안전보건관리비 | G28: =IF(P12=AE66,AF66,AF67) -> (도급재료비 ＋ 발주자재료비 ＋ 직접노무비) × 산업안전보건관리비율 ＋ 기초액 | N28: =IF(P12=AE70,AF70,AF71) -> (설비비 포함) | P28: 기계 : 00%, 전기 : 00% | V28: 2천만원~5억원 미만 | X28: 3.11 | Z28: 3.15 | AD28: 20000000 | AE28: 3.11 | AF28: 20000000 | AG28: 3.15 | AM28: 100억원～300억원 미만 | AU28: 0.00075
G29: =(N8+'[383]순공사비 내역서 '!L176)*P12+Q53*Q12*0.7 -> 10443700 | H29: ＋ | I29: =N10*P12 -> 24331500 | J29: × | K29: =((IF((G29+I29)="","",VLOOKUP((G29+I29),AD27:AE31,2,1))*Q26+IF((G29+I29)="","",VLOOKUP((G29+I29),AF27:AG31,2,1))*P26)) -> 3.11 | L29: ＋ | M29: =SUMIF(Z27:Z31,K29,AA27:AA31)+SUMIF(X27:X31,K29,Y27:Y31)+SUMIF(AB27:AB31,K29,AC27:AC31) -> 0 | N29: =INT((G29+I29)*K29/100+M29) -> 1081508 | P29: [필수면허] | V29: 5억원~50억원 미만 | W29: G2(1.86%+5,349 천원) | X29: 2.28 | Y29: 4325000 | Z29: 2.53 | AA29: 3300000 | AD29: 500000000 | AE29: 2.28 | AF29: 500000000 | AG29: 2.53 | AM29: 300억원 이상 (최저가낙찰 대상공사) | AR29: - 토목및산업설비 | AU29: 0.00071
G30: =IF(P12=AE68,AF68,AF69) -> ((도급재료비 ＋ 직접노무비) × 산업안전보건관리비율 ＋ 기초액) x 1.2 | N30: =IF(P12=AE72,AF72,AF73) -> (설비비 제외) | P30: 기계공사, 전기공사 면허 | V30: 50억원 이상 | W30: G3(1.97%) | X30: 2.37 | Z30: 2.6 | AD30: 5000000000 | AE30: 2.37 | AF30: 5000000000 | AG30: 2.6 | AR30: - 건축 | AU30: 0.00068
G31: =N8*P12+Q53*Q12*0.7 -> 9443700 | H31: ＋ | I31: =N10*P12 -> 24331500 | J31: × | K31: =((IF((G31+I31)="","",VLOOKUP((G31+I31),AF27:AG31,2,1))*P26+IF((G31+I31)="","",VLOOKUP((G31+I31),AD27:AE31,2,1))*Q26)) -> 3.11 | L31: ＋ | M31: =SUMIF(Z27:Z31,K31,AA27:AA31)+SUMIF(X27:X31,K31,Y27:Y31)+SUMIF(AB27:AB31,K31,AC27:AC31) -> 0 | N31: =INT((G31+I31)*K31/100+M31)*1.2 -> 1260489.6 | V31: 800억원 이상 | W31: G3(1.97%) | X31: 2.64 | Z31: 2.73 | AD31: 80000000000 | AE31: 2.64 | AF31: 80000000000 | AG31: 2.73 | AM31: 턴키(대안)공사 | AU31: 0.00084
B32: 산업안전보건관리비 적용 | N32: 2571687
P33: [요율]
C34: 다) 법정경비(퇴직공제비) | G34: (직접노무비) × 퇴직공제비율 | P34: 구분 | Q34: 요율 | S34: 비고
G35: =N10 -> 24331500 | J35: × | K35: =Q42 -> 2.3 | L35: = | N35: =INT((G35)*K35/100) -> 559624 | P35: 간접노무비 | Q35: =(IF((N8+N10+N16)="","",VLOOKUP((N8+N10+N16),AD12:AE14,2,1))*P20+IF((N8+N10+N16)="","",VLOOKUP((N8+N10+N16),AD12:AE14,2,1))*Q20+IF((N8+N10+N16)="","",VLOOKUP((N8+N10+N16),AH12:AI14,2,1))*S20+IF((N8+N10+N16)="","",VLOOKUP((N8+N10+N16),AH12:AI14,2,1))*T20+IF((P14)="","",VLOOKUP((P14),AF12:AG14,2,1))*P20+IF((P14)="","",VLOOKUP((P14),AF12:AG14,2,1))*Q20+IF((P14)="","",VLOOKUP((P14),AJ12:AK14,2,1))*S20+IF((P14)="","",VLOOKUP((P14),AJ12:AK14,2,1))*T20)/2 -> 11 | R35: %
P36: 산재보험 | Q36: 3.56 | R36: % | S36: 법정요율 | AF36: 설비비포함 | AG36: =IF(N32=N29,1,0) -> 0
C37: 라) 건설기계대여지급보증비 | G37: (도급재료비 ＋ 직접노무비 ＋ 산출경비 ) × 지급보증비율 | P37: 고용보험 | Q37: =IF((N8+N14+N16)="","",VLOOKUP((N8+N14+N16),AD17:AE23,2,1)) -> 1.01 | R37: % | S37: 법정요율 | AF37: 1.2배 | AG37: =IF(N32=N31,1,0) -> 0
G38: =N8 -> 9443700 | H38: ＋ | I38: =N10 -> 24331500 | J38: ＋ | K38: =N16 -> 42319539 | L38: × | M38: =Q43 -> 0.11 | N38: =INT((G38+I38+K38)*M38/100) -> 83704 | P38: 국민연금 | Q38: 4.75 | R38: % | S38: 법정요율
P39: 건강보험 | Q39: 3.595 | R39: % | S39: 법정요율
C40: 마) 환경보전비 | G40: (도급재료비 ＋ 직접노무비 ＋ 산출경비 ) × 지급보증비율 | P40: 요양보험 | Q40: 13.14 | R40: % | S40: 법정요율 | AF40: =Q58 -> 0 | AG40: =IF(AF40>=80000000000,1,0) -> 0
...

Sheet 전기공사비 내역서
B1: ○ 계약건명 : | E1: =#REF! -> #REF!
B2: ○ 시공사 :
B3: 순 공 사 비 내 역 서
B4: 구 분 | G4: 품명 | H4: 세부규격 | I4: 단 위 | J4: 수 량 | K4: 단 가 | L4: 금 액 | M4: 비 고
B5: 사 업 명 :
B6: 1. 도급 재료비
G7: 전기공사 | I7: 1 | J7: 식 | K7: 9443700 | L7: =INT(I7*K7) -> 9443700
B13: 재료비 계 | L13: =SUM(L7:L12) -> 9443700
B14: 2. 직접노무비
G15: 전기공사 | I15: 1 | J15: 식 | K15: 24331500 | L15: =K15*I15 -> 24331500
L23: =INT(J23*K23) -> 0
B24: 직접노무비 계 | L24: =SUM(L15:L23) -> 24331500
B25: 3. 경비
B26: 기계경비
G27: 전기공사 | I27: 1 | J27: 식 | K27: 42319539 | L27: =K27*I27 -> 42319539
B32: 일반경장비,공구 손료
F33: ( | L33: ) × 0.03 = | M33: =INT((H33-J33)*0.03) -> 0
B34: 경비 계 | L34: =SUM(L27:L31,M33) -> 42319539
B35: 순공사비 계 | L35: =L13+L24+L34 -> 76094739
B36: 4. 설비비
G37: 전기설비 | H37: PLC 개조, 계장밸브, 판넬류, 온도센서 등 | I37: 1 | J37: 식 | K37: 61605000 | L37: =I37*K37 -> 61605000
G38: 설계비 | H38: 기계 / 전기 설계 | I38: 1 | J38: 식 | K38: 11100000 | L38: =I38*K38 -> 11100000
L39: =INT(J39*K39) -> 0
L40: =INT(J40*K40) -> 0
B41: 설비비 계 | L41: =SUM(L37:L40) -> 72705000

Sheet 형강류
C2: 전 선 관 및 배 관 용 BRACKET 물 량 산 출 표
C3: 소 요 | D3: bracket | E3: bracket | F3: bracket | G3: bracket
A4: 구분 | B4: 규격 | C4: 거 리 | D4: 사용수량 | E4: 단위길이 | F4: 당 중량 | G4: 총중량 | H4: 비 고
C5: [ m ] | D5: [ EA ] | E5: [ mm ] | F5: [Kg/EA] | G5: [ Kg ]
A6: " | B6: ￠22 | C6: 0 | D6: =TRUNC(C6/1.5) -> 0 | E6: 200 | F6: =4.43*0.001*E6 -> 0.886 | G6: =TRUNC(+D6*F6*1000)/1000 -> 0
A7: " | B7: ￠28 | C7: 0 | D7: =TRUNC(C7/1.5) -> 0 | E7: 200 | F7: =4.43*0.001*E7 -> 0.886 | G7: =TRUNC(+D7*F7*1000)/1000 -> 0
A8: " | B8: ￠36 | C8: 0 | D8: =TRUNC(C8/1.5) -> 0 | E8: 200 | F8: =4.43*0.001*E8 -> 0.886 | G8: =TRUNC(+D8*F8*1000)/1000 -> 0
A9: " | B9: ￠42 | C9: 0 | D9: =TRUNC(C9/1.5) -> 0 | E9: 200 | F9: =4.43*0.001*E9 -> 0.886 | G9: =TRUNC(+D9*F9*1000)/1000 -> 0
A10: " | B10: ￠54 | C10: 0 | D10: =TRUNC(C10/1.5) -> 0 | E10: 200 | F10: =4.43*0.001*E10 -> 0.886 | G10: =TRUNC(+D10*F10*1000)/1000 -> 0
A11: " | B11: ￠70 | C11: 0 | D11: =TRUNC(C11/1.5) -> 0 | E11: 200 | F11: =4.43*0.001*E11 -> 0.886 | G11: =TRUNC(+D11*F11*1000)/1000 -> 0
A12: Air배관 | B12: 15A | C12: 0 | D12: =TRUNC(C12/1.5) -> 0 | E12: 200 | F12: =4.43*0.001*E12 -> 0.886 | G12: =TRUNC(+D12*F12*1000)/1000 -> 0
A13: Cable Tray | B13: W=600 | C13: 0 | D13: =TRUNC(C13/1.5) -> 0 | E13: 700 | F13: =4.43*0.001*E13 -> 3.101 | G13: =TRUNC(+D13*F13*1000)/1000 -> 0
A14: ㄷ Chanel | B14: 50x50x6t | C14: 0 | D14: 0 | F14: 9.36 | G14: =C14*F14 -> 0
A15: Angle | B15: 100X50X5X7.5 | C15: 0 | D15: 0 | F15: 17.1 | G15: =C15*F15 -> 0
A16: 합 계 | G16: =SUM(G6:G15) -> 0
A17: 참고: 1. | B17: 사용 | C17: bracket: | D17: 50m/mx50x6t[4.43Kg/m]
A18: 2. | B18: 물량 | C18: 할증: | D18: [5%=0.05]
B19: 실 사 용 물 량: | E19: = | F19: =G16 -> 0 | G19: [ kg ]
B20: 총 사 용 물 량: | D20: =G16 -> 0 | E20: x 1.05 = | F20: =TRUNC(+D20*1.05*1000)/1000 -> 0 | G20: [ kg ]
B21: 실 적 용 물 량: | E21: = | F21: =TRUNC(+F20)/1000 -> 0 | G21: [ Ton ]
C25: Panel류 Angle, Chanel 물량 산출표
A26: 구분 | B26: 수량 | C26: 길이 | D26: 단위중량(kg/ea) | E26: 중량(kg) | F26: 총중량(kg) | G26: 비고
A27: Local Panel | B27: 0 | C27: 2.4 | D27: 4.43 | E27: =D27*C27 -> 10.632 | F27: =E27*B27 -> 0 | G27: Angle
A28: Local Panel | B28: 0 | C28: 3.8 | D28: 9.36 | E28: =D28*C28 -> 35.568 | F28: =E28*B28 -> 0 | G28: Chanel
E29: 합계 | F29: =SUM(F27:F28) -> 0
A30: MCC Panel | B30: 0 | C30: 2.2 | D30: 9.36 | E30: =D30*C30 -> 20.592 | F30: =E30*B30 -> 0 | G30: 600기준
A31: 저압 Panel | B31: 2 | C31: 5.2 | D31: 9.36 | E31: =D31*C31 -> 48.672 | F31: =E31*B31 -> 97.344 | G31: 1800*1000 기준
A32: 고압 Panel | B32: 0 | C32: 5.6 | D32: 9.36 | E32: =D32*C32 -> 52.416 | F32: =E32*B32 -> 0 | G32: 2160 * 900 기준
E33: 총 합계 | F33: =SUM(F30:F32,F29) -> 97.344 | G33: [kg]
A34: 총 노무 물량 | F34: =F33/1000 -> 0.097344 | G34: [ton]
A35: 물량 할증 | D35: 0.05 | F35: =F34*0.05 -> 0.0048672 | G35: [ton]
A36: 총 재료 물량 | F36: =F34+F35 -> 0.1022112 | G36: [ton]

Sheet 도장
B1: 도장물량 및 소모자재비 · 노무비산출
A2: 가. 도장물량 산출
C3: 길 이 | D3: 기준면적 | E3: 도 장 | F3: 면 적 | G3: [ ㎡ ]
A4: 구 분 | B4: 규 격 | C4: m(ton) | D4: ㎡/m(㎡/T) | E4: 하도2회 | F4: 상도1회 | G4: 상도2회 | H4: 비 고
A5: 후강전선관 | B5: [￠16] | D5: 0.06597 | E5: - | F5: =C5*D5 -> 0 | G5: -
A6: " | B6: [￠22] | D6: 0.08325 | E6: - | F6: =C6*D6 -> 0 | G6: -
A7: " | B7: [￠28] | D7: 0.10461 | E7: - | F7: =C7*D7 -> 0 | G7: -
A8: " | B8: [￠36] | D8: 0.13163 | E8: - | F8: =C8*D8 -> 0 | G8: -
A9: " | B9: [￠42] | D9: 0.15016 | E9: - | F9: =C9*D9 -> 0 | G9: -
A10: " | B10: [￠54] | D10: 0.18723 | E10: - | F10: =C10*D10 -> 0 | G10: -
A11: " | B11: [￠70] | D11: 0.23624 | E11: - | F11: =C11*D11 -> 0 | G11: -
A12: " | B12: [￠82] | D12: 0.29612 | E12: - | F12: =C12*D12 -> 0 | G12: -
A13: " | B13: [￠104] | D13: 0.35625 | E13: - | F13: =C13*D13 -> 0 | G13: -
A14: ANGLE(ton) | B14: [30x30x3] | D14: 85.73 | E14: =C14*D14 -> 0 | F14: - | G14: =E14 -> 0
A15: ANGLE(ton) | B15: [30x30x5] | D15: 53.56 | E15: =C15*D15 -> 0 | F15: - | G15: =E15 -> 0
A16: ANGLE(ton) | B16: [50x50x4] | D16: 64.51 | E16: =C16*D16 -> 0 | F16: - | G16: =E16 -> 0
A17: ANGLE(ton) | B17: [50x50x5] | D17: 43.64 | E17: =C17*D17 -> 0 | F17: - | G17: =E17 -> 0
A18: ANGLE(ton) | B18: [50x50x6] | D18: 43.95 | E18: =C18*D18 -> 0 | F18: - | G18: =E18 -> 0
A19: CHANNELS | B19: [75x40x5] | D19: 41.81 | E19: =C19*D19 -> 0 | F19: - | G19: =E19 -> 0 | I19: 단위 확인
A20: CHANNELS | B20: [100x50x5] | D20: 40.37 | E20: =C20*D20 -> 0 | F20: - | G20: =E20 -> 0
A21: CHANNELS | B21: [150x70x6] | D21: 34.98 | E21: =C21*D21 -> 0 | F21: - | G21: =E21 -> 0
A22: STEEL PIPE | B22: [6A] | D22: 0.03299 | E22: =C22*D22 -> 0 | F22: - | G22: =E22 -> 0
A23: STEEL PIPE | B23: [8A] | D23: 0.04335 | E23: =C23*D23 -> 0 | F23: - | G23: =E23 -> 0
A24: STEEL PIPE | B24: [10A] | D24: 0.05435 | E24: =C24*D24 -> 0 | F24: - | G24: =E24 -> 0
A25: STEEL PIPE | B25: [15A] | D25: 0.06817 | E25: =C25*D25 -> 0 | F25: - | G25: =E25 -> 0
A26: STEEL PIPE | B26: [20A] | D26: 0.08545 | E26: =C26*D26 -> 0 | F26: - | G26: =E26 -> 0
A27: STEEL PIPE | B27: [25A] | D27: 0.10681 | E27: =C27*D27 -> 0 | F27: - | G27: =E27 -> 0
A28: STEEL PIPE | B28: [32A] | D28: 0.13415 | E28: =C28*D28 -> 0 | F28: - | G28: =E28 -> 0
A29: STEEL PIPE | B29: [40A] | D29: 0.15268 | E29: =C29*D29 -> 0 | F29: - | G29: =E29 -> 0
A30: STEEL PIPE | B30: [50A] | D30: 0.19007 | E30: =C30*D30 -> 0 | F30: - | G30: =E30 -> 0
A31: STEEL PIPE | B31: [65A] | D31: 0.2397 | E31: =C31*D31 -> 0 | F31: - | G31: =E31 -> 0
... A46: PLATES | B46: [6.0] | D46: 42.46 | E46: =C46*D46 -> 0 | F46: - | G46: =E46 -> 0
A47: PLATES | B47: [7.0] | D47: 36.4 | E47: =C46*D47 -> 0 | F47: - | G47: =E47 -> 0
A48: PLATES | B48: [8.0] | D48: 31.85 | E48: =C48*D48 -> 0 | F48: - | G48: =E48 -> 0
A49: PLATES | B49: [9.0] | D49: 28.309 | E49: =C49*D49 -> 0 | F49: - | G49: =E49 -> 0
A50: PLATES | B50: [10.0] | D50: 25.478 | E50: =C50*D50 -> 0 | F50: - | G50: =E50 -> 0
A51: PLATES | B51: [11.0] | D51: 23.162 | E51: =C51*D51 -> 0 | F51: - | G51: =E51 -> 0
A52: PLATES | B52: [12.0] | D52: 21.231 | E52: =C52*D52 -> 0 | F52: - | G52: =E52 -> 0
A53: PLATES | B53: [13.0] | D53: 19.598 | E53: =C53*D53 -> 0 | F53: - | G53: =E53 -> 0
A54: PLATES | B54: [14.0] | D54: 18.198 | E54: =C54*D54 -> 0 | F54: - | G54: =E54 -> 0
...

Sheet 방화
A1: 품 셈 # | D1: 방화 도료 칠 소모 자재비 및 노무비
A4: 가.방화도료 칠소모자재비
A5: 구 분 | C5: 품질 및 사양 | E5: 단 위 | F5: 수 량 | G5: 단 가 | H5: 금 액 | I5: 적용 근거
A6: 방재도료 | C6: Flame Mastic | E6: ㎡ | F6: =SUM(O59)/100 -> 1.14 | G6: 56700 | H6: =TRUNC(+F6*G6) -> 64638 | I6: VAX적용가
A7: 내화 Seal | C7: Hi-Seal | E7: ㎠ | F7: =SUM(F57) -> 300 | G7: 38 | H7: =TRUNC(+F7*G7) -> 11400 | I7: VAX적용가
A8: 방 화 판 | C8: 6tx910x1820mm | E8: 매 | F8: =SUM(O61)/100 -> 6.54 | G8: 1710 | H8: =TRUNC(+F8*G8) -> 11183 | I8: VAX적용가
A9: Rock-Wool | C9: Blanket#120x100t | E9: ㎡ | F9: =SUM(J57) -> 1.2 | G9: 18720 | H9: =TRUNC(+F9*G9) -> 22464 | I9: VAX적용가
A10: Drill Anchor | C10: M6x65L(100L) | E10: EA | F10: =SUM(L63) -> 24 | G10: 140 | H10: =TRUNC(+F10*G10) -> 3360 | I10: VAX적용가
A11: BIND WIRE | C11: 600V IV x 2.0㎟ | E11: M | F11: =SUM(L64) -> 4 | G11: 85 | H11: =TRUNC(+F11*G11) -> 340 | I11: VAX적용가
B13: 합 계 | H13: =SUM(H6:H11) -> 113385
A16: 나.방 화 도 료 칠 노 무 비
A17: 작 | B17: 업 | C17: 방 화 | D17: 도 료 | E17: Seal | F17: 단열판 | G17: 단 열
A18: 내 | B18: 용 | C18: 도포작 | D18: 업(㎡당) | E18: Putty | F18: 가 공 | G18: 충전단 | H18: 비 고
A19: 해 당 | B19: 노 임 | C19: 도 포 | D19: 소 계 | E19: 밀 착 | F19: 취 부 | G19: 가공취부
A20: 직 공 | B20: 단 가 | C20: 작 업 | E20: [㎏당] | F20: [㎡당] | G20: 부[㎡당]
A21: 도장공 | B21: =VLOOKUP(A21,#REF!,24,0) -> #REF! | C21: 0.091 | D21: =SUM(C21) -> 0.091 | E21: - | F21: - | G21: -
A22: 보통인부 | B22: =VLOOKUP(A22,#REF!,24,0) -> #REF! | C22: 0.091 | D22: =SUM(C22) -> 0.091 | E22: - | F22: - | G22: -
A23: 저압케이블전공 | B23: =VLOOKUP(A23,#REF!,24,0) -> #REF! | C23: 0.029 | D23: 0.029 | F23: - | G23: -
A24: 건축목공 | B24: =VLOOKUP(A24,#REF!,24,0) -> #REF! | C24: - | D24: - | E24: - | F24: 1.9281 | G24: 0.2375
A25: 특별인부 | B25: =VLOOKUP(A25,#REF!,24,0) -> #REF! | C25: - | D25: - | E25: 0.064 | F25: - | G25: -
A26: 단 위 노 임(A) | C26: - | D26: =TRUNC((B21*D21)+(B22*D22)) -> #REF! | E26: =B25*E25 -> #REF! | F26: =TRUNC(B24*F24) -> #REF! | G26: =TRUNC(B24*G24) -> #REF!
A27: 대 상 물 량(B) | C27: ㎡ | D27: =L59 -> 1.14 | E27: =L60 -> 0.6 | F27: =L61*0.183/1.05 -> 1.14 | G27: =J57 -> 1.2
A28: ( A x B ) | D28: =D26*D27 -> #REF! | E28: =E26*E27 -> #REF! | F28: =F26*F27 -> #REF! | G28: =TRUNC(+G26*G27) -> #REF!
A29: 노 무 비 계 | G29: =SUM(D28:G28) -> #REF!
A36: 산근 #3 | D36: 방 화 도 료 소 요 면 적 산 출
A37: [적용 구분] : [신설]
A38: 항목 | B38: 대 상 | C38: 방화도료 [㎡] | E38: 내화 Seal[㎠] | G38: 방화판 [매] | I38: RockWool[㎡] | K38: Bolt및 | L38: Nut[EA]
B39: Panel | C39: 기 준 | D39: 도 포 | E39: 기 준 | F39: 소 요 | G39: 기 준 | H39: 소 요 | I39: 기 준 | J39: 소 요 | K39: 기 준 | L39: 소 요
A40: 구분 | B40: 면 수 | C40: 면 적 | D40: 면 적 | E40: 면 적 | F40: 물 량 | G40: 면 적 | H40: 물 량 | I40: 면 적 | J40: 물 량 | K40: 면 적 | L40: 물 량
A41: MCC 반 | B41: 0 | C41: 0.35 | D41: =B41*C41 -> 0 | E41: 135 | F41: =B41*E41 -> 0 | G41: 0.16 | H41: =B41*G41 -> 0 | I41: 0.08 | J41: =B41*I41 -> 0 | K41: 6 | L41: =B41*K41 -> 0
A42: 저압반 | B42: 2 | C42: 0.38 | D42: =B42*C42 -> 0.76 | E42: 150 | F42: =B42*E42 -> 300 | G42: 0.57 | H42: =B42*G42 -> 1.14 | I42: 0.6 | J42: =B42*I42 -> 1.2 | K42: 12 | L42: =B42*K42 -> 24
A43: 고압반 | B43: 0 | C43: 0.47 | D43: =B43*C43 -> 0 | E43: 140 | F43: =B43*E43 -> 0 | G43: 0.5 | H43: =B43*G43 -> 0 | I43: 0.49 | J43: =B43*I43 -> 0 | K43: 10 | L43: =B43*K43 -> 0
A44: 벽관통 | B44: 0 | C44: 0.92 | D44: =B44*C44 -> 0 | E44: 432 | F44: =B44*E44 -> 0 | G44: 0.5 | H44: =B44*G44 -> 0 | I44: 0.18 | J44: =B44*I44 -> 0 | K44: 8 | L44: =B44*K44 -> 0
A45: [적 용] 소 계 | D45: =SUM(D41:D44) -> 0.76 | F45: =SUM(F41:F44) -> 300 | H45: =SUM(H41:H44) -> 1.14 | J45: =SUM(J41:J44) -> 1.2 | L45: =SUM(L41:L44) -> 24
A47: [적용 구분] : [개 조:품의 50%감]
A48: 항목 | B48: 대 상 | C48: 방화도료 [㎡] | E48: 내화 Seal[㎠] | G48: 방화판 [㎡] | I48: RockWool[㎡] | K48: Bolt및 | L48: Nut[EA]
B49: Panel | C49: 기 준 | D49: 도 포 | E49: 기 준 | F49: 소 요 | G49: 기 준 | H49: 소 요 | I49: 기 준 | J49: 소 요 | K49: 기 준 | L49: 소 요
A50: 구분 | B50: 면 수 | C50: 면 적 | D50: 면 적 | E50: 면 적 | F50: 물 량 | G50: 면 적 | H50: 물 량 | I50: 면 적 | J50: 물 량 | K50: 면 적 | L50: 물 량
A51: MCC 반 | B51: 0 | C51: 0.35 | D51: =B51*C51 -> 0 | E51: 135 | F51: =B51*E51 -> 0 | G51: 0.16 | H51: =B51*G51 -> 0 | I51: 0.08 | J51: =B51*I51 -> 0 | K51: 6 | L51: =B51*K51 -> 0
A52: 저압반 | B52: 0 | C52: 0.38 | D52: =B52*C52 -> 0 | E52: 150 | F52: =B52*E52 -> 0 | G52: 0.57 | H52: =B52*G52 -> 0 | I52: 0.6 | J52: =B52*I52 -> 0 | K52: 12 | L52: =B52*K52 -> 0
...

Sheet 계장배관
A1: No. | B1: 구분 | C1: 품명 | D1: 규격 | E1: 단위 | F1: 공종 | G1: 단가 | H1: 공수 | I1: 할증 | J1: 지역할증 | K1: 금액 | L1: 비고
C2: < 도압배관 공사 >
A3: 품5-A1 | C3: SGP STPG 38(SCH 40) | D3: 15A | E3: M | F3: 계장공 | G3: =VLOOKUP(F3,#REF!,23,0) -> #REF! | H3: 0.1 | I3: 1 | J3: 1.1 | K3: =H3*I3*G3*J3 -> #REF! | N3: 적용구분 | O3: 할증구분 | P3: 할증사항
F4: 배관공 | G4: =VLOOKUP(F4,#REF!,23,0) -> #REF! | H4: 0.1 | I4: 1 | J4: 1.1 | K4: =H4*I4*G4*J4 -> #REF! | N4: 계장설비 | O4: A | P4: 방폭공사 20%증,
F5: 보통인부 | G5: =VLOOKUP(F5,#REF!,23,0) -> #REF! | H5: 0.2 | I5: 1 | J5: 1.1 | K5: =H5*I5*G5*J5 -> #REF! | O5: A | P5: Loop 시험시 25%증
D6: 소 계 | G6: =VLOOKUP(F6,#REF!,23,0) -> #REF! | K6: =SUM(K3:K5) -> #REF! | O6: B | P6: 이설 40%증
G7: =VLOOKUP(F7,#REF!,23,0) -> #REF! | O7: B | P7: 철거 60%감
A8: 품5-A2 | C8: CONTROL AIR LINE | D8: 15A | E8: M | F8: 계장공 | G8: =VLOOKUP(F8,#REF!,23,0) -> #REF! | H8: 0.21 | I8: 1 | K8: =H8*I8*G8 -> #REF! | P8: ※ 1B:100A, 2B:150A,3B:200A,4B:300A 이하(Valve Size)로 적용
G9: =VLOOKUP(F9,#REF!,23,0) -> #REF!
A10: 품5-A3 | C10: VALVE | D10: 15A | E10: EA | F10: 계장공 | G10: =VLOOKUP(F10,#REF!,23,0) -> #REF! | H10: 0.2 | I10: 1 | K10: =H10*I10*G10 -> #REF!
G11: =VLOOKUP(F11,#REF!,23,0) -> #REF!
A12: 품5-A4 | C12: 강관배관 | D12: 50A | E12: M | F12: 배관공 | G12: =VLOOKUP(F12,#REF!,23,0) -> #REF! | H12: 0.248 | I12: 1.1 | K12: =H12*I12*G12 -> #REF!
E13: M | F13: 보통인부 | G13: =VLOOKUP(F13,#REF!,23,0) -> #REF! | H13: 0.063 | I13: 1.1 | K13: =H13*I13*G13 -> #REF!
D14: 소 계 | G14: =VLOOKUP(F14,#REF!,23,0) -> #REF! | K14: =SUM(K12:K13) -> #REF!
G15: =VLOOKUP(F15,#REF!,23,0) -> #REF!
A16: 품5-A5 | C16: 플랜트배관(용접탄소 강관) | D16: 150Ø | E16: 톤 | F16: 플랜트용접공 | G16: =VLOOKUP(F16,#REF!,23,0) -> #REF! | H16: 21.9 | I16: 1 | K16: =H16*I16*G16 -> #REF!
E17: 톤 | F17: 플랜트배관공 | G17: =VLOOKUP(F17,#REF!,23,0) -> #REF! | H17: 11 | I17: 1 | K17: =H17*I17*G17 -> #REF!
E18: 톤 | F18: 특별인부 | G18: =VLOOKUP(F18,#REF!,23,0) -> #REF! | H18: 11 | I18: 1 | K18: =H18*I18*G18 -> #REF!
D19: 소 계 | G19: =VLOOKUP(F19,#REF!,23,0) -> #REF! | K19: =SUM(K16:K18) -> #REF!
G20: =VLOOKUP(F20,#REF!,23,0) -> #REF!
A21: 품5-A6 | C21: 배관보온작업 | D21: 150Ø | E21: M | F21: 보온공 | G21: =VLOOKUP(F21,#REF!,23,0) -> #REF! | H21: 0.091 | I21: 1 | K21: =H21*I21*G21 -> #REF!
E22: M | F22: 특별인부 | G22: =VLOOKUP(F22,#REF!,23,0) -> #REF! | H22: 0.136 | I22: 1 | K22: =H22*I22*G22 -> #REF!
D23: 소 계 | G23: =VLOOKUP(F23,#REF!,23,0) -> #REF! | K23: 22255
A24: W8012 | G24: =VLOOKUP(F24,#REF!,23,0) -> #REF!
A25: 품5-A7 | C25: 계기설치 | D25: 일반각종 | E25: EA | F25: 계장공 | G25: =VLOOKUP(F25,#REF!,23,0) -> #REF! | H25: 0.27 | I25: 1 | K25: =H25*I25*G25 -> #REF!

Sheet Deck,접지, 컨테이너
A1: No. | B1: 구분 | C1: 품명 | D1: 규격 | E1: 단위 | F1: 공종 | G1: 단가 | H1: 공수 | I1: 할증 | J1: 지역할증 | K1: 금액 | L1: 비고
C2: < DECK 신설 > | N2: 적용구분 | O2: 할증구분 | P2: 할증사항
A3: 품4-A1 | C3: 강재류 가공 및 조립 | D3: 완제품설치 | E3: TON | F3: 보통인부 | G3: =VLOOKUP(F3,#REF!,23,0) -> #REF! | H3: 0.085 | I3: 1.8 | J3: 1 | K3: =H3*I3*G3*J3 -> #REF! | N3: 접지 | P3: 내선전공 기준
F4: 비계공 | G4: =VLOOKUP(F4,#REF!,23,0) -> #REF! | H4: 0.9 | I4: 1.8 | J4: 1 | K4: =H4*I4*G4*J4 -> #REF! | O4: B | P4: 철거 50%감
F5: 변전전공 | G5: =VLOOKUP(F5,#REF!,23,0) -> #REF! | H5: 6.85 | I5: 1.8 | J5: 1 | K5: =H5*I5*G5*J5 -> #REF! | O5: B | P5: 철거시 동판,동봉 미 설치시 90%감
D6: 소 계 | G6: =VLOOKUP(F6,#REF!,23,0) -> #REF! | K6: =SUM(K3:K5) -> #REF! | O6: B | P6: 접지봉 3본 연결을 초과한 1본연결 증가마다 0.07공(내선전공), 0.05공 (보통인부) 별도 계상
G7: =VLOOKUP(F7,#REF!,23,0) -> #REF!
A8: 품4-A2 | C8: 강재류 가공 및 조립 | D8: 현장제작설치 | E8: TON | F8: 철판공 | G8: =VLOOKUP(F8,#REF!,23,0) -> #REF! | H8: 27.4 | I8: 1.8 | J8: 1 | K8: =H8*I8*G8*J8 -> #REF!
F9: 플랜트용접공 | G9: =VLOOKUP(F9,#REF!,23,0) -> #REF! | H9: 3.6 | I9: 1.8 | J9: 1 | K9: =H9*I9*G9*J9 -> #REF!
F10: 보통인부 | G10: =VLOOKUP(F10,#REF!,23,0) -> #REF! | H10: 0.34 | I10: 1.8 | J10: 1 | K10: =H10*I10*G10*J10 -> #REF!
D11: 소 계 | G11: =VLOOKUP(F11,#REF!,23,0) -> #REF! | K11: =SUM(K8:K10) -> #REF!
G12: =VLOOKUP(F12,#REF!,23,0) -> #REF!
A13: W8611 | C13: < 접지 신설 > | G13: =VLOOKUP(F13,#REF!,23,0) -> #REF!
A14: 품4-A3 | C14: 접지봉 | D14: 길이 1~2M (3본) | E14: 개소 | F14: 통신외선공 | G14: =VLOOKUP(F14,#REF!,23,0) -> #REF! | H14: 0.45 | I14: 1 | J14: 1 | K14: =H14*I14*G14*J14 -> #REF!
F15: 보통인부 | G15: =VLOOKUP(F15,#REF!,23,0) -> #REF! | H15: 0.23 | I15: 1 | J15: 1 | K15: =H15*I15*G15*J15 -> #REF!
D16: 소 계 | G16: =VLOOKUP(F16,#REF!,23,0) -> #REF! | K16: =SUM(K14:K15) -> #REF!
G17: =VLOOKUP(F17,#REF!,23,0) -> #REF!
A18: 품4-A4 | C18: 동반매설 | D18: 1~1.5ㅡ 1매 | E18: EA | F18: 통신외선공 | G18: =VLOOKUP(F18,#REF!,23,0) -> #REF! | H18: 0.5 | I18: 1 | J18: 1 | K18: =H18*I18*G18*J18 -> #REF!
F19: 보통인부 | G19: =VLOOKUP(F19,#REF!,23,0) -> #REF! | H19: 0.5 | I19: 1 | J19: 1 | K19: =H19*I19*G19*J19 -> #REF!
D20: 소 계 | G20: =VLOOKUP(F20,#REF!,23,0) -> #REF! | K20: =SUM(K18:K19) -> #REF!
G21: =VLOOKUP(F21,#REF!,23,0) -> #REF!
A22: 품4-A5 | C22: 접지선 매설 | D22: 80mm 이하 | E22: M | F22: 통신외선공 | G22: =VLOOKUP(F22,#REF!,23,0) -> #REF! | H22: 0.015 | I22: 1 | J22: 1 | K22: =H22*I22*G22*J22 -> #REF!
G23: =VLOOKUP(F23,#REF!,23,0) -> #REF!
C24: 접지선 매설 | D24: 150mm 이하 | E24: M | F24: 통신외선공 | G24: =VLOOKUP(F24,#REF!,23,0) -> #REF! | H24: 0.02 | I24: 1 | J24: 1 | K24: =H24*I24*G24*J24 -> #REF!
G25: =VLOOKUP(F25,#REF!,23,0) -> #REF!
C26: < 컨테이너 신설 > | G26: =VLOOKUP(F26,#REF!,23,0) -> #REF!
A27: 품4-A6 | C27: 콘테이너형 가설 건축물 | D27: 6M | E27: EA | F27: 비계공 | G27: =VLOOKUP(F27,#REF!,23,0) -> #REF! | H27: 0.5 | I27: 1 | J27: 1 | K27: =H27*I27*G27*J27 -> #REF!
F28: 특별인부 | G28: =VLOOKUP(F28,#REF!,23,0) -> #REF! | H28: 0.25 | I28: 1 | J28: 1 | K28: =H28*I28*G28*J28 -> #REF!
D29: 소 계 | G29: =VLOOKUP(F29,#REF!,23,0) -> #REF! | K29: =SUM(K27:K28) -> #REF!
G30: =VLOOKUP(F30,#REF!,23,0) -> #REF!
A31: 품4-A7 | C31: 콘테이너형 가설 건축물 | D31: 12M | E31: EA | F31: 비계공 | G31: =VLOOKUP(F31,#REF!,23,0) -> #REF! | H31: 0.67 | I31: 1 | J31: 1 | K31: =H31*I31*G31*J31 -> #REF!
F32: 특별인부 | G32: =VLOOKUP(F32,#REF!,23,0) -> #REF! | H32: 0.33 | I32: 1 | J32: 1 | K32: =H32*I32*G32*J32 -> #REF!
D33: 소 계 | K33: =SUM(K31:K32) -> #REF!

Sheet pullbox, LCP
A1: No. | B1: 구분 | C1: 품명 | D1: 규격 | E1: 단위 | F1: 공종 | G1: 단가 | H1: 공수 | I1: 할증 | J1: 지역할증 | K1: 금액 | L1: 비고
A2: W7342 | C2: < Pull box > | N2: 적용구분 | O2: 할증구분 | P2: 할증사항
C3: PULL BOX 설치 | D3: 100 x 100 x 100 mm이하 | E3: EA | F3: 내선전공 | G3: =VLOOKUP(F3,#REF!,23,0) -> #REF! | H3: 0.17 | I3: 1.25 | J3: 1 | K3: =H3*I3*G3*J3 -> #REF! | N3: Pullbox | P3: 벽면 취부기준
G4: =VLOOKUP(F4,#REF!,23,0) -> #REF! | P4: Size는 Panel Size를 그대로 적용
C5: PULL BOX 설치 | D5: 250 x 250 x 200 mm이하 | E5: EA | F5: 내선전공 | G5: =VLOOKUP(F5,#REF!,23,0) -> #REF! | H5: 0.55 | I5: 1.25 | J5: 1 | K5: =H5*I5*G5*J5 -> #REF! | O5: A | P5: Block 벽체의 공동내 설치 20%증
G6: =VLOOKUP(F6,#REF!,23,0) -> #REF! | O6: A | P6: 철강조 노출설치 25%증
C7: PULL BOX 설치 | D7: 400 x 400 x 300 mm이하 | E7: EA | F7: 내선전공 | G7: =VLOOKUP(F7,#REF!,23,0) -> #REF! | H7: 0.66 | I7: 1.25 | J7: 1.1 | K7: =H7*I7*G7*J7 -> #REF! | O7: B | P7: 철거 70%감
G8: =VLOOKUP(F8,#REF!,23,0) -> #REF! | O8: A | P8: 방폭 및 방수형 200% 증
C9: PULL BOX 설치 | D9: 700 x 700 x 400 mm이하 | E9: EA | F9: 내선전공 | G9: =VLOOKUP(F9,#REF!,23,0) -> #REF! | H9: 0.95 | I9: 1.25 | J9: 1 | K9: =H9*I9*G9*J9 -> #REF! | P9: 통신공사시 통신내선공 적용
G10: =VLOOKUP(F10,#REF!,23,0) -> #REF! | N10: LCP, LCB 등 Local Box | P10: 천정면 적용
C11: PULL BOX 설치 | D11: 1000 x 1000 x 150 mm이하 | E11: EA | F11: 내선전공 | G11: =VLOOKUP(F11,#REF!,23,0) -> #REF! | H11: 1.23 | I11: 1.25 | J11: 1 | K11: =H11*I11*G11*J11 -> #REF!
G12: =VLOOKUP(F12,#REF!,23,0) -> #REF!
C13: PULL BOX 설치 | D13: 1200 x 1200 x 150 mm이하 | E13: EA | F13: 내선전공 | G13: =VLOOKUP(F13,#REF!,23,0) -> #REF! | H13: 1.56 | I13: 1.25 | J13: 1 | K13: =H13*I13*G13*J13 -> #REF!
G14: =VLOOKUP(F14,#REF!,23,0) -> #REF!
C15: < LCP > | G15: =VLOOKUP(F15,#REF!,23,0) -> #REF!
C16: LCP 설치 | D16: 100 x 100 x 100 mm이하 | E16: EA | F16: 내선전공 | G16: =VLOOKUP(F16,#REF!,23,0) -> #REF! | H16: 0.04 | I16: 1.25 | J16: 1 | K16: =H16*I16*G16*J16 -> #REF!
G17: =VLOOKUP(F17,#REF!,23,0) -> #REF!
C18: LCP 설치 | D18: 250 x 250 x 200 mm이하 | E18: EA | F18: 내선전공 | G18: =VLOOKUP(F18,#REF!,23,0) -> #REF! | H18: 0.22 | I18: 1.25 | J18: 1 | K18: =H18*I18*G18*J18 -> #REF!
G19: =VLOOKUP(F19,#REF!,23,0) -> #REF!
C20: LCP 설치 | D20: 400 x 400 x 300 mm이하 | E20: EA | F20: 내선전공 | G20: =VLOOKUP(F20,#REF!,23,0) -> #REF! | H20: 0.35 | I20: 1.25 | J20: 1 | K20: =H20*I20*G20*J20 -> #REF!
G21: =VLOOKUP(F21,#REF!,23,0) -> #REF!
C22: LCP 설치 | D22: 700 x 700 x 400 mm이하 | E22: EA | F22: 내선전공 | G22: =VLOOKUP(F22,#REF!,23,0) -> #REF! | H22: 0.66 | I22: 1.25 | J22: 1.1 | K22: =H22*I22*G22*J22 -> #REF!
G23: =VLOOKUP(F23,#REF!,23,0) -> #REF!
C24: LCP 설치 | D24: 1000 x 1000 x 150 mm이하 | E24: EA | F24: 내선전공 | G24: =VLOOKUP(F24,#REF!,23,0) -> #REF! | H24: 0.95 | I24: 1.25 | J24: 1 | K24: =H24*I24*G24*J24 -> #REF!
G25: =VLOOKUP(F25,#REF!,23,0) -> #REF!
C26: LCP 설치 | D26: 1200 x 1200 x 150 mm이하 | E26: EA | F26: 내선전공 | G26: =VLOOKUP(F26,#REF!,23,0) -> #REF! | H26: 1.3 | I26: 1.25 | J26: 1 | K26: =H26*I26*G26*J26 -> #REF!
G27: =VLOOKUP(F27,#REF!,23,0) -> #REF!
D28: 700 x 700 x 400 mm이하 | E28: EA | F28: 내선전공 | G28: =VLOOKUP(F28,#REF!,23,0) -> #REF! | H28: 0.66 | I28: =1.25*0.3 -> 0.375 | J28: 1.1 | K28: =H28*I28*G28*J28 -> #REF! | N28: 철거

Sheet 잡공사
A1: No. | B1: 구분 | C1: 품명 | D1: 규격 | E1: 단위 | F1: 공종 | G1: 단가 | H1: 공수 | I1: 할증 | J1: 지역할증 | K1: 금액 | L1: 비고
A2: W7344 | N2: 적용구분 | O2: 할증구분 | P2: 할증사항
A3: 품04-A3 | C3: 벽관통 구멍파기 | D3: 50cm | E3: 개소 | F3: 보통인부 | G3: =VLOOKUP(F3,#REF!,23,0) -> #REF! | H3: 2.3 | I3: 1 | J3: 1 | K3: =H3*I3*G3*J3 -> #REF! | N3: 벽관통 구멍파기 | O3: A | P3: 천정 50%증
G4: =VLOOKUP(F4,#REF!,23,0) -> #REF! | O4: A | P4: 방폭형 100%증
G5: =VLOOKUP(F5,#REF!,23,0) -> #REF!
A6: 품04-A7 | C6: 헐기 및 부수기 | D6: 콘크리트 | E6: M3 | F6: 할석공 | G6: =VLOOKUP(F6,#REF!,23,0) -> #REF! | H6: 2 | I6: 1 | J6: 1 | K6: =H6*I6*G6*J6 -> #REF!
G7: =VLOOKUP(F7,#REF!,23,0) -> #REF!
A8: 품04-A8 | C8: 비빔 콘크리트 타설(인력) | D8: 무근 | E8: M3 | F8: 보통인부 | G8: =VLOOKUP(F8,#REF!,23,0) -> #REF! | H8: 0.82 | I8: 1 | J8: 1 | K8: =H8*I8*G8*J8 -> #REF!
E9: M3 | F9: 콘크리트공 | G9: =VLOOKUP(F9,#REF!,23,0) -> #REF! | H9: 0.85 | I9: 1 | J9: 1 | K9: =H9*I9*G9*J9 -> #REF!
D10: 소 계 | G10: =VLOOKUP(F10,#REF!,23,0) -> #REF! | K10: =SUM(K8:K9) -> #REF!
G11: =VLOOKUP(F11,#REF!,23,0) -> #REF!
A12: 품04-A9 | C12: 인력터파기 | E12: M3 | F12: 보통인부 | G12: =VLOOKUP(F12,#REF!,23,0) -> #REF! | H12: 0.54 | I12: 1 | J12: 1 | K12: =H12*I12*G12*J12 -> #REF!
G13: =VLOOKUP(F13,#REF!,23,0) -> #REF!
A14: 품04-A10 | C14: 인력되묻기 | E14: M3 | F14: 보통인부 | G14: =VLOOKUP(F14,#REF!,23,0) -> #REF! | H14: 0.1 | I14: 1 | J14: 1 | K14: =H14*I14*G14*J14 -> #REF!
G15: =VLOOKUP(F15,#REF!,23,0) -> #REF!
A16: 품04-A11 | C16: 인력잔토처리 | E16: M3 | F16: 보통인부 | G16: =VLOOKUP(F16,#REF!,23,0) -> #REF! | H16: 0.2 | I16: 1 | J16: 1 | K16: =H16*I16*G16*J16 -> #REF!
G17: =VLOOKUP(F17,#REF!,23,0) -> #REF!
A18: 품04-A12 | C18: CORE DRILL D200 | E18: EA | F18: 활석공 | G18: =VLOOKUP(F18,#REF!,23,0) -> #REF! | H18: 0.65 | I18: 1 | K18: =H18*I18*G18 -> #REF!
C19: 300mm 기준 | G19: =VLOOKUP(F19,#REF!,23,0) -> #REF!
D20: 소 계 | G20: =VLOOKUP(F20,#REF!,23,0) -> #REF! | K20: =SUM(K18:K19) -> #REF!
A21: 품04-A13 | C21: CORE DRILL D100 | E21: EA | F21: 활석공 | G21: =VLOOKUP(F21,#REF!,23,0) -> #REF! | H21: 0.51 | I21: 1 | K21: =H21*I21*G21 -> #REF!
C22: 300mm 기준 | G22: =VLOOKUP(F22,#REF!,23,0) -> #REF!
D23: 소 계 | K23: =SUM(K21:K22) -> #REF!

Sheet Cable 단말처리
A1: No. | B1: 구분 | C1: 품명 | D1: 규격 | E1: 단위 | F1: 공종 | G1: 단가 | H1: 공수 | I1: 할증 | J1: 지역할증 | K1: 금액 | L1: 비고
A2: W7238
A3: 품02-L1 | C3: 전력 CABLE 단말처리(1C) | D3: 6/10KV F-CV 1C x 400SQ | E3: M | F3: 고압케이블전공 | G3: =VLOOKUP(F3,#REF!,23,0) -> #REF! | H3: 1.47 | I3: 1.2 | J3: 1 | K3: =H3*I3*G3*J3 -> #REF! | N3: 적용구분 | O3: 할증구분 | P3: 할증사항
A4: 품02-L2 | D4: 6/10KV F-CV 1C x 300SQ | E4: M | F4: 고압케이블전공 | G4: =VLOOKUP(F4,#REF!,23,0) -> #REF! | H4: 1.28 | I4: 1.2 | J4: 1 | K4: =H4*I4*G4*J4 -> #REF! | N4: 고압케이블 | P4: 저압적용하지않음
A5: 품02-L3 | D5: 6/10KV F-CV 1C x 240SQ | E5: M | F5: 고압케이블전공 | G5: =VLOOKUP(F5,#REF!,23,0) -> #REF! | H5: 1.17 | I5: 1.2 | J5: 1 | K5: =H5*I5*G5*J5 -> #REF! | O5: B | P5: 철거30%감, 이설60%감 (내압시험은 적용안함)
A6: 품02-L4 | D6: 6/10KV F-CV 1C x 185SQ | E6: M | F6: 고압케이블전공 | G6: =VLOOKUP(F6,#REF!,23,0) -> #REF! | H6: 1.06 | I6: 1.2 | J6: 1 | K6: =H6*I6*G6*J6 -> #REF!
A7: 품02-L5 | D7: 6/10KV F-CV 1C x 150SQ | E7: M | F7: 고압케이블전공 | G7: =VLOOKUP(F7,#REF!,23,0) -> #REF! | H7: 1.06 | I7: 1.2 | J7: 1 | K7: =H7*I7*G7*J7 -> #REF!
A8: 품02-L6 | D8: 6/10KV F-CV 1C x 120SQ | E8: M | F8: 고압케이블전공 | G8: =VLOOKUP(F8,#REF!,23,0) -> #REF! | H8: 0.83 | I8: 1.2 | J8: 1 | K8: =H8*I8*G8*J8 -> #REF!
A10: 품02-L7 | C10: 전력 CABLE 단말처리(3C) | D10: 6/10KV F-CV 3C x 300SQ | E10: M | F10: 고압케이블전공 | G10: =VLOOKUP(F10,#REF!,23,0) -> #REF! | H10: 2.02 | I10: 1.2 | J10: 1 | K10: =H10*I10*G10*J10 -> #REF!
A11: 품02-L8 | D11: 6/10KV F-CV 3C x 240SQ | E11: M | F11: 고압케이블전공 | G11: =VLOOKUP(F11,#REF!,23,0) -> #REF! | H11: 1.95 | I11: 1.2 | J11: 1 | K11: =H11*I11*G11*J11 -> #REF!
A12: 품02-L9 | D12: 6/10KV F-CV 3C x 185SQ | E12: M | F12: 고압케이블전공 | G12: =VLOOKUP(F12,#REF!,23,0) -> #REF! | H12: 1.76 | I12: 1.2 | J12: 1 | K12: =H12*I12*G12*J12 -> #REF!
A13: 품02-L10 | D13: 6/10KV F-CV 3C x 150SQ | E13: M | F13: 고압케이블전공 | G13: =VLOOKUP(F13,#REF!,23,0) -> #REF! | H13: 1.38 | I13: 1.2 | J13: 1.1 | K13: =H13*I13*G13*J13*1.6 -> #REF! | L13: 이설
A14: 품02-L11 | D14: 6/10KV F-CV 3C x 120SQ | E14: M | F14: 고압케이블전공 | G14: =VLOOKUP(F14,#REF!,23,0) -> #REF! | H14: 1.38 | I14: 1.2 | J14: 1 | K14: =H14*I14*G14*J14 -> #REF!
A15: 품02-L12 | D15: 6/10KV F-CV 3C x 95SQ | E15: M | F15: 고압케이블전공 | G15: =VLOOKUP(F15,#REF!,23,0) -> #REF! | H15: 1.27 | I15: 1.2 | J15: 1 | K15: =H15*I15*G15*J15 -> #REF!
A16: 품02-L13 | D16: 6/10KV F-CV 3C x 70SQ | E16: M | F16: 고압케이블전공 | G16: =VLOOKUP(F16,#REF!,23,0) -> #REF! | H16: 1.22 | I16: 1.2 | J16: 1 | K16: =H16*I16*G16*J16 -> #REF!
A17: 품02-L14 | D17: 6/10KV F-CV 3C x 50SQ | E17: M | F17: 고압케이블전공 | G17: =VLOOKUP(F17,#REF!,23,0) -> #REF! | H17: 1.07 | I17: 1.2 | J17: 1 | K17: =H17*I17*G17*J17 -> #REF!
A18: 품02-L15 | D18: 6/10KV F-CV 3C x 35SQ | E18: M | F18: 고압케이블전공 | G18: =VLOOKUP(F18,#REF!,23,0) -> #REF! | H18: 0.91 | I18: 1.2 | J18: 1 | K18: =H18*I18*G18*J18 -> #REF!
A20: 품02-L16 | C20: 전력 CABLE 직선접속(3C) | D20: 6/10KV F-CV 1C x 300SQ | E20: M | F20: 고압케이블전공 | G20: =VLOOKUP(F20,#REF!,23,0) -> #REF! | H20: 0.78 | I20: 1.2 | J20: 1 | K20: =H20*I20*G20*J20 -> #REF!
A21: 품02-L17 | D21: 6/10KV F-CV 1C x 240SQ | E21: M | F21: 고압케이블전공 | G21: =VLOOKUP(F21,#REF!,23,0) -> #REF! | H21: 0.73 | I21: 1.2 | J21: 1 | K21: =H21*I21*G21*J21 -> #REF!
A22: 품02-L18 | D22: 6/10KV F-CV 1C x 185SQ | E22: M | F22: 고압케이블전공 | G22: =VLOOKUP(F22,#REF!,23,0) -> #REF! | H22: 0.64 | I22: 1.2 | J22: 1 | K22: =H22*I22*G22*J22 -> #REF!
A23: 품02-L19 | D23: 6/10KV F-CV 1C x 150SQ | E23: M | F23: 고압케이블전공 | G23: =VLOOKUP(F23,#REF!,23,0) -> #REF! | H23: 0.5 | I23: 1.2 | J23: 1 | K23: =H23*I23*G23*J23 -> #REF!
A24: 품02-L20 | D24: 6/10KV F-CV 1C x 120SQ | E24: M | F24: 고압케이블전공 | G24: =VLOOKUP(F24,#REF!,23,0) -> #REF! | H24: 0.5 | I24: 1.2 | J24: 1 | K24: =H24*I24*G24*J24 -> #REF!
A25: 품02-L21 | D25: 6/10KV F-CV 1C x 95SQ | E25: M | F25: 고압케이블전공 | G25: =VLOOKUP(F25,#REF!,23,0) -> #REF! | H25: 0.46 | I25: 1.2 | J25: 1 | K25: =H25*I25*G25*J25 -> #REF!
A26: 품02-L22 | D26: 6/10KV F-CV 1C x 70SQ | E26: M | F26: 고압케이블전공 | G26: =VLOOKUP(F26,#REF!,23,0) -> #REF! | H26: 0.43 | I26: 1.2 | J26: 1 | K26: =H26*I26*G26*J26 -> #REF!
A28: 품02-L23 | C28: 전력 CABLE 직선접속(3C) | D28: 6/10KV F-CV 3C x 300SQ | E28: M | F28: 고압케이블전공 | G28: =VLOOKUP(F28,#REF!,23,0) -> #REF! | H28: 0.84 | I28: 1.2 | J28: 1 | K28: =H28*I28*G28*J28 -> #REF!
A29: 품02-L24 | D29: 6/10KV F-CV 3C x 240SQ | E29: M | F29: 고압케이블전공 | G29: =VLOOKUP(F29,#REF!,23,0) -> #REF! | H29: 0.77 | I29: 1.2 | J29: 1 | K29: =H29*I29*G29*J29 -> #REF!
A30: 품02-L25 | D30: 6/10KV F-CV 3C x 185SQ | E30: M | F30: 고압케이블전공 | G30: =VLOOKUP(F30,#REF!,23,0) -> #REF! | H30: 0.68 | I30: 1.2 | J30: 1 | K30: =H30*I30*G30*J30 -> #REF!
A31: 품02-L26 | D31: 6/10KV F-CV 3C x 150SQ | E31: M | F31: 고압케이블전공 | G31: =VLOOKUP(F31,#REF!,23,0) -> #REF! | H31: 0.57 | I31: 1.2 | J31: 1 | K31: =H31*I31*G31*J31 -> #REF!
A32: 품02-L27 | D32: 6/10KV F-CV 3C x 120SQ | E32: M | F32: 고압케이블전공 | G32: =VLOOKUP(F32,#REF!,23,0) -> #REF! | H32: 0.57 | I32: 1.2 | J32: 1 | K32: =H32*I32*G32*J32 -> #REF!
A33: 품02-L28 | D33: 6/10KV F-CV 3C x 95SQ | E33: M | F33: 고압케이블전공 | G33: =VLOOKUP(F33,#REF!,23,0) -> #REF! | H33: 0.5 | I33: 1.2 | J33: 1 | K33: =H33*I33*G33*J33 -> #REF!
A34: 품02-L29 | D34: 6/10KV F-CV 3C x 70SQ | E34: M | F34: 고압케이블전공 | G34: =VLOOKUP(F34,#REF!,23,0) -> #REF! | H34: 0.46 | I34: 1.2 | J34: 1 | K34: =H34*I34*G34*J34 -> #REF!
A36: 품02-L30 | C36: CABLE CLEAT | D36: 개소당 | E36: M | F36: 고압케이블전공 | G36: =VLOOKUP(F36,#REF!,23,0) -> #REF! | H36: 0.05 | I36: 1 | J36: 1 | K36: =H36*I36*G36*J36 -> #REF!
A38: 품02-L31 | C38: 앵커볼트(16~19) | D38: 개소당 | E38: M | F38: 내선전공 | G38: =VLOOKUP(F38,#REF!,23,0) -> #REF! | H38: 0.12 | I38: 1 | J38: 1 | K38: =H38*I38*G38*J38 -> #REF!

Sheet 강재제작설치
A1: No. | B1: 구분 | C1: 품명 | D1: 규격 | E1: 단위 | F1: 공종 | G1: 단가 | H1: 공수 | I1: 할증 | J1: 지역할증 | K1: 금액 | L1: 비고
A2: W7600 | B2: 강재제작설치 | N2: 적용구분 | O2: 할증구분 | P2: 할증사항
C3: < 전선관 SUPPORT 신설 > | N3: Bracket, Support | P3: 현장제작설치 기준
A4: 품02-K17 | C4: 강재류 가공 및 조립 | D4: 완제품설치 | E4: TON | F4: 보통인부 | G4: =VLOOKUP(F4,#REF!,23,0) -> #REF! | H4: 0.085 | I4: 1 | J4: 1 | K4: =H4*I4*G4*J4 -> #REF! | O4: B | P4: 철거 50%감, 재사용 철거 20%감
F5: 비계공 | G5: =VLOOKUP(F5,#REF!,23,0) -> #REF! | H5: 0.9 | I5: 1 | J5: 1 | K5: =H5*I5*G5*J5 -> #REF!
F6: 변전전공 | G6: =VLOOKUP(F6,#REF!,23,0) -> #REF! | H6: 6.85 | I6: 1 | J6: 1 | K6: =H6*I6*G6*J6 -> #REF!
D7: 소 계 | K7: =SUM(K4:K6) -> #REF!
A9: 품02-K18 | C9: 강재류 가공 및 조립 | D9: 현장제작설치 | E9: TON | F9: 철판공 | G9: =VLOOKUP(F9,#REF!,23,0) -> #REF! | H9: 27.4 | I9: 1 | J9: 1 | K9: =H9*I9*G9*J9 -> #REF!
F10: 용접공 | G10: =VLOOKUP(F10,#REF!,23,0) -> #REF! | H10: 3.6 | I10: 1 | J10: 1 | K10: =H10*I10*G10*J10 -> #REF!
F11: 보통인부 | G11: =VLOOKUP(F11,#REF!,23,0) -> #REF! | H11: 0.34 | I11: 1 | J11: 1 | K11: =H11*I11*G11*J11 -> #REF!
D12: 소 계 | K12: =SUM(K9:K11) -> #REF!

Sheet 통신Cable
A1: No. | B1: 구분 | C1: 품명 | D1: 규격 | E1: 단위 | F1: 공종 | G1: 단가 | H1: 공수 | I1: 할증 | J1: 지역할증 | K1: 금액 | L1: 비고
C2: 0.6KV~1KV | D2: OPTICAL CABLE
A3: 품02-F01 | C3: UTP CABLE | D3: UTP CABLE CAT.6 | E3: M | F3: 통신내선공 | G3: =VLOOKUP(F3,#REF!,23,0) -> #REF! | H3: 0.015 | I3: 1 | J3: 1 | K3: =H3*I3*G3*J3 -> #REF!
F4: RACK 설치 20%증 | H4: 0.2 | I4: 1 | J4: 1 | K4: =H4*I4*G4*J4 -> 0
D5: 소 계 | K5: =SUM(K3:K4) -> #REF!
A7: 품02-F02 | C7: OPTICAL CABLE | D7: 지중, 인력 | E7: M | F7: 광케이블설치사 | G7: =VLOOKUP(F7,#REF!,23,0) -> #REF! | H7: 0.0083 | I7: 1 | J7: 1 | K7: =H7*I7*G7*J7 -> #REF!
F8: 보통인부 | G8: =VLOOKUP(F8,#REF!,23,0) -> #REF! | H8: 0.021 | I8: 1 | J8: 1 | K8: =H8*I8*G8*J8 -> #REF!
D9: 소 계 | K9: =SUM(K7:K8) -> #REF!
A11: 품02-F03 | C11: OPTICAL CABLE | D11: 광케이블 코아접속 | E11: 코아당 | F11: 광케이블설치사 | G11: =VLOOKUP(F11,#REF!,23,0) -> #REF! | H11: 0.06 | I11: 1 | J11: 1 | K11: =H11*I11*G11*J11 -> #REF!
F12: 특별인부 | G12: =VLOOKUP(F12,#REF!,23,0) -> #REF! | H12: 0.06 | I12: 1 | J12: 1 | K12: =H12*I12*G12*J12 -> #REF!
K13: =SUM(K11:K12) -> #REF!
A15: 품02-F04 | C15: OPTICAL CABLE | D15: 외피접속 | E15: M | F15: 광케이블설치사 | G15: =VLOOKUP(F15,#REF!,23,0) -> #REF! | H15: 0.67 | I15: 1 | J15: 1 | K15: =H15*I15*G15*J15 -> #REF!
F16: 보통인부 | G16: =VLOOKUP(F16,#REF!,23,0) -> #REF! | H16: 0.31 | I16: 1 | J16: 1 | K16: =H16*I16*G16*J16 -> #REF!
D17: 소 계 | K17: =SUM(K15:K16) -> #REF!
A19: 품02-F05 | C19: OPTICAL CABLE | D19: 광케이블시험/측정(접속후) | E19: M | F19: 광케이블설치사 | G19: =VLOOKUP(F19,#REF!,23,0) -> #REF! | H19: 0.15 | I19: 1 | J19: 1 | K19: =H19*I19*G19*J19 -> #REF!
F20: 보통인부 | G20: =VLOOKUP(F20,#REF!,23,0) -> #REF! | H20: 0.13 | I20: 1 | J20: 1 | K20: =H20*I20*G20*J20 -> #REF!
D21: 소 계 | K21: =SUM(K19:K20) -> #REF!
A23: 품02-F06 | C23: OPTICAL CABLE | D23: 광케이블시험/측정(최종) | E23: M | F23: 광케이블설치사 | G23: =VLOOKUP(F23,#REF!,23,0) -> #REF! | H23: 0.25 | I23: 1 | J23: 1 | K23: =H23*I23*G23*J23 -> #REF!
F24: 보통인부 | G24: =VLOOKUP(F24,#REF!,23,0) -> #REF! | H24: 0.2 | I24: 1 | J24: 1 | K24: =H24*I24*G24*J24 -> #REF!
D25: 소 계 | K25: =SUM(K23:K24) -> #REF!

Sheet 전선관
A1: No. | B1: 구분 | C1: 품명 | D1: 규격 | E1: 단위 | F1: 공종 | G1: 단가 | H1: 공수 | I1: 할증 | J1: 지역할증 | K1: 금액 | L1: 비고
A2: W7311 | B2: 전선관로 | N2: 적용구분 | O2: 할증구분 | P2: 할증사항
C3: < 전선관 배관 > | O3: A | P3: 방폭 20%증, 콘크리트 노출 & 부럭칸막이 벽내 20%증
C4: 전선관 신설 | D4: 후강전선관 | O4: A | P4: 철강조 노출 25%증, 천정, 마루밑 공사30%증, 철거 70%감
C5: 전선관 포설 | D5: 22C | E5: M | F5: 내선전공 | G5: =VLOOKUP(F5,#REF!,23,0) -> #REF! | H5: 0.11 | I5: 1.25 | J5: 1 | K5: =H5*I5*G5 -> #REF! | O5: B | P5: 재사용철거 60%감,지중매설 30%감
C6: 전선관 포설 | D6: 28C | E6: M | F6: 내선전공 | G6: =VLOOKUP(F6,#REF!,23,0) -> #REF! | H6: 0.14 | I6: 1.25 | J6: 1 | K6: =H6*I6*G6 -> #REF! | P6: 전선관 부속품율 17.5%
C7: 전선관 포설 | D7: 36C | E7: M | F7: 내선전공 | G7: =VLOOKUP(F7,#REF!,23,0) -> #REF! | H7: 0.2 | I7: 1.25 | J7: 1 | K7: =H7*I7*G7 -> #REF! | N7: 후강전선관 | P7: W7311
C8: 전선관 포설 | D8: 42C | E8: M | F8: 내선전공 | G8: =VLOOKUP(F8,#REF!,23,0) -> #REF! | H8: 0.25 | I8: 1.25 | J8: 1 | K8: =H8*I8*G8 -> #REF! | N8: Flexible 전선관 | P8: W7311, 금속가요전선관
C9: 전선관 포설 | D9: 54C | E9: M | F9: 내선전공 | G9: =VLOOKUP(F9,#REF!,23,0) -> #REF! | H9: 0.34 | I9: 1.25 | J9: 1.1 | K9: =H9*I9*G9 -> #REF! | N9: ELP 전선관 | O9: A | P9: 2열동시 80%증, 3열 160%증, 4열 240%증, 6열 320%증, 8열 400%증, 10열 480%증, 12열 560%증, 14열 640%증, 16열 720%증
C10: 전선관 포설 | D10: 70C | E10: M | F10: 내선전공 | G10: =VLOOKUP(F10,#REF!,23,0) -> #REF! | H10: 0.44 | I10: 1.25 | J10: 1 | K10: =H10*I10*G10 -> #REF! | O10: B | P10: 철거 50%감, 재사용철거 20%감
C11: 전선관 포설 | D11: 82C | E11: M | F11: 내선전공 | G11: =VLOOKUP(F11,#REF!,23,0) -> #REF! | H11: 0.54 | I11: 1.25 | J11: 1 | K11: =H11*I11*G11 -> #REF!
C12: 전선관 포설 | D12: 104C | E12: M | F12: 내선전공 | G12: =VLOOKUP(F12,#REF!,23,0) -> #REF! | H12: 0.71 | I12: 1.25 | J12: 1 | K12: =H12*I12*G12 -> #REF!
C14: FLEXIBLE 포설 | D14: 22C | E14: M | F14: 내선전공 | G14: =VLOOKUP(F14,#REF!,23,0) -> #REF! | H14: 0.059 | I14: 1.25 | J14: 1 | K14: =H14*I14*G14 -> #REF!
C15: FLEXIBLE 포설 | D15: 28C | E15: M | F15: 내선전공 | G15: =VLOOKUP(F15,#REF!,23,0) -> #REF! | H15: 0.072 | I15: 1.25 | J15: 1 | K15: =H15*I15*G15 -> #REF!
C16: FLEXIBLE 포설 | D16: 36C | E16: M | F16: 내선전공 | G16: =VLOOKUP(F16,#REF!,23,0) -> #REF! | H16: 0.087 | I16: 1.25 | J16: 1 | K16: =H16*I16*G16 -> #REF!
C17: FLEXIBLE 포설 | D17: 42C | E17: M | F17: 내선전공 | G17: =VLOOKUP(F17,#REF!,23,0) -> #REF! | H17: 0.104 | I17: 1.25 | J17: 1 | K17: =H17*I17*G17 -> #REF!
C18: FLEXIBLE 포설 | D18: 54C | E18: M | F18: 내선전공 | G18: =VLOOKUP(F18,#REF!,23,0) -> #REF! | H18: 0.136 | I18: 1.25 | J18: 1 | K18: =H18*I18*G18 -> #REF!
C19: FLEXIBLE 포설 | D19: 70C | E19: M | F19: 내선전공 | G19: =VLOOKUP(F19,#REF!,23,0) -> #REF! | H19: 0.156 | I19: 1.25 | J19: 1 | K19: =H19*I19*G19 -> #REF!
C20: FLEXIBLE 포설 | D20: 82C | E20: M | F20: 내선전공 | G20: =VLOOKUP(F20,#REF!,23,0) -> #REF! | H20: 0.156 | I20: 1.25 | J20: 1 | K20: =H20*I20*G20 -> #REF!
C21: FLEXIBLE 포설 | D21: 104C | E21: M | F21: 내선전공 | G21: =VLOOKUP(F21,#REF!,23,0) -> #REF! | H21: 0.156 | I21: 1.25 | J21: 1 | K21: =H21*I21*G21 -> #REF!
A23: 품04-A4 | C23: ELP | D23: 150Ø | E23: M | F23: 배관공 | G23: =VLOOKUP(F23,#REF!,23,0) -> #REF! | H23: 0.019 | I23: 1 | J23: 1 | K23: =H23*I23*G23 -> #REF!
E24: M | F24: 보통인부 | G24: =VLOOKUP(F24,#REF!,23,0) -> #REF! | H24: 0.062 | I24: 1 | J24: 1 | K24: =H24*I24*G24 -> #REF!
D25: 소 계 | K25: =SUM(K23:K24) -> #REF!
A27: 품04-A5 | C27: ELP | D27: 100Ø | E27: M | F27: 배관공 | G27: 226771 | H27: 0.012 | I27: 1 | J27: 1 | K27: =H27*I27*G27 -> 2721.252
E28: M | F28: 보통인부 | G28: 157068 | H28: 0.036 | I28: 1 | J28: 1 | K28: =H28*I28*G28 -> 5654.448
D29: 소 계 | K29: =SUM(K27:K28) -> 8375.7
A31: 품04-A6 | C31: ELP | D31: 40Ø | E31: M | F31: 배관공 | G31: 226771 | H31: 0.007 | I31: 1 | J31: 1 | K31: =H31*I31*G31 -> 1587.397
E32: M | F32: 보통인부 | G32: 157068 | H32: 0.018 | I32: 1 | J32: 1 | K32: =H32*I32*G32 -> 2827.224
D33: 소 계 | K33: =SUM(K31:K32) -> 4414.621

Sheet Cable
A1: No. | B1: 구분 | C1: 품명 | D1: 규격 | E1: 단위 | F1: 공종 | G1: 단가 | H1: 공수 | I1: 할증 | J1: 지역할증 | K1: 금액 | L1: 비고
A2: W7239 | B2: 모선 배선 | N2: 적용구분 | O2: 할증구분 | P2: 할증사항
C3: < CABLE 신설 > | N3: 저압 Cable | O3: A | P3: 직매시 20%감
C4: 3.3~6.6KV | D4: 고압 POWER CABLE 1C | O4: A | P4: 2심 40%증, 3심 100%증, 4심 160%증
A5: 품02-A01 | C5: POWER CABLE(HV) | D5: 6/10KV F-CV 1C x 1000SQ | E5: M | F5: 저압케이블전공 | G5: =VLOOKUP(F5,#REF!,23,0) -> #REF! | H5: 0.394 | I5: 1.15 | J5: 1 | K5: =H5*I5*G5 -> #REF! | O5: B | P5: 철거 50%감, 이설 40%증
A6: 품02-A02 | C6: POWER CABLE(HV) | D6: 6/10KV F-CV 1C x 630SQ | E6: M | F6: 저압케이블전공 | G6: =VLOOKUP(F6,#REF!,23,0) -> #REF! | H6: 0.27 | I6: 1.15 | J6: 1 | K6: =H6*I6*G6 -> #REF! | P6: * 600V 8㎟이하 : Control Cable 준용
A7: 품02-A03 | C7: POWER CABLE(HV) | D7: 6/10KV F-CV 1C x 500SQ | E7: M | F7: 저압케이블전공 | G7: =VLOOKUP(F7,#REF!,23,0) -> #REF! | H7: 0.228 | I7: 1.15 | J7: 1 | K7: =H7*I7*G7 -> #REF! | N7: 고압 Cable & 전기실 ~ 전기실 | P7: W7236 적용(작성필요)
A8: 품02-A04 | C8: POWER CABLE(HV) | D8: 6/10KV F-CV 1C x 400SQ | E8: M | F8: 저압케이블전공 | G8: =VLOOKUP(F8,#REF!,23,0) -> #REF! | H8: 0.195 | I8: 1.15 | J8: 1 | K8: =H8*I8*G8 -> #REF! | N8: 고압 Cable & 전기실 to Motor | P8: W7239 적용
A9: 품02-A05 | C9: POWER CABLE(HV) | D9: 6/10KV F-CV 1C x 325SQ | E9: M | F9: 저압케이블전공 | G9: =VLOOKUP(F9,#REF!,23,0) -> #REF! | H9: 0.163 | I9: 1.15 | J9: 1 | K9: =H9*I9*G9 -> #REF! | N9: 고압 Cable 공통 | O9: A | P9: 직매시 20%감
A10: 품02-A06 | C10: POWER CABLE(HV) | D10: 6/10KV F-CV 1C x 300SQ | E10: M | F10: 저압케이블전공 | G10: =VLOOKUP(F10,#REF!,23,0) -> #REF! | H10: 0.151 | I10: 1.15 | J10: 1 | K10: =H10*I10*G10 -> #REF! | O10: A | P10: 2열동시80%증,3열동시160%증
A11: 품02-A07 | C11: POWER CABLE(HV) | D11: 6/10KV F-CV 1C x 250SQ | E11: M | F11: 저압케이블전공 | G11: =VLOOKUP(F11,#REF!,23,0) -> #REF! | H11: 0.135 | I11: 1.15 | J11: 1 | K11: =H11*I11*G11 -> #REF! | O11: A | P11: 4열동시240%증,5열동시320%증
A12: 품02-A08 | C12: POWER CABLE(HV) | D12: 6/10KV F-CV 1C x 240SQ | E12: M | F12: 저압케이블전공 | G12: =VLOOKUP(F12,#REF!,23,0) -> #REF! | H12: 0.129 | I12: 1.15 | J12: 1 | K12: =H12*I12*G12 -> #REF! | O12: A | P12: 단심케이블을 동일 2조이상 포설시 1조 추가시마다 본품의 80%씩가산
A13: 품02-A09 | C13: POWER CABLE(HV) | D13: 6/10KV F-CV 1C x 200SQ | E13: M | F13: 저압케이블전공 | G13: =VLOOKUP(F13,#REF!,23,0) -> #REF! | H13: 0.111 | I13: 1.15 | J13: 1 | K13: =H13*I13*G13 -> #REF! | O13: A | P13: 배전전력케이블 포설시구내부설부문 전력케이블은 50%증(기본적용)
A14: 품02-A10 | C14: POWER CABLE(HV) | D14: 6/10KV F-CV 1C x 185SQ | E14: M | F14: 저압케이블전공 | G14: =VLOOKUP(F14,#REF!,23,0) -> #REF! | H14: 0.103 | I14: 1.15 | J14: 1 | K14: =H14*I14*G14 -> #REF! | O14: A | P14: 공동구(전력구,Cable Truss,공동가대 포함)의 경우 이품의 25%증(기본적용)
A15: 품02-A11 | C15: POWER CABLE(HV) | D15: 6/10KV F-CV 1C x 150SQ | E15: M | F15: 저압케이블전공 | G15: =VLOOKUP(F15,#REF!,23,0) -> #REF! | H15: 0.092 | I15: 1.15 | J15: 1.1 | K15: =H15*I15*G15 -> #REF! | O15: B | P15: 철거 50%감, 이설 40%증
A16: 품02-A12 | C16: POWER CABLE(HV) | D16: 6/10KV F-CV 1C x 120SQ | E16: M | F16: 저압케이블전공 | G16: =VLOOKUP(F16,#REF!,23,0) -> #REF! | H16: 0.08 | I16: 1.15 | J16: 1 | K16: =H16*I16*G16 -> #REF! | P16: * 600V 8㎟이하 : Control Cable 준용
D17: 6/10KV F-CV 1C x 95SQ | E17: M | F17: 저압케이블전공 | G17: =VLOOKUP(F17,#REF!,23,0) -> #REF! | H17: 0.08 | I17: 1.15 | J17: 1.1 | K17: =H17*I17*G17 -> #REF! | N17: Control Cable | O17: A | P17: 직매시 20%감
C18: 3.3~6.6KV | D18: 고압 POWER CABLE 3C | O18: A | P18: 쉴드케이블 20%증
A19: 품02-A13 | C19: POWER CABLE(HV) | D19: 6/10KV F-CV 3C x 1000SQ | E19: M | F19: 저압케이블전공 | G19: =VLOOKUP(F19,#REF!,23,0) -> #REF! | H19: 0.394 | I19: 2.15 | J19: 1 | K19: =H19*I19*G19 -> #REF! | O19: B
A20: 품02-A14 | C20: POWER CABLE(HV) | D20: 6/10KV F-CV 3C x 630SQ | E20: M | F20: 저압케이블전공 | G20: =VLOOKUP(F20,#REF!,23,0) -> #REF! | H20: 0.27 | I20: 2.15 | J20: 1 | K20: =H20*I20*G20 -> #REF!
A21: 품02-A15 | C21: POWER CABLE(HV) | D21: 6/10KV F-CV 3C x 500SQ | E21: M | F21: 저압케이블전공 | G21: =VLOOKUP(F21,#REF!,23,0) -> #REF! | H21: 0.228 | I21: 2.15 | J21: 1 | K21: =H21*I21*G21 -> #REF!
A22: 품02-A16 | C22: POWER CABLE(HV) | D22: 6/10KV F-CV 3C x 400SQ | E22: M | F22: 저압케이블전공 | G22: =VLOOKUP(F22,#REF!,23,0) -> #REF! | H22: 0.195 | I22: 2.15 | J22: 1 | K22: =H22*I22*G22 -> #REF!
A23: 품02-A17 | C23: POWER CABLE(HV) | D23: 6/10KV F-CV 3C x 325SQ | E23: M | F23: 저압케이블전공 | G23: =VLOOKUP(F23,#REF!,23,0) -> #REF! | H23: 0.163 | I23: 2.15 | J23: 1 | K23: =H23*I23*G23 -> #REF!
A24: 품02-A18 | C24: POWER CABLE(HV) | D24: 6/10KV F-CV 3C x 300SQ | E24: M | F24: 저압케이블전공 | G24: =VLOOKUP(F24,#REF!,23,0) -> #REF! | H24: 0.151 | I24: 2.15 | J24: 1 | K24: =H24*I24*G24 -> #REF!
A25: 품02-A19 | C25: POWER CABLE(HV) | D25: 6/10KV F-CV 3C x 250SQ | E25: M | F25: 저압케이블전공 | G25: =VLOOKUP(F25,#REF!,23,0) -> #REF! | H25: 0.135 | I25: 2.15 | J25: 1 | K25: =H25*I25*G25 -> #REF!
A26: 품02-A20 | C26: POWER CABLE(HV) | D26: 6/10KV F-CV 3C x 240SQ | E26: M | F26: 저압케이블전공 | G26: =VLOOKUP(F26,#REF!,23,0) -> #REF! | H26: 0.129 | I26: 2.15 | J26: 1 | K26: =H26*I26*G26 -> #REF!
