Workbook
Name _: #REF!
Name _: #REF!
Name _: #REF!
Name _: #REF!
Name _??±?????³?¿ª: #REF!
Name ____________sn0001: [1]도!#REF!
Name ___________A70000: '[2]4-3 보온 기본물량집계'!#REF!
Name ___________A70001: '[2]4-3 보온 기본물량집계'!#REF!
Name ___________o12111: '[3]#REF'!#REF!
Name ___________sn0001: [1]도!#REF!
Name __________A70000: #REF!
Name __________A70000: #REF!
Name __________A70001: '[2]4-3 보온 기본물량집계'!#REF!
Name __________o12111: '[3]#REF'!#REF!
Name __________sn0001: [1]도!#REF!
Name _________A70000: #REF!
Name _________A70000: #REF!
Name _________A70001: #REF!
Name _________A70001: #REF!
Name _________o12111: #REF!
Name _________o12111: #REF!
Name _________sn0001: #REF!
Name _________sn0001: #REF!
Name ________A1: #REF!
Name ________A70000: #REF!
Name ________A70000: #REF!
Name ________A70001: #REF!
Name ________A70001: #REF!
Name ________LPB1: [4]부하계산서!#REF!
Name ________LPK1: [4]부하계산서!#REF!
Name ________LU1: '[5]부하(성남)'!#REF!
Name ________LU2: '[5]부하(성남)'!#REF!
Name ________LV01: '[5]부하(성남)'!#REF!
Name ________o12111: #REF!
Name ________o12111: #REF!
Name ________sn0001: #REF!
Name ________sn0001: #REF!
Name ________UP1: [4]부하계산서!#REF!
Name ________UP2: [4]부하계산서!#REF!
Name _______A1: #REF!
Name _______A70000: #REF!
Name _______A70000: #REF!
Name _______A70001: #REF!
Name _______A70001: #REF!
Name _______aaa01: #REF!
Name _______aaa02: #REF!
Name _______aaa03: #REF!
Name _______aaa04: #REF!
Name _______aaa97: #REF!
Name _______aaa98: #REF!
Name _______aaa99: #REF!
Name _______ELL45: #REF!
Name _______ELL90: #REF!
Name _______LP1: #REF!
Name _______LP2: #REF!
Name _______NEW1: ROUND([0]!_______NEW1*0.0254,3)
Name _______o12111: #REF!
Name _______o12111: #REF!
Name _______QQ1: #REF!
Name _______QQ1: #REF!

Sheet VXXXXX

Sheet 내역비교(이앤씨, 플랜텍)
B4: 플랜텍 견적 | L4: 포스코 이앤씨 견적 | V4: 최종 투자비
B7: [ 재료비 ] | I7: ( 단위 : 원, 단가/금액) | L7: [ 재료비 ] | S7: ( 단위 : 원, 단가/금액) | V7: [ 재료비 ] | AC7: ( 단위 : 원, 단가/금액)
B8: 항목 | C8: 수량 | D8: 단위 | E8: 재료비 | F8: 노무비 | G8: 경 비 | H8: 계 | I8: 비고 | L8: 항목 | M8: 수량 | N8: 단위 | O8: 재료비 | P8: 노무비 | Q8: 경 비 | R8: 계 | S8: 비고 | V8: 항목 | W8: 수량 | X8: 단위 | Y8: 재료비 | Z8: 노무비 | AA8: 경 비 | AB8: 계 | AC8: 비고
B9: GIRDER 제작 | C9: 1 | D9: 식 | E9: 0 | F9: 0 | G9: 228200000 | H9: 228200000 | I9: A | L9: Idler(B-315) | M9: 2.31 | N9: Ton | O9: - | R9: - | V9: Frame
B10: GRIZZLY BAR 제작 | C10: 15 | D10: Ton | E10: 0 | F10: 0 | G10: 700800000 | H10: 700800000 | I10: A | L10: C/Self Align | M10: 0.16 | N10: Ton | O10: - | R10: - | V10: Walkway
B11: Duct 제작 | C11: 1 | D11: 식 | E11: 0 | F11: 0 | G11: 228200000 | I11: A | L11: R/Self Align | M11: 0.16 | N11: Ton | O11: - | R11: - | V11: Grizzly Bar
B12: DAMPER 제작(Manual 및 Auto) | C12: 1 | D12: 식 | E12: 0 | F12: 0 | G12: 68700000 | I12: A | L12: Tripper Car Frame | M12: 26 | N12: Ton | O12: 4812500 | R12: =M12*O12 -> 125125000 | V12: Safety Fence
B13: RAIL 제작 | C13: 1 | D13: 식 | E13: 0 | F13: 0 | G13: 27600000 | H13: 27600000 | I13: A | L13: Tripper Rail | M13: 3.43 | N13: Ton | O13: 1687500 | R13: =O13*M13 -> 5788125 | V13: Rail
L14: Grizzly Bar | M14: 13.39 | N14: Ton | O14: 13750000 | R14: =O14*M14 -> 184112500
L15: Safety Fence | M15: 7.7 | N15: Ton | O15: 5000000 | R15: =O15*M15 -> 38500000
L16: Idler(B-415) | M16: 2.31 | N16: Ton | O16: - | R16: -
L17: C/Self Align | M17: 0.16 | N17: Ton | O17: - | R17: -
L18: R/Self Align | M18: 0.16 | N18: Ton | O18: - | R18: -
L19: Tripper Car Frame | M19: 26 | N19: Ton | O19: 4812500 | R19: =M19*O19 -> 125125000
L20: Tripper Rail | M20: 3.43 | N20: Ton | O20: 1687500 | R20: =O20*M20 -> 5788125
L21: Grizzly Bar | M21: 13.39 | N21: Ton | O21: 13750000 | R21: =O21*M21 -> 184112500
L22: Safety Fence | M22: 7.7 | N22: Ton | O22: 5000000 | R22: =O22*M22 -> 38500000
L23: WalkWay | M23: 5 | N23: Ton | O23: 4500000 | R23: =M23*O23 -> 22500000
B24: 합계 | H24: =SUM(H9:H23) -> 956600000 | L24: 합계 | R24: =SUM(R9:R23) -> 729551250 | V24: 합계 | AB24: =SUM(AB9:AB23) -> 0
H26: =H24+H51+H78+H91 -> 2.695488e+09 | R26: =R24+S50+S69+S77 -> 1.9822711e+09
B30: 플랜텍 견적 | L30: 포스코 이앤씨 견적
B33: [ 기계공사 ] | I33: ( 단위 : 원, 단가/금액) | L33: [ 기계공사 ] | S33: ( 단위 : 원, 단가/금액)
B34: 항목 | C34: 수량 | D34: 단위 | E34: 재료비 | F34: 노무비 | G34: 경 비 | H34: 계 | I34: 비고 | L34: 항목 | M34: 수량 | N34: 단위 | O34: 재료비 | P34: 노무비 | Q34: 경 비 | R34: 단가 | S34: 총액
B35: 강재류 조립설치 | C35: 76.153 | D35: Ton | E35: 201957 | F35: 275055724 | G35: 6975185 | H35: 282232866 | L35: 기기 강재류 철거 | M35: 98.582 | N35: Ton | R35: 657885 | S35: =M35*R35 -> 64855619
B36: Duct 설치 | C36: 31.272 | D36: Ton | E36: 82933 | F36: 89058653 | G36: 2258432 | L36: 강재류 조립 설치 0.5Ton 미만 | M36: 46.852 | N36: Ton | R36: 5420440 | S36: =M36*R36 -> 2.5395845e+08
B37: 강재Stand 설치 | C37: 2.85 | D37: Ton | E37: 7558 | F37: 3581352 | G37: 90818 | H37: 3679728 | L37: 강재류 조립 설치 5~10Ton | M37: 52 | N37: Ton | R37: 3336809 | S37: =M37*R37 -> 173514068
B38: Rail 설치 | C38: 3.624 | D38: Ton | E38: 226666 | F38: 9505723 | G38: 475298 | H38: 10207687 | L38: 가설강재 제작 | M38: 10 | N38: Ton | R38: 5251831 | S38: =M38*R38 -> 52518310
B39: 강재류 이설 | C39: 10 | D39: Ton | E39: 26520 | F39: 50819960 | G39: 1288750 | H39: 52135230 | L39: 가설강재 설치 | M39: 10 | N39: Ton | R39: 3753072 | S39: =M39*R39 -> 37530720
B40: 강재류 제작 | C40: 37.482 | D40: Ton | E40: 3520400 | F40: 180247484 | G40: 6752744 | H40: 190520628 | L40: 가설강재 철거 | M40: 10 | N40: Ton | R40: 657885 | S40: =M40*R40 -> 6578850
B41: 도장공사 | C41: 1 | D41: 식 | E41: 1173240 | F41: 28031084 | G41: 509730 | H41: 29714054 | L41: 200 Ton H/C | M41: 5 | N41: 개월 | R41: 45000000 | S41: =M41*R41 -> 225000000
B42: 가설공사(강관비계 포함) | C42: 1 | D42: 식 | E42: 793263 | F42: 19180463 | G42: 228313455 | H42: 248287181 | L42: 100 Ton H/C | M42: 2 | N42: 개월 | R42: 30000000 | S42: =M42*R42 -> 60000000
B43: 전담안전관리자 | C43: 30 | D43: MD | G43: 9029400 | H43: 9029400 | I43: A | L43: 25Ton Cargo | M43: 8 | N43: 개월 | R43: 15000000 | S43: =M43*R43 -> 120000000
B44: 장비비(300톤 크레인 외) | C44: 1 | D44: 식 | E44: 0 | F44: 0 | G44: 484812500 | H44: 484812500 | I44: A | L44: 화재감시자 | M44: 200 | N44: MD | R44: 164387 | S44: =M44*R44 -> 32877400
B45: 기계기타 | C45: 1 | D45: 식 | E45: 2996752 | F45: 7032112 | G45: 4970160 | H45: 14999024 | L45: 장비신호수 | M45: 400 | N45: MD | R45: 164387 | S45: =M45*R45 -> 65754800
B46: 강재류 조립철거 | C46: 76.153 | D46: Ton | E46: 201957 | F46: 68763872 | G46: 1743795 | H46: 70709624 | L46: 강관비계매기(3개월) | M46: 2000 | N46: MD | R46: 19013 | S46: =M46*R46 -> 38026000
B47: Duct 철거 | C47: 31.272 | D47: Ton | E47: 82933 | F47: 22264632 | G47: 564584 | L47: 안전발판 400×1,829(3개월) | M47: 300 | N47: 장 | R47: 7938 | S47: =M47*R47 -> 2381400
B48: 기기강재류 철거 | C48: 2.85 | D48: Ton | E48: 5759 | F48: 349438 | G48: 8860 | H48: 364057 | L48: 가설형강류/철판 | M48: 10 | N48: Ton | R48: 1200000 | S48: =M48*R48 -> 12000000
B49: Rail 철거 | C49: 3.624 | D49: Ton | E49: 226666 | F49: 3544790 | G49: 324134 | H49: 4095590 | L49: 기타 재료비 | M49: 1 | N49: 식 | R49: 2000000 | S49: =M49*R49 -> 2000000
B50: 철거재 운반 등 | C50: 113.9 | D50: Ton | E50: 52279 | F50: 6863895 | G50: 7770939 | H50: 14687113 | L50: (공종 도급계) | S50: =SUM(S35:S49) -> 1.1469956e+09
B51: (공종 도급계) | E51: =SUM(E35:E50) -> 9598883 | F51: =SUM(F35:F50) -> 764299182 | G51: =SUM(G35:G50) -> 755888784 | H51: =SUM(H35:H50) -> 1415474682
...

Sheet 검토 내역_포스코 이앤씨
A2: [투자비 검토 내역] | I2: 포스코이앤씨 | K2: 플랜텍 | N2: 공급사 (3) | Q2: 검토 적용가 | T2: (단위 : 원, VAT별도)
A3: 구분 | B3: No. | C3: 품목 | D3: Spec. | E3: 중량(Ton) | F3: 단위 | G3: 수량 | H3: 단가 | I3: 합계 | J3: 비고 | K3: 단가 | L3: 합계 | M3: 비고 | N3: 단가 | O3: 합계 | P3: 비고 | Q3: 단가 | R3: 합계 | S3: 비고 | T3: 비고
A4: 설비비 | B4: 1) | C4: Idler(B-315 B.C, B-416 B.C) | E4: =SUM(E5:E8) -> 5.42 | F4: Set | G4: =SUM(G5:G8) -> 162 | H4: =SUM(H5:H8) -> 0 | I4: =SUM(I5:I8) -> 0 | J4: 사급자재 | K4: =SUM(K5:K8) -> 0 | L4: =SUM(L5:L8) -> 0 | M4: 사급자재
B5: 1 | C5: Carrier | E5: 4.62 | F5: Set | G5: 110
B6: 2 | C6: Return | E6: 0.48 | F6: Set | G6: 44
B7: 3 | C7: C/SELF ALIGN | E7: 0.16 | F7: Set | G7: 4
B8: 4 | C8: R/SELF ALIGN | E8: 0.16 | F8: Set | G8: 4
A9: 설비비 | B9: 2) | C9: Steel Structure(B-315 B.C, B-416 B.C) | E9: =SUM(E10:E13) -> 76.52 | F9: Set | G9: 8 | H9: =SUM(H10:H13) -> 25250000 | I9: =SUM(I10:I13) -> 707051250
B10: 1 | C10: Tripper Girder Frame | D10: SS275 | E10: 52 | F10: Set | G10: 10 | H10: 4812500 | I10: =H10*E10 -> 250250000
C11: Tripper Rail(22kg) | E11: 3.43 | F11: Lot | G11: 2 | H11: 1687500 | I11: =E11*H11*G11 -> 11576250
C12: Grizzly Bar(Hard Facing 5t) | E12: 13.39 | F12: Lot | G12: 2 | H12: 13750000 | I12: =E12*H12*G12 -> 368225000
C13: Safety Fence | E13: 7.7 | F13: Lot | G13: 2 | H13: 5000000 | I13: =E13*H13*G13 -> 77000000
A14: 설비비 | B14: 3) | C14: 기타 | E14: 5 | F14: Lot | G14: 1 | H14: =SUM(H15:H18) -> 4500000 | I14: =SUM(I15:I18) -> 22500000
B15: 1 | C15: Roof Walkway | E15: 5 | F15: Lot | G15: 1 | H15: 4500000 | I15: =E15*H15 -> 22500000
A19: 설비비 | B19: 4) | C19: 기타설비 | F19: Set | G19: 1
B20: 1 | C20: Safety Fence | E20: 7.7 | F20: Ton | G20: 2 | H20: 5000000 | I20: =H20*E20*G20 -> 77000000
A35: 설비비 합계 | I35: =I9+I4+I14+I19 -> 729551250 | L35: =L9+L4+L14+L19 -> 0 | O35: =O9+O4+O14+O19 -> 0 | R35: =R9+R4+R14+R19 -> 0
A36: 공사비 | B36: 5) | C36: 설치공사 | F36: 식 | G36: 1 | I36: =I37+I49+I64 -> 1.2906148e+09 | L36: =SUM(L37:L47) -> 0 | O36: =SUM(O37:O47) -> 0
B37: 1 | C37: 기계공사 | F37: 식 | G37: 1 | I37: =SUM(I38:I48)*1.1 -> 1.1796985e+09 | J37: 재경비 10% 반영
C38: Tripper Car 및 간섭구조물 철거 후 신설 | D38: 기기강재류 철거 | E38: 98.582 | F38: Ton | H38: 657885 | I38: =E38*H38 -> 64855619
D39: 강재류 조립 설치 0.5Ton 미만 | E39: 46.582 | F39: Ton | H39: 5420440 | I39: =E39*H39 -> 2.5249494e+08
D40: 강재류 조립 설치 5~10Ton | E40: 52 | F40: Ton | H40: 3336809 | I40: =E40*H40 -> 173514068
C41: 장비비 | D41: 200Ton/ H/C | E41: 5 | F41: 월 | H41: 45000000 | I41: =E41*H41 -> 225000000
D42: 100Ton H/C | E42: 2 | F42: 월 | H42: 30000000 | I42: =E42*H42 -> 60000000
D43: 25Ton 카고 | E43: 8 | F43: 월 | H43: 15000000 | I43: =E43*H43 -> 120000000
C44: 안전관리비 | D44: 화재감시자 | E44: 200 | F44: MD | H44: 164387 | I44: =E44*H44 -> 32877400
D45: 신호수 | E45: 400 | F45: MD | H45: 164387 | I45: =E45*H45 -> 65754800
D46: 전담안전관리자 | E46: 400 | F46: MD | H46: 164387 | I46: =E46*H46 -> 65754800
C47: 가설비계(배관/기계용) | D47: 강관비계매기(3개월) | E47: 600 | F47: ㎡ | H47: 19013 | I47: =E47*H47 -> 11407800
D48: 안전발판 400×1,829(3개월) | E48: 100 | F48: 장 | H48: 7938 | I48: =E48*H48 -> 793800
B49: 2 | C49: 건축공사 | I49: =SUM(I50:I63) -> 98863649
C50: 철골가공조립 | E50: 6.05 | F50: Ton | H50: 2796442 | I50: =E50*H50 -> 16918474
C51: 철골세우기 | E51: 6.15 | F51: Ton | H51: 960850 | I51: =E51*H51 -> 5909227.5
C52: 부대철골가공설치 | E52: 5.56 | F52: Ton | H52: 2653000 | I52: =E52*H52 -> 14750680
C53: 철물제작설치 | E53: 1.62 | F53: Ton | H53: 6180000 | I53: =E53*H53 -> 10011600
C54: Color Sheet 신설 | E54: 133.8 | F54: ㎡ | H54: 49150 | I54: =E54*H54 -> 6576270
C55: 도장 | E55: 42 | F55: ㎡ | H55: 12022 | I55: =E55*H55 -> 504924
C56: 철골철거 | D56: Purlin 철거 포함 | E56: 11.61 | F56: Ton | H56: 1142744 | I56: =E56*H56 -> 13267258
C57: Color Sheet 철거 | E57: 133.8 | F57: ㎡ | H57: 27008 | I57: =E57*H57 -> 3613670.4
C58: 장비비 | D58: 200Ton H/C | E58: 0.3 | F58: 월 | H58: 45000000 | I58: =E58*H58 -> 13500000
...

Sheet 도면 비교 검토
B2: 기계공사
B3: 구분(대분류) | C3: 구분(하위) | D3: Ton | E3: 개소 | F3: 물량(m,Ton 등) | G3: 단가 | H3: 투자비 | I3: 비고
B4: Idler(B-315 B.C, B-416 B.C) | C4: 1. Belt Idler
C5: - (자재비) Cariier | D5: 4.62 | E5: 110 | F5: - | G5: - | H5: - | I5: 사급자재로, 운전부서에서 자재 제공 → 설치/철거비만 반영
C6: - (자재비) Return | D6: 0.96 | E6: 44 | F6: - | G6: - | H6: -
C7: - (자재비) C/Self Align | D7: 0.32 | E7: 4 | F7: - | G7: - | H7: -
C8: - (자재비) R/Self Align | D8: 0.32 | E8: 4 | F8: - | G8: - | H8: -
C9: - 철거비 | D9: 6.22 | E9: 162 | F9: 6.22 | G9: ='#설치품'!L17 -> 3369748.6 | H9: =F9*G9 -> 20959836 | I9: *강재류 조립설치(0.5~1Ton 미만)
C10: - 설치비 | D10: 6.22 | E10: 162 | F10: 6.22 | G10: ='#설치품'!L96 -> 499752.35 | H10: =F10*G10 -> 3108459.6 | I10: *기기 강재류 철거
C11: 합계 | H11: =SUM(H5:H10) -> 24068296
B12: Steel Structure(B-315 B.C, B-416 B.C) | C12: 1. Tripper Girder Frame | H12: =SUM(H13:H16) -> 3.3603451e+08
C13: - 자재비 | D13: 3.15 | E13: 10 | F13: =D13*E13 -> 31.5 | G13: 1300000 | H13: =F13*G13 -> 40950000 | I13: *도면상에는,1EA 3.15Ton 가량으로 산출 // SS275 기준
C14: - 제작비 | D14: 3.15 | E14: 10 | F14: =D14*E14 -> 31.5 | G14: ='#제작품'!M20 -> 5937793.7 | H14: =F14*G14 -> 1.870405e+08 | I14: *제작공사 Frame류 2.5~5.0Ton
C15: - 설치비 | D15: 3.15 | E15: 10 | F15: =D15*E15 -> 31.5 | G15: ='#설치품'!L18 -> 2930216.2 | H15: =F15*G15 -> 92301809 | I15: *강재류조립설치 (1~5Ton 미만)
C16: - 철거비 | D16: 3.15 | E16: 10 | F16: =D16*E16 -> 31.5 | G16: ='#설치품'!L96 -> 499752.35 | H16: =F16*G16 -> 15742199
C17: 2. Tripper Rail(22kg/m) | H17: =SUM(H18:H20) -> 1.8668718e+08
C18: - 자재비 | D18: 4.84 | E18: =55*4 -> 220 | F18: =E18 -> 220 | G18: 720790 | H18: =G18*F18 -> 158573800 | I18: * Q-Code 산출 (Q1114110, 720,790원)
C19: - 설치비 | D19: 4.84 | E19: =55*4 -> 220 | F19: =E19 -> 220 | G19: ='#설치품'!L85 -> 5308796.4 | H19: =D19*G19 -> 25694575
C20: - 철거비 | D20: 4.84 | E20: =55*4 -> 220 | F20: =E20 -> 220 | G20: ='#설치품'!L96 -> 499752.35 | H20: =D20*G20 -> 2418801.4
C21: 3. Grizzly Bar(Hard Facing 5t) | H21: =SUM(H22:H24) -> 4.9186739e+08
C22: - 자재비 | D22: 0.1429 | E22: 220 | F22: =D22*E22 -> 31.438 | G22: =1620000 -> 1620000 | H22: =E22*G22 -> 356400000 | I22: * Q-Code 산출 (Q4027673, 1,620,000원)
C23: - 설치비 | D23: 0.1429 | E23: 220 | F23: =D23*E23 -> 31.438 | G23: ='#설치품'!L16 -> 3809281 | H23: =F23*G23 -> 1.1975618e+08
C24: - 철거비 | D24: 0.1429 | E24: 220 | F24: =D24*E24 -> 31.438 | G24: ='#설치품'!L96 -> 499752.35 | H24: =F24*G24 -> 15711214
C25: 4. Safety Fence | H25: =D26*G26 -> 28305888
C26: - 이설비(철거 후 재설치) | D26: 9.24 | E26: 1 | F26: 1 | G26: ='#설치품'!L92 -> 3063407.8 | H26: =D26*G26 -> 28305888 | I26: * 강재류 조립설치(5~10 Ton 미만)
C27: 합계 | H27: =H25+H21+H17+H12 -> 1.042895e+09
B28: Duct(B-315 B.C, B-416 B.C) | C28: 1. Duct Assembley
C29: - 자재 및 제작비
C30: - 설치비
C31: - 철거비
C32: - Damper 제작(Manual 및 Auto)
C33: 합계
B34: Safety Fence | C34: 1. Safety Fence
C35: - 이설(철거 후 재설치) | D35: 10 | E35: 1 | F35: =D35*E35 -> 10 | G35: ='#설치품'!L92 -> 3063407.8 | H35: =G35*F35 -> 30634078 | I35: *강재류 조립설치 (5~10ton 미만)
C36: 합계 | H36: =H35 -> 30634078
B37: 공사비(장비, 안전관리비 등) | C37: 1 . 장비비 | H37: =SUM(H38:H40) -> 405000000
C38: - 200Ton H/C | D38: 45000000 | E38: 5 | F38: 월 | H38: =D38*E38 -> 225000000
C39: - 100Ton H/C | D39: 30000000 | E39: 2 | F39: 월 | H39: =D39*E39 -> 60000000
C40: - 25Ton 카고 | D40: 15000000 | E40: 8 | F40: 월 | H40: =D40*E40 -> 120000000
C41: 2. 안전관리비 | H41: =SUM(H42:H44) -> 164387000
...

Sheet 내역비교(이앤씨, 플랜텍) (2)
B2: 항목 | C2: 수량 | D2: 단위 | E2: 재료비 | F2: 노무비 | G2: 경 비 | H2: 계 | I2: 비고
B5: 강재Stand 설치 | C5: 2.85 | D5: Ton | E5: 7558 | F5: 3581352 | G5: 90818 | H5: 3679728
B8: 강재류 제작 | C8: 37.482 | D8: Ton | E8: 3520400 | F8: 180247484 | G8: 6752744 | H8: 190520628 | J8: stpper,잔넬, 에이치 빔 덕트 서포트 브라켓 헤드 풀레 프레임 핸드레일 그레이팅 덱크
B9: 도장공사 | C9: 1 | D9: 식 | E9: 1173240 | F9: 28031084 | G9: 509730 | H9: 29714054
B10: 가설공사(강관비계 포함) | C10: 1 | D10: 식 | E10: 793263 | F10: 19180463 | G10: 228313455 | H10: 248287181
B12: DAMPER 제작(Manual 및 Auto) | C12: 1 | D12: 식 | E12: 0 | F12: 0 | G12: 68700000 | H12: 68700000 | I12: A
B15: GRIZZLY BAR 제작 | C15: 15 | D15: Ton | E15: 0 | F15: 0 | G15: 700800000 | H15: 700800000 | I15: A
B16: 전담안전관리자 | C16: 30 | D16: MD | G16: 9029400 | H16: 9029400 | I16: A
B17: 장비비(300톤 크레인 외) | C17: 1 | D17: 식 | E17: 0 | F17: 0 | G17: 484812500 | H17: 484812500 | I17: A
B18: 기계기타 | C18: 1 | D18: 식 | E18: 2996752 | F18: 7032112 | G18: 4970160 | H18: 14999024
B21: 기기강재류 철거 | C21: 2.85 | D21: Ton | E21: 5759 | F21: 349438 | G21: 8860 | H21: 364057
B23: 철거재 운반 등 | C23: 113.9 | D23: Ton | E23: 52279 | F23: 6863895 | G23: 7770939 | H23: 14687113
B24: (공종 도급계) | E24: =SUM(E3:E23) -> 8549251 | F24: =SUM(F3:F23) -> 245285828 | G24: =SUM(G3:G23) -> 1511758606 | H24: =SUM(H3:H23) -> 1765593685
B26: Duct 제작 | C26: 1 | D26: 식 | E26: 0 | F26: 0 | G26: 228200000 | H26: 228200000 | I26: A
B27: Duct 설치 | C27: 31.272 | D27: Ton | E27: 82933 | F27: 89058653 | G27: 2258432 | H27: 91400018
B28: Duct 철거 | C28: 31.272 | D28: Ton | E28: 82933 | F28: 22264632 | G28: 564584 | H28: 22912149
B30: RAIL 제작 | C30: 1 | D30: 식 | E30: 0 | F30: 0 | G30: 27600000 | H30: 27600000 | I30: A
B31: Rail 설치 | C31: 3.624 | D31: Ton | E31: 226666 | F31: 9505723 | G31: 475298 | H31: 10207687
B32: Rail 철거 | C32: 3.624 | D32: Ton | E32: 226666 | F32: 3544790 | G32: 324134 | H32: 4095590
B34: GIRDER 제작 | C34: 1 | D34: 식 | E34: 0 | F34: 0 | G34: 228200000 | H34: 228200000 | I34: A | J34: girder 자재비
B35: 강재류 조립설치 | C35: 76.153 | D35: Ton | E35: 201957 | F35: 275055724 | G35: 6975185 | H35: 282232866 | J35: 아이들러 설치
B36: 강재류 조립철거 | C36: 76.153 | D36: Ton | E36: 201957 | F36: 68763872 | G36: 1743795 | H36: 70709624
B38: 강재류 이설 | C38: 10 | D38: Ton | E38: 26520 | F38: 50819960 | G38: 1288750 | H38: 52135230 | J38: 도면 안전펜스

Sheet 기계_제경비 내역서
B1: '25. 01. 01.부 시행 | Q1: 투자부서에서는 파란색 점선영역과 순공사비내역서 노란색 영역을 기입하여 구매부서로 구매의뢰시 첨부 (File Naming Rule : YYMMDD_부서명_제경비내역서 초안_투자명)
Q2: 산업안전보건관리비를 산출하여 구매부서로 구매의뢰시 첨부 (File Naming Rule : YYMMDD_부서명_제경비내역서 초안_투자명)
B3: ○ 계약건명 : | E3: 포)3FINEX 수처리 RTO 소각로 노후교체 | Q3: 공급사에서 노란색셀에 Data를 제경비요율표 및 가이드라인 확인 후 입력
B4: 제 경 비(설치비) 내 역 서 | P4: 1. 산업안전보건관리비 계산산식 : 대상액 구분 가능여부와 현장 제작설비 여부에 따른 구분, 해당부분에만 숫자 1입력
B5: 구 분 | G5: 계산근거 | N5: 공사비 | P5: 2. 공사기간 : 해당 공사기간입력
B6: 사 업 명 : | P6: 3. 공사구분 : 해당 공사구분에만 숫자 1 입력 (ex) 기계,전기, 토목, 건축 등 복합공종인 경우 주공종 1개에만 숫자 1입력)
B7: 1. 도급 재료비 | P7: 4. 요율 : 제경비 요율표를 참조하여 해당 건설하도급대금지급보증비 요율과 건설기계대여금 지급보증비 요율 합해 %를 제외한 숫자 셋째짜리까지 기입
B8: 재료비 계 | N8: ='기계_순공사비 내역서 '!L54 -> 21219299 | P8: 5. 환경보전비 0.4% 고정(단, 전기,정보통신,소방공사는 0 입력)
B9: 2. 노무비 | V9: [간접노무비 요율표] | AD9: [간접노무비 요율표]
C10: 가) 직접노무비 | N10: ='기계_순공사비 내역서 '!L116 -> 151528900 | P10: [산업안전보건관리비 계산산식] | V10: 금액/개월 | Y10: 토목,건축 | AA10: 기계,전기 | AD10: 토목,건축 | AH10: 기계,전기
C11: 나) 간접노무비 | G11: (직접노무비) × 간접노무비율 | P11: 대상액 구분가능 or 완제품설비 | Q11: 대상액 구분불가 or 현장제작설비 | Y11: 금액 | Z11: 기간 | AA11: 금액 | AB11: 기간 | AD11: 금액 | AE11: 요율 | AF11: 기간 | AG11: 요율 | AH11: 금액 | AI11: 요율 | AJ11: 기간 | AK11: 요율 | AM11: [건설기계대여지급보증비 요율표]
G12: =N10 -> 151528900 | J12: × | K12: =Q35 -> 11 | L12: = | N12: =INT((G12)*K12/100) -> 16668179 | P12: 1 | V12: 5억원미만 / 6개월미만 | Y12: 0.15 | Z12: 0.13 | AA12: 0.12 | AB12: 0.1 | AD12: 0 | AE12: 15 | AF12: 0 | AG12: 13 | AH12: 0 | AI12: 12 | AJ12: 0 | AK12: 10 | AM12: 1. 발주자와 종합건설업자가 계약시 적용요율
P13: [공사기간] | V13: 5억원~20억원미만 / 6~18개월 | Y13: 0.14 | Z13: 0.14 | AA13: 0.11 | AB13: 0.11 | AD13: 500000000 | AE13: 14 | AF13: 6 | AG13: 14 | AH13: 500000000 | AI13: 11 | AJ13: 6 | AK13: 11 | AM13: 토목공사(토목·건축공사 포함) | AU13: 0.004
B14: 노무비 계 | N14: =SUM(N10,N12) -> 168197079 | P14: 3 | Q14: 개월 | V14: 20억원이상 / 18개월이상 | Y14: 0.13 | Z14: 0.15 | AA14: 0.1 | AB14: 0.12 | AD14: 2000000000 | AE14: 13 | AF14: 18 | AG14: 15 | AH14: 2000000000 | AI14: 10 | AJ14: 18 | AK14: 12 | AM14: 건축공사 | AU14: 0.0007
B15: 3. 경비 | P15: [투자구분] | V15: [고용보험료 요율표] | AD15: [고용보험료 요율표] | AE15: 토건 | AG15: 건축 | AM15: 산업·환경설비공사 | AU15: 0.0016
B16: 경비 | N16: ='기계_순공사비 내역서 '!L136 -> 62432867 | P16: 프로젝트성 | Q16: 정비성 | V16: 등 급 별 (추정금액) (단위 : 미만 ~ 이상) | AA16: 2024년도 | AD16: 금액 | AE16: 요율 | AF16: 등급 | AG16: 금액 | AH16: 요율 | AI16: 등급 | AM16: 조경공사 | AU16: 0.0018
C17: 가) 보험료 (산재보험) | G17: (직접노무비 ＋ 간접노무비) × 산재보험율 | Q17: 1 | V17: 1 등급 : | W17: 토목 1400억이상 | Y17: 건축 1200억 이상 | AA17: 0.0157 | AD17: 0 | AE17: 1.01 | AF17: 7 | AG17: 0 | AH17: 1.01 | AI17: 7 | AM17: 2. 발주자와 전문건설업자가 계약시 적용요율
G18: =N10 -> 151528900 | H18: ＋ | I18: =N12 -> 16668179 | J18: × | K18: =Q36 -> 3.56 | L18: = | N18: =INT((G18+I18)*K18/100) -> 5987816 | P18: [공사구분 : 공사비] | V18: 2 등급 : | W18: 토목 1400억~900억 | Y18: 건축 1200억~900억 | AA18: 0.013 | AD18: 14000000000 | AE18: 1.02 | AF18: 6 | AG18: 13000000000 | AH18: 1.02 | AI18: 6 | AM18: A 그룹 : | AN18: 준설공사, 포장공사, 토공사, 비계·구조물해체공사 | AU18: 0.0068
F19: (고용보험) | G19: (직접노무비 ＋ 간접노무비) × 고용보험율 | P19: 토목 | Q19: 건축 | S19: 기계 | T19: 전기 | V19: 3 등급 : | W19: 토목 900억~570억 | Y19: 건축 800억~520억 | AA19: 0.0113 | AD19: 22000000000 | AE19: 1.03 | AF19: 5 | AG19: 21000000000 | AH19: 1.03 | AI19: 5 | AM19: B 그룹 : | AN19: 상·하수도설비공사, 수중공사, 보링·그라우팅공사 | AU19: 0.0051
G20: =N10 -> 151528900 | H20: ＋ | I20: =N12 -> 16668179 | J20: × | K20: =Q37 -> 1.01 | L20: = | N20: =INT((G20+I20)*K20/100) -> 1698790 | S20: 1 | V20: 4 등급 : | W20: 토목 570억~370억 | Y20: 건축 520억~340억 | AA20: 0.01063 | AD20: 37000000000 | AE20: 1.06 | AF20: 4 | AG20: 34000000000 | AH20: 1.06 | AI20: 4 | AM20: C 그룹 : | AN20: 석공사, 시설물유지관리, 철근·콘크리트공사, 가스시설공사(1종) | AU20: 0.0032
F21: (국민연금) | G21: (직접노무비) × 국민연금율 | P21: [공사구분 : 공사비+설비비] | V21: 5 등급 : | W21: 토목 370억~220억 | Y21: 건축 340억~210억 | AA21: 0.0103 | AD21: 57000000000 | AE21: 1.13 | AF21: 3 | AG21: 52000000000 | AH21: 1.13 | AI21: 3 | AM21: D 그룹 : | AN21: 조경시설물설치, 조경식재, 도장공사, 철도궤도, 철강재설치공사 | AU21: 0.0016
G22: =N10 -> 151528900 | J22: × | K22: =Q38 -> 4.5 | L22: = | N22: =INT((G22)*K22/100) -> 6818800 | P22: 토목 | Q22: 건축 | S22: 기계 | T22: 전기 | V22: 6 등급 : | W22: 토목 220억~140억 | Y22: 건축 210억~130억 | AA22: 0.0102 | AD22: 90000000000 | AE22: 1.3 | AF22: 2 | AG22: 80000000000 | AH22: 1.3 | AI22: 2 | AM22: E 그룹 : | AN22: A그룹～D그룹 이외의 공사 | AU22: 0.001
F23: (건강보험) | G23: (직접노무비) × 건강보험율 | S23: 1 | V23: 7 등급 : | W23: 토목 140억~ 7등급 미만 | Y23: 건축 130억~ 7등급 미만 | AA23: 0.0101 | AD23: 140000000000 | AE23: 1.57 | AF23: 1 | AG23: 120000000000 | AH23: 1.57 | AI23: 1
G24: =N10 -> 151528900 | J24: × | K24: =Q39 -> 3.545 | L24: = | N24: =INT((G24)*K24/100) -> 5371699 | P24: [산업안전보건관리비 요율 구분] | AD24: [산업안전보건관리비 요율표] | AM24: [건설 하도급대금지급보증비 요율표]
F25: (요양보험) | G25: (국민건강보험료) × 노인장기요양보험율 | P25: 플랜트 공사 | Q25: 플랜트 外 공사 | V25: [산업안전보건관리비 요율표] | AD25: 건축공사 | AF25: 토목공사 | AM25: 공사규모 (추정가격) | AU25: 2018년도
G26: =N24 -> 5371699 | J26: × | K26: =Q40 -> 12.95 | L26: = | N26: =INT((G26)*K26/100) -> 695635 | Q26: 1 | V26: 구분 | X26: 건축공사 요율/기초액 | Z26: 토목공사 요율/기초액 | AD26: 금액 | AE26: 요율 | AF26: 금액 | AG26: 요율 | AM26: 50억 미만 | AU26: 0.00081
P27: [공종별 추정비율 : 공급사에서 필히 현장조사 후 입찰 준비하시길 바랍니다] | V27: 2천만원 미만 | X27: 3.11 | Z27: 3.15 | AD27: 0 | AE27: 3.11 | AF27: 0 | AG27: 3.15 | AM27: 50억원～100억원 미만 | AU27: 0.0008
C28: 나) 산업안전보건관리비 | G28: =IF(P12=AE66,AF66,AF67) -> (도급재료비 ＋ 발주자재료비 ＋ 직접노무비) × 산업안전보건관리비율 ＋ 기초액 | N28: =IF(P12=AE70,AF70,AF71) -> (설비비 포함) | P28: 기계 : 100%, 전기 : 0% | V28: 2천만원~5억원 미만 | X28: 3.11 | Z28: 3.15 | AD28: 20000000 | AE28: 3.11 | AF28: 20000000 | AG28: 3.15 | AM28: 100억원～300억원 미만 | AU28: 0.00075
G29: =(N8+'기계_순공사비 내역서 '!L184)*P12+Q53*Q12*0.7 -> 1382675299 | H29: ＋ | I29: =N10*P12 -> 151528900 | J29: × | K29: =((IF((G29+I29)="","",VLOOKUP((G29+I29),AD27:AE31,2,1))*Q26+IF((G29+I29)="","",VLOOKUP((G29+I29),AF27:AG31,2,1))*P26)) -> 2.28 | L29: ＋ | M29: =SUMIF(Z27:Z31,K29,AA27:AA31)+SUMIF(X27:X31,K29,Y27:Y31)+SUMIF(AB27:AB31,K29,AC27:AC31) -> 4325000 | N29: =INT((G29+I29)*K29/100+M29) -> 39304855 | P29: [필수면허] | V29: 5억원~50억원 미만 | W29: G2(1.86%+5,349 천원) | X29: 2.28 | Y29: 4325000 | Z29: 2.53 | AA29: 3300000 | AD29: 500000000 | AE29: 2.28 | AF29: 500000000 | AG29: 2.53 | AM29: 300억원 이상 (최저가낙찰 대상공사) | AR29: - 토목및산업설비 | AU29: 0.00071
G30: =IF(P12=AE68,AF68,AF69) -> ((도급재료비 ＋ 직접노무비) × 산업안전보건관리비율 ＋ 기초액) x 1.2 | N30: =IF(P12=AE72,AF72,AF73) -> (설비비 제외) | P30: 기계공사 면허 | V30: 50억원 이상 | W30: G3(1.97%) | X30: 2.37 | Z30: 2.6 | AD30: 5000000000 | AE30: 2.37 | AF30: 5000000000 | AG30: 2.6 | AR30: - 건축 | AU30: 0.00068
G31: =N8*P12+Q53*Q12*0.7 -> 21219299 | H31: ＋ | I31: =N10*P12 -> 151528900 | J31: × | K31: =((IF((G31+I31)="","",VLOOKUP((G31+I31),AF27:AG31,2,1))*P26+IF((G31+I31)="","",VLOOKUP((G31+I31),AD27:AE31,2,1))*Q26)) -> 3.11 | L31: ＋ | M31: =SUMIF(Z27:Z31,K31,AA27:AA31)+SUMIF(X27:X31,K31,Y27:Y31)+SUMIF(AB27:AB31,K31,AC27:AC31) -> 0 | N31: =INT((G31+I31)*K31/100+M31)*1.2 -> 6446961.6 | V31: 800억원 이상 | W31: G3(1.97%) | X31: 2.64 | Z31: 2.73 | AD31: 80000000000 | AE31: 2.64 | AF31: 80000000000 | AG31: 2.73 | AM31: 턴키(대안)공사 | AU31: 0.00084
B32: 산업안전보건관리비 적용 | N32: 14227829
P33: [요율]
C34: 다) 법정경비(퇴직공제비) | G34: (직접노무비) × 퇴직공제비율 | P34: 구분 | Q34: 요율 | S34: 비고
G35: =N10 -> 151528900 | J35: × | K35: =Q42 -> 2.3 | L35: = | N35: =INT((G35)*K35/100) -> 3485164 | P35: 간접노무비 | Q35: =(IF((N8+N10+N16)="","",VLOOKUP((N8+N10+N16),AD12:AE14,2,1))*P20+IF((N8+N10+N16)="","",VLOOKUP((N8+N10+N16),AD12:AE14,2,1))*Q20+IF((N8+N10+N16)="","",VLOOKUP((N8+N10+N16),AH12:AI14,2,1))*S20+IF((N8+N10+N16)="","",VLOOKUP((N8+N10+N16),AH12:AI14,2,1))*T20+IF((P14)="","",VLOOKUP((P14),AF12:AG14,2,1))*P20+IF((P14)="","",VLOOKUP((P14),AF12:AG14,2,1))*Q20+IF((P14)="","",VLOOKUP((P14),AJ12:AK14,2,1))*S20+IF((P14)="","",VLOOKUP((P14),AJ12:AK14,2,1))*T20)/2 -> 11 | R35: %
P36: 산재보험 | Q36: 3.56 | R36: % | S36: 법정요율 | AF36: 설비비포함 | AG36: =IF(N32=N29,1,0) -> 0
C37: 라) 건설기계대여지급보증비 | G37: (도급재료비 ＋ 직접노무비 ＋ 산출경비 ) × 지급보증비율 | P37: 고용보험 | Q37: =IF((N8+N14+N16)="","",VLOOKUP((N8+N14+N16),AD17:AE23,2,1)) -> 1.01 | R37: % | S37: 법정요율 | AF37: 1.2배 | AG37: =IF(N32=N31,1,0) -> 0
G38: =N8 -> 21219299 | H38: ＋ | I38: =N10 -> 151528900 | J38: ＋ | K38: =N16 -> 62432867 | L38: × | M38: =Q43 -> 0.11 | N38: =INT((G38+I38+K38)*M38/100) -> 258699 | P38: 국민연금 | Q38: 4.5 | R38: % | S38: 법정요율
P39: 건강보험 | Q39: 3.545 | R39: % | S39: 법정요율
C40: 마) 환경보전비 | G40: (도급재료비 ＋ 직접노무비 ＋ 산출경비 ) × 지급보증비율 | P40: 요양보험 | Q40: 12.95 | R40: % | S40: 법정요율 | AF40: =Q58 -> 0 | AG40: =IF(AF40>=80000000000,1,0) -> 0
...

Sheet 기계_순공사비 내역서 
B1: ○ 계약건명 : | E1: ='기계_제경비 내역서'!E3:N3 -> 포)3FINEX 수처리 RTO 소각로 노후교체
B2: ○ 시공사 : | E2: ㈜플랜텍
B3: 순 공 사 비 내 역 서
B4: 구 분 | G4: 품명 | H4: 세부규격 | I4: 단 위 | J4: 수 량 | K4: 단 가 | L4: 금 액 | M4: 비 고
B5: 사 업 명 :
B6: 1. 도급 재료비
G7: RTO 소각설비 신설 공사 | H7: Angle, H-Beam, Pipe Spp(15~200A) | I7: LOT | J7: 1 | K7: 21219299 | L7: =J7*K7 -> 21219299 | M7: Sheet 참고
L30: =INT(J30*K30) -> 0
L31: =INT(J31*K31) -> 0
L32: =INT(J32*K32) -> 0
L33: =INT(J33*K33) -> 0
L34: =INT(J34*K34) -> 0
L35: =INT(J35*K35) -> 0
L36: =INT(J36*K36) -> 0
L37: =INT(J37*K37) -> 0
L38: =INT(J38*K38) -> 0
L39: =INT(J39*K39) -> 0
L40: =INT(J40*K40) -> 0
L41: =INT(J41*K41) -> 0
... L53: =INT(J53*K53) -> 0
B54: 재료비 계 | L54: =SUM(L7:L53) -> 21219299
B55: 2. 직접노무비
G56: RTO 소각설비 신설 공사 | H56: RTO 설비, 배관, 도장, 가설공사 등 | I56: LOT | J56: 1 | K56: 151528900 | L56: =J56*K56 -> 151528900
L91: =K91*J91 -> 0
L92: =K92*J92 -> 0
L93: =K93*J93 -> 0
L94: =K94*J94 -> 0
L95: =K95*J95 -> 0
L96: =INT(J96*K96) -> 0
L97: =INT(J97*K97) -> 0
L98: =INT(J98*K98) -> 0
L99: =INT(J99*K99) -> 0
L100: =INT(J100*K100) -> 0
L101: =INT(J101*K101) -> 0
L102: =INT(J102*K102) -> 0
L103: =INT(J103*K103) -> 0
L104: =INT(J104*K104) -> 0
L105: =INT(J105*K105) -> 0
L106: =INT(J106*K106) -> 0
L107: =INT(J107*K107) -> 0
...

Sheet 기계 철거_제경비 내역서
B1: '25. 01. 01.부 시행 | Q1: 투자부서에서는 파란색 점선영역과 순공사비내역서 노란색 영역을 기입하여 구매부서로 구매의뢰시 첨부 (File Naming Rule : YYMMDD_부서명_제경비내역서 초안_투자명)
Q2: 산업안전보건관리비를 산출하여 구매부서로 구매의뢰시 첨부 (File Naming Rule : YYMMDD_부서명_제경비내역서 초안_투자명)
B3: ○ 계약건명 : | E3: 포)3FINEX 수처리 RTO 소각로 노후교체 | Q3: 공급사에서 노란색셀에 Data를 제경비요율표 및 가이드라인 확인 후 입력
B4: 제 경 비(설치비) 내 역 서 | P4: 1. 산업안전보건관리비 계산산식 : 대상액 구분 가능여부와 현장 제작설비 여부에 따른 구분, 해당부분에만 숫자 1입력
B5: 구 분 | G5: 계산근거 | N5: 공사비 | P5: 2. 공사기간 : 해당 공사기간입력
B6: 사 업 명 : | P6: 3. 공사구분 : 해당 공사구분에만 숫자 1 입력 (ex) 기계,전기, 토목, 건축 등 복합공종인 경우 주공종 1개에만 숫자 1입력)
B7: 1. 도급 재료비 | P7: 4. 요율 : 제경비 요율표를 참조하여 해당 건설하도급대금지급보증비 요율과 건설기계대여금 지급보증비 요율 합해 %를 제외한 숫자 셋째짜리까지 기입
B8: 재료비 계 | N8: ='기계 철거_순공사비 내역서'!L54 -> 62791.902 | P8: 5. 환경보전비 0.4% 고정(단, 전기,정보통신,소방공사는 0 입력)
B9: 2. 노무비 | V9: [간접노무비 요율표] | AD9: [간접노무비 요율표]
C10: 가) 직접노무비 | N10: ='기계 철거_순공사비 내역서'!L116 -> 10452779 | P10: [산업안전보건관리비 계산산식] | V10: 금액/개월 | Y10: 토목,건축 | AA10: 기계,전기 | AD10: 토목,건축 | AH10: 기계,전기
C11: 나) 간접노무비 | G11: (직접노무비) × 간접노무비율 | P11: 대상액 구분가능 or 완제품설비 | Q11: 대상액 구분불가 or 현장제작설비 | Y11: 금액 | Z11: 기간 | AA11: 금액 | AB11: 기간 | AD11: 금액 | AE11: 요율 | AF11: 기간 | AG11: 요율 | AH11: 금액 | AI11: 요율 | AJ11: 기간 | AK11: 요율 | AM11: [건설기계대여지급보증비 요율표]
G12: =N10 -> 10452779 | J12: × | K12: =Q35 -> 11 | L12: = | N12: =INT((G12)*K12/100) -> 1149805 | P12: 1 | V12: 5억원미만 / 6개월미만 | Y12: 0.15 | Z12: 0.13 | AA12: 0.12 | AB12: 0.1 | AD12: 0 | AE12: 15 | AF12: 0 | AG12: 13 | AH12: 0 | AI12: 12 | AJ12: 0 | AK12: 10 | AM12: 1. 발주자와 종합건설업자가 계약시 적용요율
P13: [공사기간] | V13: 5억원~20억원미만 / 6~18개월 | Y13: 0.14 | Z13: 0.14 | AA13: 0.11 | AB13: 0.11 | AD13: 500000000 | AE13: 14 | AF13: 6 | AG13: 14 | AH13: 500000000 | AI13: 11 | AJ13: 6 | AK13: 11 | AM13: 토목공사(토목·건축공사 포함) | AU13: 0.004
B14: 노무비 계 | N14: =SUM(N10,N12) -> 11602584 | P14: 3 | Q14: 개월 | V14: 20억원이상 / 18개월이상 | Y14: 0.13 | Z14: 0.15 | AA14: 0.1 | AB14: 0.12 | AD14: 2000000000 | AE14: 13 | AF14: 18 | AG14: 15 | AH14: 2000000000 | AI14: 10 | AJ14: 18 | AK14: 12 | AM14: 건축공사 | AU14: 0.0007
B15: 3. 경비 | P15: [투자구분] | V15: [고용보험료 요율표] | AD15: [고용보험료 요율표] | AE15: 토건 | AG15: 건축 | AM15: 산업·환경설비공사 | AU15: 0.0016
B16: 경비 | N16: ='기계 철거_순공사비 내역서'!L136 -> 572452 | P16: 프로젝트성 | Q16: 정비성 | V16: 등 급 별 (추정금액) (단위 : 미만 ~ 이상) | AA16: 2024년도 | AD16: 금액 | AE16: 요율 | AF16: 등급 | AG16: 금액 | AH16: 요율 | AI16: 등급 | AM16: 조경공사 | AU16: 0.0018
C17: 가) 보험료 (산재보험) | G17: (직접노무비 ＋ 간접노무비) × 산재보험율 | Q17: 1 | V17: 1 등급 : | W17: 토목 1400억이상 | Y17: 건축 1200억 이상 | AA17: 0.0157 | AD17: 0 | AE17: 1.01 | AF17: 7 | AG17: 0 | AH17: 1.01 | AI17: 7 | AM17: 2. 발주자와 전문건설업자가 계약시 적용요율
G18: =N10 -> 10452779 | H18: ＋ | I18: =N12 -> 1149805 | J18: × | K18: =Q36 -> 3.56 | L18: = | N18: =INT((G18+I18)*K18/100) -> 413052 | P18: [공사구분 : 공사비] | V18: 2 등급 : | W18: 토목 1400억~900억 | Y18: 건축 1200억~900억 | AA18: 0.013 | AD18: 14000000000 | AE18: 1.02 | AF18: 6 | AG18: 13000000000 | AH18: 1.02 | AI18: 6 | AM18: A 그룹 : | AN18: 준설공사, 포장공사, 토공사, 비계·구조물해체공사 | AU18: 0.0068
F19: (고용보험) | G19: (직접노무비 ＋ 간접노무비) × 고용보험율 | P19: 토목 | Q19: 건축 | S19: 기계 | T19: 전기 | V19: 3 등급 : | W19: 토목 900억~570억 | Y19: 건축 800억~520억 | AA19: 0.0113 | AD19: 22000000000 | AE19: 1.03 | AF19: 5 | AG19: 21000000000 | AH19: 1.03 | AI19: 5 | AM19: B 그룹 : | AN19: 상·하수도설비공사, 수중공사, 보링·그라우팅공사 | AU19: 0.0051
G20: =N10 -> 10452779 | H20: ＋ | I20: =N12 -> 1149805 | J20: × | K20: =Q37 -> 1.01 | L20: = | N20: =INT((G20+I20)*K20/100) -> 117186 | S20: 1 | V20: 4 등급 : | W20: 토목 570억~370억 | Y20: 건축 520억~340억 | AA20: 0.01063 | AD20: 37000000000 | AE20: 1.06 | AF20: 4 | AG20: 34000000000 | AH20: 1.06 | AI20: 4 | AM20: C 그룹 : | AN20: 석공사, 시설물유지관리, 철근·콘크리트공사, 가스시설공사(1종) | AU20: 0.0032
F21: (국민연금) | G21: (직접노무비) × 국민연금율 | P21: [공사구분 : 공사비+설비비] | V21: 5 등급 : | W21: 토목 370억~220억 | Y21: 건축 340억~210억 | AA21: 0.0103 | AD21: 57000000000 | AE21: 1.13 | AF21: 3 | AG21: 52000000000 | AH21: 1.13 | AI21: 3 | AM21: D 그룹 : | AN21: 조경시설물설치, 조경식재, 도장공사, 철도궤도, 철강재설치공사 | AU21: 0.0016
G22: =N10 -> 10452779 | J22: × | K22: =Q38 -> 4.5 | L22: = | N22: =INT((G22)*K22/100) -> 470375 | P22: 토목 | Q22: 건축 | S22: 기계 | T22: 전기 | V22: 6 등급 : | W22: 토목 220억~140억 | Y22: 건축 210억~130억 | AA22: 0.0102 | AD22: 90000000000 | AE22: 1.3 | AF22: 2 | AG22: 80000000000 | AH22: 1.3 | AI22: 2 | AM22: E 그룹 : | AN22: A그룹～D그룹 이외의 공사 | AU22: 0.001
F23: (건강보험) | G23: (직접노무비) × 건강보험율 | S23: 1 | V23: 7 등급 : | W23: 토목 140억~ 7등급 미만 | Y23: 건축 130억~ 7등급 미만 | AA23: 0.0101 | AD23: 140000000000 | AE23: 1.57 | AF23: 1 | AG23: 120000000000 | AH23: 1.57 | AI23: 1
G24: =N10 -> 10452779 | J24: × | K24: =Q39 -> 3.545 | L24: = | N24: =INT((G24)*K24/100) -> 370551 | P24: [산업안전보건관리비 요율 구분] | AD24: [산업안전보건관리비 요율표] | AM24: [건설 하도급대금지급보증비 요율표]
F25: (요양보험) | G25: (국민건강보험료) × 노인장기요양보험율 | P25: 플랜트 공사 | Q25: 플랜트 外 공사 | V25: [산업안전보건관리비 요율표] | AD25: 건축공사 | AF25: 토목공사 | AM25: 공사규모 (추정가격) | AU25: 2018년도
G26: =N24 -> 370551 | J26: × | K26: =Q40 -> 12.95 | L26: = | N26: =INT((G26)*K26/100) -> 47986 | Q26: 1 | V26: 구분 | X26: 건축공사 요율/기초액 | Z26: 토목공사 요율/기초액 | AD26: 금액 | AE26: 요율 | AF26: 금액 | AG26: 요율 | AM26: 50억 미만 | AU26: 0.00081
P27: [공종별 추정비율 : 공급사에서 필히 현장조사 후 입찰 준비하시길 바랍니다] | V27: 2천만원 미만 | X27: 3.11 | Z27: 3.15 | AD27: 0 | AE27: 3.11 | AF27: 0 | AG27: 3.15 | AM27: 50억원～100억원 미만 | AU27: 0.0008
C28: 나) 산업안전보건관리비 | G28: =IF(P12=AE66,AF66,AF67) -> (도급재료비 ＋ 발주자재료비 ＋ 직접노무비) × 산업안전보건관리비율 ＋ 기초액 | N28: =IF(P12=AE70,AF70,AF71) -> (설비비 포함) | P28: 기계 : 100%, 전기 : 0% | V28: 2천만원~5억원 미만 | X28: 3.11 | Z28: 3.15 | AD28: 20000000 | AE28: 3.11 | AF28: 20000000 | AG28: 3.15 | AM28: 100억원～300억원 미만 | AU28: 0.00075
G29: =(N8+'기계 철거_순공사비 내역서'!L184)*P12+Q53*Q12*0.7 -> 62791.902 | H29: ＋ | I29: =N10*P12 -> 10452779 | J29: × | K29: =((IF((G29+I29)="","",VLOOKUP((G29+I29),AD27:AE31,2,1))*Q26+IF((G29+I29)="","",VLOOKUP((G29+I29),AF27:AG31,2,1))*P26)) -> 3.11 | L29: ＋ | M29: =SUMIF(Z27:Z31,K29,AA27:AA31)+SUMIF(X27:X31,K29,Y27:Y31)+SUMIF(AB27:AB31,K29,AC27:AC31) -> 0 | N29: =INT((G29+I29)*K29/100+M29) -> 327034 | P29: [필수면허] | V29: 5억원~50억원 미만 | W29: G2(1.86%+5,349 천원) | X29: 2.28 | Y29: 4325000 | Z29: 2.53 | AA29: 3300000 | AD29: 500000000 | AE29: 2.28 | AF29: 500000000 | AG29: 2.53 | AM29: 300억원 이상 (최저가낙찰 대상공사) | AR29: - 토목및산업설비 | AU29: 0.00071
G30: =IF(P12=AE68,AF68,AF69) -> ((도급재료비 ＋ 직접노무비) × 산업안전보건관리비율 ＋ 기초액) x 1.2 | N30: =IF(P12=AE72,AF72,AF73) -> (설비비 제외) | P30: 기계공사 면허 | V30: 50억원 이상 | W30: G3(1.97%) | X30: 2.37 | Z30: 2.6 | AD30: 5000000000 | AE30: 2.37 | AF30: 5000000000 | AG30: 2.6 | AR30: - 건축 | AU30: 0.00068
G31: =N8*P12+Q53*Q12*0.7 -> 62791.902 | H31: ＋ | I31: =N10*P12 -> 10452779 | J31: × | K31: =((IF((G31+I31)="","",VLOOKUP((G31+I31),AF27:AG31,2,1))*P26+IF((G31+I31)="","",VLOOKUP((G31+I31),AD27:AE31,2,1))*Q26)) -> 3.11 | L31: ＋ | M31: =SUMIF(Z27:Z31,K31,AA27:AA31)+SUMIF(X27:X31,K31,Y27:Y31)+SUMIF(AB27:AB31,K31,AC27:AC31) -> 0 | N31: =INT((G31+I31)*K31/100+M31)*1.2 -> 392440.8 | V31: 800억원 이상 | W31: G3(1.97%) | X31: 2.64 | Z31: 2.73 | AD31: 80000000000 | AE31: 2.64 | AF31: 80000000000 | AG31: 2.73 | AM31: 턴키(대안)공사 | AU31: 0.00084
B32: 산업안전보건관리비 적용 | N32: 575681
P33: [요율]
C34: 다) 법정경비(퇴직공제비) | G34: (직접노무비) × 퇴직공제비율 | P34: 구분 | Q34: 요율 | S34: 비고
G35: =N10 -> 10452779 | J35: × | K35: =Q42 -> 2.3 | L35: = | N35: =INT((G35)*K35/100) -> 240413 | P35: 간접노무비 | Q35: =(IF((N8+N10+N16)="","",VLOOKUP((N8+N10+N16),AD12:AE14,2,1))*P20+IF((N8+N10+N16)="","",VLOOKUP((N8+N10+N16),AD12:AE14,2,1))*Q20+IF((N8+N10+N16)="","",VLOOKUP((N8+N10+N16),AH12:AI14,2,1))*S20+IF((N8+N10+N16)="","",VLOOKUP((N8+N10+N16),AH12:AI14,2,1))*T20+IF((P14)="","",VLOOKUP((P14),AF12:AG14,2,1))*P20+IF((P14)="","",VLOOKUP((P14),AF12:AG14,2,1))*Q20+IF((P14)="","",VLOOKUP((P14),AJ12:AK14,2,1))*S20+IF((P14)="","",VLOOKUP((P14),AJ12:AK14,2,1))*T20)/2 -> 11 | R35: %
P36: 산재보험 | Q36: 3.56 | R36: % | S36: 법정요율 | AF36: 설비비포함 | AG36: =IF(N32=N29,1,0) -> 0
C37: 라) 건설기계대여지급보증비 | G37: (도급재료비 ＋ 직접노무비 ＋ 산출경비 ) × 지급보증비율 | P37: 고용보험 | Q37: =IF((N8+N14+N16)="","",VLOOKUP((N8+N14+N16),AD17:AE23,2,1)) -> 1.01 | R37: % | S37: 법정요율 | AF37: 1.2배 | AG37: =IF(N32=N31,1,0) -> 0
G38: =N8 -> 62791.902 | H38: ＋ | I38: =N10 -> 10452779 | J38: ＋ | K38: =N16 -> 572452 | L38: × | M38: =Q43 -> 0.11 | N38: =INT((G38+I38+K38)*M38/100) -> 12196 | P38: 국민연금 | Q38: 4.5 | R38: % | S38: 법정요율
P39: 건강보험 | Q39: 3.545 | R39: % | S39: 법정요율
C40: 마) 환경보전비 | G40: (도급재료비 ＋ 직접노무비 ＋ 산출경비 ) × 지급보증비율 | P40: 요양보험 | Q40: 12.95 | R40: % | S40: 법정요율 | AF40: =Q58 -> 0 | AG40: =IF(AF40>=80000000000,1,0) -> 0
...

Sheet 기계 철거_순공사비 내역서
B1: ○ 계약건명 : | E1: ='기계 철거_제경비 내역서'!E3:N3 -> 포)3FINEX 수처리 RTO 소각로 노후교체
B2: ○ 시공사 : | E2: ㈜플랜텍
B3: 순 공 사 비 내 역 서
B4: 구 분 | G4: 품명 | H4: 세부규격 | I4: 단 위 | J4: 수 량 | K4: 단 가 | L4: 금 액 | M4: 비 고
B5: 사 업 명 :
B6: 1. 도급 재료비
G7: 기존 RTO 설비 철거 | H7: RTO설비 | I7: TON | J7: 34.539 | K7: 1818 | L7: =J7*K7 -> 62791.902
L30: =INT(J30*K30) -> 0
L31: =INT(J31*K31) -> 0
L32: =INT(J32*K32) -> 0
L33: =INT(J33*K33) -> 0
L34: =INT(J34*K34) -> 0
L35: =INT(J35*K35) -> 0
L36: =INT(J36*K36) -> 0
L37: =INT(J37*K37) -> 0
L38: =INT(J38*K38) -> 0
L39: =INT(J39*K39) -> 0
L40: =INT(J40*K40) -> 0
L41: =INT(J41*K41) -> 0
... L53: =INT(J53*K53) -> 0
B54: 재료비 계 | L54: =SUM(L7:L53) -> 62791.902
B55: 2. 직접노무비
G56: 기존 RTO 설비 철거 | H56: RTO설비 | I56: TON | J56: 34.539 | K56: 302637 | L56: =K56*J56 -> 10452779
L57: =K57*J57 -> 0
L58: =K58*J58 -> 0
L59: =K59*J59 -> 0
L60: =K60*J60 -> 0
L61: =K61*J61 -> 0
L62: =K62*J62 -> 0
L63: =K63*J63 -> 0
L64: =K64*J64 -> 0
L65: =K65*J65 -> 0
L66: =K66*J66 -> 0
L67: =K67*J67 -> 0
L68: =K68*J68 -> 0
... L95: =K95*J95 -> 0
L96: =INT(J96*K96) -> 0
L97: =INT(J97*K97) -> 0
L98: =INT(J98*K98) -> 0
L99: =INT(J99*K99) -> 0
...

Sheet 전기_제경비 내역서
B1: '25. 01. 01.부 시행 | Q1: 투자부서에서는 파란색 점선영역과 순공사비내역서 노란색 영역을 기입하여 구매부서로 구매의뢰시 첨부 (File Naming Rule : YYMMDD_부서명_제경비내역서 초안_투자명)
Q2: 산업안전보건관리비를 산출하여 구매부서로 구매의뢰시 첨부 (File Naming Rule : YYMMDD_부서명_제경비내역서 초안_투자명)
B3: ○ 계약건명 : | E3: 포)3FINEX 수처리 RTO 소각로 노후교체 | Q3: 공급사에서 노란색셀에 Data를 제경비요율표 및 가이드라인 확인 후 입력
B4: 제 경 비(설치비) 내 역 서 | P4: 1. 산업안전보건관리비 계산산식 : 대상액 구분 가능여부와 현장 제작설비 여부에 따른 구분, 해당부분에만 숫자 1입력
B5: 구 분 | G5: 계산근거 | N5: 공사비 | P5: 2. 공사기간 : 해당 공사기간입력
B6: 사 업 명 : | P6: 3. 공사구분 : 해당 공사구분에만 숫자 1 입력 (ex) 기계,전기, 토목, 건축 등 복합공종인 경우 주공종 1개에만 숫자 1입력)
B7: 1. 도급 재료비 | P7: 4. 요율 : 제경비 요율표를 참조하여 해당 건설하도급대금지급보증비 요율과 건설기계대여금 지급보증비 요율 합해 %를 제외한 숫자 셋째짜리까지 기입
B8: 재료비 계 | N8: ='전기_순공사비 내역서'!L55 -> 9560180 | P8: 5. 환경보전비 0.4% 고정(단, 전기,정보통신,소방공사는 0 입력)
B9: 2. 노무비 | V9: [간접노무비 요율표] | AD9: [간접노무비 요율표]
C10: 가) 직접노무비 | N10: ='전기_순공사비 내역서'!L105 -> 43989000 | P10: [산업안전보건관리비 계산산식] | V10: 금액/개월 | Y10: 토목,건축 | AA10: 기계,전기 | AD10: 토목,건축 | AH10: 기계,전기
C11: 나) 간접노무비 | G11: (직접노무비) × 간접노무비율 | P11: 대상액 구분가능 or 완제품설비 | Q11: 대상액 구분불가 or 현장제작설비 | Y11: 금액 | Z11: 기간 | AA11: 금액 | AB11: 기간 | AD11: 금액 | AE11: 요율 | AF11: 기간 | AG11: 요율 | AH11: 금액 | AI11: 요율 | AJ11: 기간 | AK11: 요율 | AM11: [건설기계대여지급보증비 요율표]
G12: =N10 -> 43989000 | J12: × | K12: =Q35 -> 11 | L12: = | N12: =INT((G12)*K12/100) -> 4838790 | P12: 1 | V12: 5억원미만 / 6개월미만 | Y12: 0.15 | Z12: 0.13 | AA12: 0.12 | AB12: 0.1 | AD12: 0 | AE12: 15 | AF12: 0 | AG12: 13 | AH12: 0 | AI12: 12 | AJ12: 0 | AK12: 10 | AM12: 1. 발주자와 종합건설업자가 계약시 적용요율
P13: [공사기간] | V13: 5억원~20억원미만 / 6~18개월 | Y13: 0.14 | Z13: 0.14 | AA13: 0.11 | AB13: 0.11 | AD13: 500000000 | AE13: 14 | AF13: 6 | AG13: 14 | AH13: 500000000 | AI13: 11 | AJ13: 6 | AK13: 11 | AM13: 토목공사(토목·건축공사 포함) | AU13: 0.004
B14: 노무비 계 | N14: =SUM(N10,N12) -> 48827790 | P14: 3 | Q14: 개월 | V14: 20억원이상 / 18개월이상 | Y14: 0.13 | Z14: 0.15 | AA14: 0.1 | AB14: 0.12 | AD14: 2000000000 | AE14: 13 | AF14: 18 | AG14: 15 | AH14: 2000000000 | AI14: 10 | AJ14: 18 | AK14: 12 | AM14: 건축공사 | AU14: 0.0007
B15: 3. 경비 | P15: [투자구분] | V15: [고용보험료 요율표] | AD15: [고용보험료 요율표] | AE15: 토건 | AG15: 건축 | AM15: 산업·환경설비공사 | AU15: 0.0016
B16: 경비 | N16: ='전기_순공사비 내역서'!L125 -> 20240614 | P16: 프로젝트성 | Q16: 정비성 | V16: 등 급 별 (추정금액) (단위 : 미만 ~ 이상) | AA16: 2024년도 | AD16: 금액 | AE16: 요율 | AF16: 등급 | AG16: 금액 | AH16: 요율 | AI16: 등급 | AM16: 조경공사 | AU16: 0.0018
C17: 가) 보험료 (산재보험) | G17: (직접노무비 ＋ 간접노무비) × 산재보험율 | Q17: 1 | V17: 1 등급 : | W17: 토목 1400억이상 | Y17: 건축 1200억 이상 | AA17: 0.0157 | AD17: 0 | AE17: 1.01 | AF17: 7 | AG17: 0 | AH17: 1.01 | AI17: 7 | AM17: 2. 발주자와 전문건설업자가 계약시 적용요율
G18: =N10 -> 43989000 | H18: ＋ | I18: =N12 -> 4838790 | J18: × | K18: =Q36 -> 3.56 | L18: = | N18: =INT((G18+I18)*K18/100) -> 1738269 | P18: [공사구분 : 공사비] | V18: 2 등급 : | W18: 토목 1400억~900억 | Y18: 건축 1200억~900억 | AA18: 0.013 | AD18: 14000000000 | AE18: 1.02 | AF18: 6 | AG18: 13000000000 | AH18: 1.02 | AI18: 6 | AM18: A 그룹 : | AN18: 준설공사, 포장공사, 토공사, 비계·구조물해체공사 | AU18: 0.0068
F19: (고용보험) | G19: (직접노무비 ＋ 간접노무비) × 고용보험율 | P19: 토목 | Q19: 건축 | S19: 기계 | T19: 전기 | V19: 3 등급 : | W19: 토목 900억~570억 | Y19: 건축 800억~520억 | AA19: 0.0113 | AD19: 22000000000 | AE19: 1.03 | AF19: 5 | AG19: 21000000000 | AH19: 1.03 | AI19: 5 | AM19: B 그룹 : | AN19: 상·하수도설비공사, 수중공사, 보링·그라우팅공사 | AU19: 0.0051
G20: =N10 -> 43989000 | H20: ＋ | I20: =N12 -> 4838790 | J20: × | K20: =Q37 -> 1.01 | L20: = | N20: =INT((G20+I20)*K20/100) -> 493160 | S20: 1 | V20: 4 등급 : | W20: 토목 570억~370억 | Y20: 건축 520억~340억 | AA20: 0.01063 | AD20: 37000000000 | AE20: 1.06 | AF20: 4 | AG20: 34000000000 | AH20: 1.06 | AI20: 4 | AM20: C 그룹 : | AN20: 석공사, 시설물유지관리, 철근·콘크리트공사, 가스시설공사(1종) | AU20: 0.0032
F21: (국민연금) | G21: (직접노무비) × 국민연금율 | P21: [공사구분 : 공사비+설비비] | V21: 5 등급 : | W21: 토목 370억~220억 | Y21: 건축 340억~210억 | AA21: 0.0103 | AD21: 57000000000 | AE21: 1.13 | AF21: 3 | AG21: 52000000000 | AH21: 1.13 | AI21: 3 | AM21: D 그룹 : | AN21: 조경시설물설치, 조경식재, 도장공사, 철도궤도, 철강재설치공사 | AU21: 0.0016
G22: =N10 -> 43989000 | J22: × | K22: =Q38 -> 4.5 | L22: = | N22: =INT((G22)*K22/100) -> 1979505 | P22: 토목 | Q22: 건축 | S22: 기계 | T22: 전기 | V22: 6 등급 : | W22: 토목 220억~140억 | Y22: 건축 210억~130억 | AA22: 0.0102 | AD22: 90000000000 | AE22: 1.3 | AF22: 2 | AG22: 80000000000 | AH22: 1.3 | AI22: 2 | AM22: E 그룹 : | AN22: A그룹～D그룹 이외의 공사 | AU22: 0.001
F23: (건강보험) | G23: (직접노무비) × 건강보험율 | S23: 1 | V23: 7 등급 : | W23: 토목 140억~ 7등급 미만 | Y23: 건축 130억~ 7등급 미만 | AA23: 0.0101 | AD23: 140000000000 | AE23: 1.57 | AF23: 1 | AG23: 120000000000 | AH23: 1.57 | AI23: 1
G24: =N10 -> 43989000 | J24: × | K24: =Q39 -> 3.545 | L24: = | N24: =INT((G24)*K24/100) -> 1559410 | P24: [산업안전보건관리비 요율 구분] | AD24: [산업안전보건관리비 요율표] | AM24: [건설 하도급대금지급보증비 요율표]
F25: (요양보험) | G25: (국민건강보험료) × 노인장기요양보험율 | P25: 플랜트 공사 | Q25: 플랜트 外 공사 | V25: [산업안전보건관리비 요율표] | AD25: 건축공사 | AF25: 토목공사 | AM25: 공사규모 (추정가격) | AU25: 2018년도
G26: =N24 -> 1559410 | J26: × | K26: =Q40 -> 12.95 | L26: = | N26: =INT((G26)*K26/100) -> 201943 | Q26: 1 | V26: 구분 | X26: 건축공사 요율/기초액 | Z26: 토목공사 요율/기초액 | AD26: 금액 | AE26: 요율 | AF26: 금액 | AG26: 요율 | AM26: 50억 미만 | AU26: 0.00081
P27: [공종별 추정비율 : 공급사에서 필히 현장조사 후 입찰 준비하시길 바랍니다] | V27: 2천만원 미만 | X27: 3.11 | Z27: 3.15 | AD27: 0 | AE27: 3.11 | AF27: 0 | AG27: 3.15 | AM27: 50억원～100억원 미만 | AU27: 0.0008
C28: 나) 산업안전보건관리비 | G28: =IF(P12=AE66,AF66,AF67) -> (도급재료비 ＋ 발주자재료비 ＋ 직접노무비) × 산업안전보건관리비율 ＋ 기초액 | N28: =IF(P12=AE70,AF70,AF71) -> (설비비 포함) | P28: 기계 : 100%, 전기 : 0% | V28: 2천만원~5억원 미만 | X28: 3.11 | Z28: 3.15 | AD28: 20000000 | AE28: 3.11 | AF28: 20000000 | AG28: 3.15 | AM28: 100억원～300억원 미만 | AU28: 0.00075
G29: =(N8+'전기_순공사비 내역서'!L173)*P12+Q53*Q12*0.7 -> 30423180 | H29: ＋ | I29: =N10*P12 -> 43989000 | J29: × | K29: =((IF((G29+I29)="","",VLOOKUP((G29+I29),AD27:AE31,2,1))*Q26+IF((G29+I29)="","",VLOOKUP((G29+I29),AF27:AG31,2,1))*P26)) -> 3.11 | L29: ＋ | M29: =SUMIF(Z27:Z31,K29,AA27:AA31)+SUMIF(X27:X31,K29,Y27:Y31)+SUMIF(AB27:AB31,K29,AC27:AC31) -> 0 | N29: =INT((G29+I29)*K29/100+M29) -> 2314218 | P29: [필수면허] | V29: 5억원~50억원 미만 | W29: G2(1.86%+5,349 천원) | X29: 2.28 | Y29: 4325000 | Z29: 2.53 | AA29: 3300000 | AD29: 500000000 | AE29: 2.28 | AF29: 500000000 | AG29: 2.53 | AM29: 300억원 이상 (최저가낙찰 대상공사) | AR29: - 토목및산업설비 | AU29: 0.00071
G30: =IF(P12=AE68,AF68,AF69) -> ((도급재료비 ＋ 직접노무비) × 산업안전보건관리비율 ＋ 기초액) x 1.2 | N30: =IF(P12=AE72,AF72,AF73) -> (설비비 제외) | P30: 기계공사 면허 | V30: 50억원 이상 | W30: G3(1.97%) | X30: 2.37 | Z30: 2.6 | AD30: 5000000000 | AE30: 2.37 | AF30: 5000000000 | AG30: 2.6 | AR30: - 건축 | AU30: 0.00068
G31: =N8*P12+Q53*Q12*0.7 -> 9560180 | H31: ＋ | I31: =N10*P12 -> 43989000 | J31: × | K31: =((IF((G31+I31)="","",VLOOKUP((G31+I31),AF27:AG31,2,1))*P26+IF((G31+I31)="","",VLOOKUP((G31+I31),AD27:AE31,2,1))*Q26)) -> 3.11 | L31: ＋ | M31: =SUMIF(Z27:Z31,K31,AA27:AA31)+SUMIF(X27:X31,K31,Y27:Y31)+SUMIF(AB27:AB31,K31,AC27:AC31) -> 0 | N31: =INT((G31+I31)*K31/100+M31)*1.2 -> 1998454.8 | V31: 800억원 이상 | W31: G3(1.97%) | X31: 2.64 | Z31: 2.73 | AD31: 80000000000 | AE31: 2.64 | AF31: 80000000000 | AG31: 2.73 | AM31: 턴키(대안)공사 | AU31: 0.00084
B32: 산업안전보건관리비 적용 | N32: 2589110
P33: [요율]
C34: 다) 법정경비(퇴직공제비) | G34: (직접노무비) × 퇴직공제비율 | P34: 구분 | Q34: 요율 | S34: 비고
G35: =N10 -> 43989000 | J35: × | K35: =Q42 -> 2.3 | L35: = | N35: =INT((G35)*K35/100) -> 1011747 | P35: 간접노무비 | Q35: =(IF((N8+N10+N16)="","",VLOOKUP((N8+N10+N16),AD12:AE14,2,1))*P20+IF((N8+N10+N16)="","",VLOOKUP((N8+N10+N16),AD12:AE14,2,1))*Q20+IF((N8+N10+N16)="","",VLOOKUP((N8+N10+N16),AH12:AI14,2,1))*S20+IF((N8+N10+N16)="","",VLOOKUP((N8+N10+N16),AH12:AI14,2,1))*T20+IF((P14)="","",VLOOKUP((P14),AF12:AG14,2,1))*P20+IF((P14)="","",VLOOKUP((P14),AF12:AG14,2,1))*Q20+IF((P14)="","",VLOOKUP((P14),AJ12:AK14,2,1))*S20+IF((P14)="","",VLOOKUP((P14),AJ12:AK14,2,1))*T20)/2 -> 11 | R35: %
P36: 산재보험 | Q36: 3.56 | R36: % | S36: 법정요율 | AF36: 설비비포함 | AG36: =IF(N32=N29,1,0) -> 0
C37: 라) 건설기계대여지급보증비 | G37: (도급재료비 ＋ 직접노무비 ＋ 산출경비 ) × 지급보증비율 | P37: 고용보험 | Q37: =IF((N8+N14+N16)="","",VLOOKUP((N8+N14+N16),AD17:AE23,2,1)) -> 1.01 | R37: % | S37: 법정요율 | AF37: 1.2배 | AG37: =IF(N32=N31,1,0) -> 0
G38: =N8 -> 9560180 | H38: ＋ | I38: =N10 -> 43989000 | J38: ＋ | K38: =N16 -> 20240614 | L38: × | M38: =Q43 -> 0.11 | N38: =INT((G38+I38+K38)*M38/100) -> 81168 | P38: 국민연금 | Q38: 4.5 | R38: % | S38: 법정요율
P39: 건강보험 | Q39: 3.545 | R39: % | S39: 법정요율
C40: 마) 환경보전비 | G40: (도급재료비 ＋ 직접노무비 ＋ 산출경비 ) × 지급보증비율 | P40: 요양보험 | Q40: 12.95 | R40: % | S40: 법정요율 | AF40: =Q58 -> 0 | AG40: =IF(AF40>=80000000000,1,0) -> 0
...

Sheet 전기_순공사비 내역서
B1: ○ 계약건명 : | E1: ='전기_제경비 내역서'!E3:N3 -> 포)3FINEX 수처리 RTO 소각로 노후교체
B2: ○ 시공사 : | E2: ㈜플랜텍
B3: 순 공 사 비 내 역 서
B4: 구 분 | G4: 품명 | H4: 세부규격 | I4: 단 위 | J4: 수 량 | K4: 단 가 | L4: 금 액 | M4: 비 고
B5: 사 업 명 :
B6: 1. 도급 재료비
G7: RTO 소각로 전기설비 | H7: Local Box, Cable, Cable Tray 등 | I7: LOT | J7: 1 | K7: 9560180 | L7: =J7*K7 -> 9560180
L8: =J8*K8 -> 0
L9: =J9*K9 -> 0
L10: =J10*K10 -> 0
L11: =J11*K11 -> 0
L12: =J12*K12 -> 0
L13: =J13*K13 -> 0
L14: =J14*K14 -> 0
L15: =J15*K15 -> 0
L16: =J16*K16 -> 0
L17: =J17*K17 -> 0
L18: =J18*K18 -> 0
L19: =J19*K19 -> 0
... L25: =J25*K25 -> 0
L26: =INT(J26*K26) -> 0
L27: =INT(J27*K27) -> 0
L28: =INT(J28*K28) -> 0
L29: =INT(J29*K29) -> 0
L30: =INT(J30*K30) -> 0
L31: =INT(J31*K31) -> 0
L32: =INT(J32*K32) -> 0
L33: =INT(J33*K33) -> 0
L34: =INT(J34*K34) -> 0
L35: =INT(J35*K35) -> 0
L36: =INT(J36*K36) -> 0
L37: =INT(J37*K37) -> 0
... L54: =INT(J54*K54) -> 0
B55: 재료비 계 | L55: =SUM(L7:L54) -> 9560180
B56: 2. 직접노무비
G57: RTO 소각로 전기설비 이설 | H57: Local Box 이설, Cable 포설, Cable Tray 설치 등 | I57: LOT | J57: 1 | K57: 43989000 | L57: =INT(J57*K57) -> 43989000
L59: =INT(J59*K59) -> 0
L60: =INT(J60*K60) -> 0
L61: =INT(J61*K61) -> 0
L62: =INT(J62*K62) -> 0
...

Sheet 토건_제경비 내역서
B1: '25. 01. 01.부 시행 | Q1: 투자부서에서는 파란색 점선영역과 순공사비내역서 노란색 영역을 기입하여 구매부서로 구매의뢰시 첨부 (File Naming Rule : YYMMDD_부서명_제경비내역서 초안_투자명)
Q2: 산업안전보건관리비를 산출하여 구매부서로 구매의뢰시 첨부 (File Naming Rule : YYMMDD_부서명_제경비내역서 초안_투자명)
B3: ○ 계약건명 : | E3: 포)3FINEX 수처리 RTO 소각로 노후교체 | Q3: 공급사에서 노란색셀에 Data를 제경비요율표 및 가이드라인 확인 후 입력
B4: 제 경 비(설치비) 내 역 서 | P4: 1. 산업안전보건관리비 계산산식 : 대상액 구분 가능여부와 현장 제작설비 여부에 따른 구분, 해당부분에만 숫자 1입력
B5: 구 분 | G5: 계산근거 | N5: 공사비 | P5: 2. 공사기간 : 해당 공사기간입력
B6: 사 업 명 : | P6: 3. 공사구분 : 해당 공사구분에만 숫자 1 입력 (ex) 기계,전기, 토목, 건축 등 복합공종인 경우 주공종 1개에만 숫자 1입력)
B7: 1. 도급 재료비 | P7: 4. 요율 : 제경비 요율표를 참조하여 해당 건설하도급대금지급보증비 요율과 건설기계대여금 지급보증비 요율 합해 %를 제외한 숫자 셋째짜리까지 기입
B8: 재료비 계 | N8: ='토건_순공사비 내역서'!L55 -> 14750000 | P8: 5. 환경보전비 0.4% 고정(단, 전기,정보통신,소방공사는 0 입력)
B9: 2. 노무비 | V9: [간접노무비 요율표] | AD9: [간접노무비 요율표]
C10: 가) 직접노무비 | N10: ='토건_순공사비 내역서'!L107 -> 34484213 | P10: [산업안전보건관리비 계산산식] | V10: 금액/개월 | Y10: 토목,건축 | AA10: 기계,전기 | AD10: 토목,건축 | AH10: 기계,전기
C11: 나) 간접노무비 | G11: (직접노무비) × 간접노무비율 | P11: 대상액 구분가능 or 완제품설비 | Q11: 대상액 구분불가 or 현장제작설비 | Y11: 금액 | Z11: 기간 | AA11: 금액 | AB11: 기간 | AD11: 금액 | AE11: 요율 | AF11: 기간 | AG11: 요율 | AH11: 금액 | AI11: 요율 | AJ11: 기간 | AK11: 요율 | AM11: [건설기계대여지급보증비 요율표]
G12: =N10 -> 34484213 | J12: × | K12: =Q35 -> 11 | L12: = | N12: =INT((G12)*K12/100) -> 3793263 | P12: 1 | V12: 5억원미만 / 6개월미만 | Y12: 0.15 | Z12: 0.13 | AA12: 0.12 | AB12: 0.1 | AD12: 0 | AE12: 15 | AF12: 0 | AG12: 13 | AH12: 0 | AI12: 12 | AJ12: 0 | AK12: 10 | AM12: 1. 발주자와 종합건설업자가 계약시 적용요율
P13: [공사기간] | V13: 5억원~20억원미만 / 6~18개월 | Y13: 0.14 | Z13: 0.14 | AA13: 0.11 | AB13: 0.11 | AD13: 500000000 | AE13: 14 | AF13: 6 | AG13: 14 | AH13: 500000000 | AI13: 11 | AJ13: 6 | AK13: 11 | AM13: 토목공사(토목·건축공사 포함) | AU13: 0.004
B14: 노무비 계 | N14: =SUM(N10,N12) -> 38277476 | P14: 3 | Q14: 개월 | V14: 20억원이상 / 18개월이상 | Y14: 0.13 | Z14: 0.15 | AA14: 0.1 | AB14: 0.12 | AD14: 2000000000 | AE14: 13 | AF14: 18 | AG14: 15 | AH14: 2000000000 | AI14: 10 | AJ14: 18 | AK14: 12 | AM14: 건축공사 | AU14: 0.0007
B15: 3. 경비 | P15: [투자구분] | V15: [고용보험료 요율표] | AD15: [고용보험료 요율표] | AE15: 토건 | AG15: 건축 | AM15: 산업·환경설비공사 | AU15: 0.0016
B16: 경비 | N16: ='토건_순공사비 내역서'!L127 -> 10272271 | P16: 프로젝트성 | Q16: 정비성 | V16: 등 급 별 (추정금액) (단위 : 미만 ~ 이상) | AA16: 2024년도 | AD16: 금액 | AE16: 요율 | AF16: 등급 | AG16: 금액 | AH16: 요율 | AI16: 등급 | AM16: 조경공사 | AU16: 0.0018
C17: 가) 보험료 (산재보험) | G17: (직접노무비 ＋ 간접노무비) × 산재보험율 | Q17: 1 | V17: 1 등급 : | W17: 토목 1400억이상 | Y17: 건축 1200억 이상 | AA17: 0.0157 | AD17: 0 | AE17: 1.01 | AF17: 7 | AG17: 0 | AH17: 1.01 | AI17: 7 | AM17: 2. 발주자와 전문건설업자가 계약시 적용요율
G18: =N10 -> 34484213 | H18: ＋ | I18: =N12 -> 3793263 | J18: × | K18: =Q36 -> 3.56 | L18: = | N18: =INT((G18+I18)*K18/100) -> 1362678 | P18: [공사구분 : 공사비] | V18: 2 등급 : | W18: 토목 1400억~900억 | Y18: 건축 1200억~900억 | AA18: 0.013 | AD18: 14000000000 | AE18: 1.02 | AF18: 6 | AG18: 13000000000 | AH18: 1.02 | AI18: 6 | AM18: A 그룹 : | AN18: 준설공사, 포장공사, 토공사, 비계·구조물해체공사 | AU18: 0.0068
F19: (고용보험) | G19: (직접노무비 ＋ 간접노무비) × 고용보험율 | P19: 토목 | Q19: 건축 | S19: 기계 | T19: 전기 | V19: 3 등급 : | W19: 토목 900억~570억 | Y19: 건축 800억~520억 | AA19: 0.0113 | AD19: 22000000000 | AE19: 1.03 | AF19: 5 | AG19: 21000000000 | AH19: 1.03 | AI19: 5 | AM19: B 그룹 : | AN19: 상·하수도설비공사, 수중공사, 보링·그라우팅공사 | AU19: 0.0051
G20: =N10 -> 34484213 | H20: ＋ | I20: =N12 -> 3793263 | J20: × | K20: =Q37 -> 1.01 | L20: = | N20: =INT((G20+I20)*K20/100) -> 386602 | S20: 1 | V20: 4 등급 : | W20: 토목 570억~370억 | Y20: 건축 520억~340억 | AA20: 0.01063 | AD20: 37000000000 | AE20: 1.06 | AF20: 4 | AG20: 34000000000 | AH20: 1.06 | AI20: 4 | AM20: C 그룹 : | AN20: 석공사, 시설물유지관리, 철근·콘크리트공사, 가스시설공사(1종) | AU20: 0.0032
F21: (국민연금) | G21: (직접노무비) × 국민연금율 | P21: [공사구분 : 공사비+설비비] | V21: 5 등급 : | W21: 토목 370억~220억 | Y21: 건축 340억~210억 | AA21: 0.0103 | AD21: 57000000000 | AE21: 1.13 | AF21: 3 | AG21: 52000000000 | AH21: 1.13 | AI21: 3 | AM21: D 그룹 : | AN21: 조경시설물설치, 조경식재, 도장공사, 철도궤도, 철강재설치공사 | AU21: 0.0016
G22: =N10 -> 34484213 | J22: × | K22: =Q38 -> 4.5 | L22: = | N22: =INT((G22)*K22/100) -> 1551789 | P22: 토목 | Q22: 건축 | S22: 기계 | T22: 전기 | V22: 6 등급 : | W22: 토목 220억~140억 | Y22: 건축 210억~130억 | AA22: 0.0102 | AD22: 90000000000 | AE22: 1.3 | AF22: 2 | AG22: 80000000000 | AH22: 1.3 | AI22: 2 | AM22: E 그룹 : | AN22: A그룹～D그룹 이외의 공사 | AU22: 0.001
F23: (건강보험) | G23: (직접노무비) × 건강보험율 | S23: 1 | V23: 7 등급 : | W23: 토목 140억~ 7등급 미만 | Y23: 건축 130억~ 7등급 미만 | AA23: 0.0101 | AD23: 140000000000 | AE23: 1.57 | AF23: 1 | AG23: 120000000000 | AH23: 1.57 | AI23: 1
G24: =N10 -> 34484213 | J24: × | K24: =Q39 -> 3.545 | L24: = | N24: =INT((G24)*K24/100) -> 1222465 | P24: [산업안전보건관리비 요율 구분] | AD24: [산업안전보건관리비 요율표] | AM24: [건설 하도급대금지급보증비 요율표]
F25: (요양보험) | G25: (국민건강보험료) × 노인장기요양보험율 | P25: 플랜트 공사 | Q25: 플랜트 外 공사 | V25: [산업안전보건관리비 요율표] | AD25: 건축공사 | AF25: 토목공사 | AM25: 공사규모 (추정가격) | AU25: 2018년도
G26: =N24 -> 1222465 | J26: × | K26: =Q40 -> 12.95 | L26: = | N26: =INT((G26)*K26/100) -> 158309 | Q26: 1 | V26: 구분 | X26: 건축공사 요율/기초액 | Z26: 토목공사 요율/기초액 | AD26: 금액 | AE26: 요율 | AF26: 금액 | AG26: 요율 | AM26: 50억 미만 | AU26: 0.00081
P27: [공종별 추정비율 : 공급사에서 필히 현장조사 후 입찰 준비하시길 바랍니다] | V27: 2천만원 미만 | X27: 3.11 | Z27: 3.15 | AD27: 0 | AE27: 3.11 | AF27: 0 | AG27: 3.15 | AM27: 50억원～100억원 미만 | AU27: 0.0008
C28: 나) 산업안전보건관리비 | G28: =IF(P12=AE66,AF66,AF67) -> (도급재료비 ＋ 발주자재료비 ＋ 직접노무비) × 산업안전보건관리비율 ＋ 기초액 | N28: =IF(P12=AE70,AF70,AF71) -> (설비비 포함) | P28: 기계 : 100%, 전기 : 0% | V28: 2천만원~5억원 미만 | X28: 3.11 | Z28: 3.15 | AD28: 20000000 | AE28: 3.11 | AF28: 20000000 | AG28: 3.15 | AM28: 100억원～300억원 미만 | AU28: 0.00075
G29: =(N8+'토건_순공사비 내역서'!L175)*P12+Q53*Q12*0.7 -> 14750000 | H29: ＋ | I29: =N10*P12 -> 34484213 | J29: × | K29: =((IF((G29+I29)="","",VLOOKUP((G29+I29),AD27:AE31,2,1))*Q26+IF((G29+I29)="","",VLOOKUP((G29+I29),AF27:AG31,2,1))*P26)) -> 3.11 | L29: ＋ | M29: =SUMIF(Z27:Z31,K29,AA27:AA31)+SUMIF(X27:X31,K29,Y27:Y31)+SUMIF(AB27:AB31,K29,AC27:AC31) -> 0 | N29: =INT((G29+I29)*K29/100+M29) -> 1531184 | P29: [필수면허] | V29: 5억원~50억원 미만 | W29: G2(1.86%+5,349 천원) | X29: 2.28 | Y29: 4325000 | Z29: 2.53 | AA29: 3300000 | AD29: 500000000 | AE29: 2.28 | AF29: 500000000 | AG29: 2.53 | AM29: 300억원 이상 (최저가낙찰 대상공사) | AR29: - 토목및산업설비 | AU29: 0.00071
G30: =IF(P12=AE68,AF68,AF69) -> ((도급재료비 ＋ 직접노무비) × 산업안전보건관리비율 ＋ 기초액) x 1.2 | N30: =IF(P12=AE72,AF72,AF73) -> (설비비 제외) | P30: 기계공사 면허 | V30: 50억원 이상 | W30: G3(1.97%) | X30: 2.37 | Z30: 2.6 | AD30: 5000000000 | AE30: 2.37 | AF30: 5000000000 | AG30: 2.6 | AR30: - 건축 | AU30: 0.00068
G31: =N8*P12+Q53*Q12*0.7 -> 14750000 | H31: ＋ | I31: =N10*P12 -> 34484213 | J31: × | K31: =((IF((G31+I31)="","",VLOOKUP((G31+I31),AF27:AG31,2,1))*P26+IF((G31+I31)="","",VLOOKUP((G31+I31),AD27:AE31,2,1))*Q26)) -> 3.11 | L31: ＋ | M31: =SUMIF(Z27:Z31,K31,AA27:AA31)+SUMIF(X27:X31,K31,Y27:Y31)+SUMIF(AB27:AB31,K31,AC27:AC31) -> 0 | N31: =INT((G31+I31)*K31/100+M31)*1.2 -> 1837420.8 | V31: 800억원 이상 | W31: G3(1.97%) | X31: 2.64 | Z31: 2.73 | AD31: 80000000000 | AE31: 2.64 | AF31: 80000000000 | AG31: 2.73 | AM31: 턴키(대안)공사 | AU31: 0.00084
B32: 산업안전보건관리비 적용 | N32: 2358340
P33: [요율]
C34: 다) 법정경비(퇴직공제비) | G34: (직접노무비) × 퇴직공제비율 | P34: 구분 | Q34: 요율 | S34: 비고
G35: =N10 -> 34484213 | J35: × | K35: =Q42 -> 2.3 | L35: = | N35: =INT((G35)*K35/100) -> 793136 | P35: 간접노무비 | Q35: =(IF((N8+N10+N16)="","",VLOOKUP((N8+N10+N16),AD12:AE14,2,1))*P20+IF((N8+N10+N16)="","",VLOOKUP((N8+N10+N16),AD12:AE14,2,1))*Q20+IF((N8+N10+N16)="","",VLOOKUP((N8+N10+N16),AH12:AI14,2,1))*S20+IF((N8+N10+N16)="","",VLOOKUP((N8+N10+N16),AH12:AI14,2,1))*T20+IF((P14)="","",VLOOKUP((P14),AF12:AG14,2,1))*P20+IF((P14)="","",VLOOKUP((P14),AF12:AG14,2,1))*Q20+IF((P14)="","",VLOOKUP((P14),AJ12:AK14,2,1))*S20+IF((P14)="","",VLOOKUP((P14),AJ12:AK14,2,1))*T20)/2 -> 11 | R35: %
P36: 산재보험 | Q36: 3.56 | R36: % | S36: 법정요율 | AF36: 설비비포함 | AG36: =IF(N32=N29,1,0) -> 0
C37: 라) 건설기계대여지급보증비 | G37: (도급재료비 ＋ 직접노무비 ＋ 산출경비 ) × 지급보증비율 | P37: 고용보험 | Q37: =IF((N8+N14+N16)="","",VLOOKUP((N8+N14+N16),AD17:AE23,2,1)) -> 1.01 | R37: % | S37: 법정요율 | AF37: 1.2배 | AG37: =IF(N32=N31,1,0) -> 0
G38: =N8 -> 14750000 | H38: ＋ | I38: =N10 -> 34484213 | J38: ＋ | K38: =N16 -> 10272271 | L38: × | M38: =Q43 -> 0.11 | N38: =INT((G38+I38+K38)*M38/100) -> 65457 | P38: 국민연금 | Q38: 4.5 | R38: % | S38: 법정요율
P39: 건강보험 | Q39: 3.545 | R39: % | S39: 법정요율
C40: 마) 환경보전비 | G40: (도급재료비 ＋ 직접노무비 ＋ 산출경비 ) × 지급보증비율 | P40: 요양보험 | Q40: 12.95 | R40: % | S40: 법정요율 | AF40: =Q58 -> 0 | AG40: =IF(AF40>=80000000000,1,0) -> 0
...

Sheet 토건_순공사비 내역서
B1: ○ 계약건명 : | E1: ='토건_제경비 내역서'!E3:N3 -> 포)3FINEX 수처리 RTO 소각로 노후교체
B2: ○ 시공사 : | E2: ㈜플랜텍
B3: 순 공 사 비 내 역 서
B4: 구 분 | G4: 품명 | H4: 세부규격 | I4: 단 위 | J4: 수 량 | K4: 단 가 | L4: 금 액 | M4: 비 고
B5: 사 업 명 :
B6: 1. 도급 재료비
G7: 토목공사 | H7: 철근, Remicon외 | I7: LOT | J7: 1 | K7: 14750000 | L7: =INT(J7*K7) -> 14750000
L8: =INT(J8*K8) -> 0
L9: =INT(J9*K9) -> 0
L10: =INT(J10*K10) -> 0
L11: =INT(J11*K11) -> 0
L12: =INT(J12*K12) -> 0
L13: =INT(J13*K13) -> 0
L14: =INT(J14*K14) -> 0
L15: =INT(J15*K15) -> 0
L16: =INT(J16*K16) -> 0
L17: =INT(J17*K17) -> 0
L18: =INT(J18*K18) -> 0
L19: =INT(J19*K19) -> 0
... L54: =INT(J54*K54) -> 0
B55: 재료비 계 | L55: =SUM(L7:L54) -> 14750000
B56: 2. 직접노무비
G57: 토목공사 | H57: 토공 (운반거리 L=20.0km) | I57: ㎥ | J57: 17.6112 | K57: 28768 | L57: =INT(J57*K57) -> 506639
H58: 건설폐토석 | I58: Ton | J58: 15.85008 | K58: 110358 | L58: =INT(J58*K58) -> 1749183
H59: 철근 현장가공조립(각종) | I59: Ton | J59: 6.3762612 | K59: 787520 | L59: =INT(J59*K59) -> 5021433
H60: 콘크리트(각종) | I60: ㎥ | J60: 73.0512 | K60: 91581 | L60: =INT(J60*K60) -> 6690101
H61: 거푸집(각종) | I61: ㎡ | J61: 40.8528 | K61: 75657 | L61: =INT(J61*K61) -> 3090800
H62: 구체철거(CONC + ASCON) | I62: ㎥ | J62: 75.1392 | K62: 78751 | L62: =INT(J62*K62) -> 5917287
H63: 포장(ASCON T=10) | I63: Ar | J63: 1.428336 | K63: 3215406 | L63: =INT(J63*K63) -> 4592680
H64: 철물제작설치 (각 종) | I64: Ton | J64: 1.3423751 | K64: 5152130 | L64: =INT(J64*K64) -> 6916090
L65: =INT(J65*K65) -> 0
L66: =INT(J66*K66) -> 0
L67: =INT(J67*K67) -> 0
L68: =INT(J68*K68) -> 0
L69: =INT(J69*K69) -> 0
L70: =INT(J70*K70) -> 0
L71: =INT(J71*K71) -> 0
L72: =INT(J72*K72) -> 0
L73: =INT(J73*K73) -> 0
L74: =INT(J74*K74) -> 0
...

Sheet 견적서_포스코이앤씨

Sheet 제경비사용실적 제출표지
A1: 공사명 : (포항)~~ (계약명으로 수정)
A2: 제경비 사용실적 | O2: (단위:원)
A3: 구분 | B3: 산재보험 | C3: 고용보험 | D3: 국민연금 | E3: 건강보험 | F3: 요양보험 | G3: 퇴직공제비 | H3: 건설기계 지급보증비 | I3: 환경보전비 | J3: 산업안전보건관리비 | K3: 전담안전관리자 | L3: 생명지킴이 | M3: 안전관리비 | N3: 품질관리비 | O3: 계
A4: 계상금액 | B4: ='기계_제경비 내역서'!N18 -> 5987816 | C4: ='기계_제경비 내역서'!N20 -> 1698790 | D4: ='기계_제경비 내역서'!N22 -> 6818800 | E4: ='기계_제경비 내역서'!N24 -> 5371699 | F4: ='기계_제경비 내역서'!N26 -> 695635 | G4: ='기계_제경비 내역서'!N35 -> 3485164 | H4: ='기계_제경비 내역서'!N38 -> 258699 | I4: ='기계_제경비 내역서'!N41 -> 0 | J4: ='기계_제경비 내역서'!N32 -> 14227829 | K4: ='기계_제경비 내역서'!T64 -> 18058800 | L4: ='기계_제경비 내역서'!T65 -> 0 | M4: ='기계_제경비 내역서'!N49 -> 0 | N4: ='기계_제경비 내역서'!N51 -> 0 | O4: =SUM(B4:N4) -> 56603232
A5: 가입(사용)금액 | B5: 계약건명으로 가입증명 제출 | O5: =SUM(B5:N5) -> 0
A6: 정산요구금액 | D6: =D5*1/2 -> 0 | E6: =E5*1/2 -> 0 | F6: =F5*1/2 -> 0 | G6: =G5 -> 0 | H6: =H5 -> 0 | I6: =I5 -> 0 | J6: =J5 -> 0 | K6: =K5 -> 0 | L6: =L5 -> 0 | M6: =M5 -> 0 | N6: =N5 -> 0 | O6: =SUM(B6:N6) -> 0
A7: 정산금액 | B7: =B6-B4 -> -5987816 | C7: =C6-C4 -> -1698790 | D7: =D6-D4 -> -6818800 | E7: =E6-E4 -> -5371699 | F7: =F6-F4 -> -695635 | G7: =G6-G4 -> -3485164 | H7: =H6-H4 -> -258699 | I7: =I6-I4 -> 0 | ... N7: =N6-N4 -> 0 | O7: =SUM(B7:N7) -> -56603232
A8: *근거서류는 '을'지로 첨부해서 제출 !
A9: *대표이사 사용인감 필수 ! | I9: 제 출 일 : . .
I10: 제 출 처 : 주식회사 포스코
I11: 원도급사 :
I12: 대표이사 : (인)
A14: [입력방법]
A15: *계상금액 : 2Page "제경비내역서"에서 산출된 금액 기록
A16: *가입(사용)금액 : 실제로 가입한 금액 기록
A17: *정산요구금액 : 업체가 정산 기준에 의거 계산금액 기록
A18: *감액 : 계상금액보다 많이 사용해도(즉 가액 일때에도) "Zero" 기록
A20: 정산 기준
A21: 1.산업안전보건관리비는 사용실적 기준 미사용분 감액[노동부 2012-126호 양식에 의거]
A22: 2.퇴직공제비는 가입근거 기준 미사용분 감액
A23: 3.산재보험 및 고용보험은 "공사건"으로 원도급사가 필히 가입하고 근거를 제출하여야 한다[가입시만 전액 인정]
A24: 4.건강보험,국민연금,요양보험은 "공사건" 가입근거중 1/2(사업자분)만 인정하고 미사용분에 대해선 감액[건설기본법 제22조 5항]
A25: 5.건설기계지급보증비 및 환경보전비 증빙에 따라 정산하며 미사용분에 대해선 감액 [건설산업기본법 제68조의3, 건설기술관리법 시행규칙 제28조의2제1항제2조]
A26: 6.안전관리비는 사용실적 기준 미사용분 감액 | D26: [건설기술진흥법 시행규칙 제60조 5항]
A27: 7.품질관리비는 사용실적 기준 미사용분 감액 | D27: [건설기술진흥법 시행규칙 제53조 1항]
A28: ※상기 금액중 제경비내역서의 "기준(계상된)금액"보다 많이 사용(가입)해도 정산불가 함.
A29: 단, 당사의 요청에 의해 계상된 산업안전보건관리비의 금액보다 추가로 집행된 산업안전보건관리비가 있는 경우에는 당사의 승인을 거쳐 정산할 수 있다.

Sheet 제경비요율표
A1: 적용 요율
A2: 금액/구분 | B2: 간접노무비 | F2: 기타 경비 | G2: 일반관리비 | I2: 이윤 | K2: 산재 보험료 | L2: 고용 보험료 | M2: 산업안전보건관리비 | Q2: 퇴직 공제비 | R2: 건강 보험료 | S2: 노인 장기 요양 보험료 | T2: 연금 보험료 | U2: 환경 보전비 | V2: 건설기계 대여금 지급보증비 | W2: 건설 하도급대금 지급보증비
B3: 토목,건축 | D3: 기계,전기 | G3: 적산 | H3: 경상 투자 | I3: 토목 건축 | J3: 기계 전기 | M3: 건축공사 | N3: 토목공사 | O3: 중건설공사 | P3: 특수건설공사
B4: 금액 | C4: 기간 | D4: 금액 | E4: 기간
B5: (직노)x율 | F5: (재+노+대상경비)x율 | G5: (재+노+경)x율 | I5: (노+경+일)x율 | K5: (노)x율 | L5: (노)x율 | M5: (재+직노+사급자재)x율 | Q5: (직노) x율 | R5: (직노) x율 | S5: (건강 보험료) x율 | T5: (직노) x율 | U5: (재+직노+산경)x율 | V5: (재+직노+산경)x율 | W5: (재+직노+산경)x율
A6: 2천만원미만 | B6: 0.15 | C6: 13.0% 6개월 미만 | D6: 0.12 | E6: 10% 6개월 미만 | F6: 0.0372 | G6: 0.06 | H6: 0.06 | I6: 0.15 | J6: 0.12 | M6: 0.0311 | N6: 0.0315 | O6: 0.0364 | P6: 0.0207 | Q6: 준설:0% 토건기전공통 :2.3% | R6: 0.03545 | S6: 0.1295 | T6: 0.045 | U6: 도로:0.9% 플랜트:0.4% 지하철:0.5% 철도:1.5% 상하수도:0.5% 항만:0.8%(오탁방지막 또는 준설토방지막을 설치하는 경우:1.8%) 댐:1.1% 택지개발:0.6% 그 밖의 토목공사:0.8% 주택(재개발 및 재건축):0.7% 주택(신축):0.3% 그 밖의 건축공사:0.5% | V6: 주1) 종합건설업자 계약시 토목공사:0.4%건축공사:0.07% 산업.환경설비공 사:0.16% 조경공사:0.18% 주2) 전문건설업자계약시 A그룹 : 0.68% B그룹 : 0.51% C그룹 : 0.32% D그룹 : 0.16% E그룹 : 0.10% | W6: 50억 미만 : 0.081%
A7: 2천만원~4천만원미만 | K7: 0.0356 | L7: 1등급: 1.57% 2등급: 1.30% 3등급: 1.13% 4등급: 1.06% 5등급: 1.03% 6등급: 1.02% 7등급이하: 1.01%
A8: 4천만원~5천만원미만
A9: 5천만원~3억원미만 | H9: 0.055
A10: 3억원~3.4억원미만 | H10: 0.05
A11: 3.4억원~5억원미만
A12: 5억원~10억원미만 | B12: 0.14 | C12: 14.0% 6~18 개월 | D12: 0.11 | E12: 11% 6~18 개월 | G12: 0.055 | M12: 2.28% 4,325 천원 (기초액) | N12: 2.53% 3,300 천원 (기초액) | O12: 3.05% 2,975 천원 (기초액) | P12: 1.59% 2,450 천원 (기초액)
A13: 10억원~20억원미만 | I13: 0.14 | J13: 0.11
A14: 20억원~30억원미만 | B14: 0.13 | C14: 15.0% 18개월 이상 | D14: 0.1 | E14: 12% 18개월 이상
A15: 30억원~50억원미만 | G15: 0.05 | I15: 0.13 | J15: 0.1
A16: 50억원~100억원미만 | M16: 0.0237 | N16: 0.026 | O16: 0.0311 | P16: 0.0164 | W16: 50～100억 : 0.08%
A17: 100억원~300억 미만 | W17: 100～300억 : 0.075%
A18: 300억원~800억 미만 | W18: 300억 이상 토목,산업설비 :0.071% 건축 : 0.068% 턴키,대안공사 :0.084%
A19: 800억원이상 | M19: 0.0264 | N19: 0.0273 | O19: 0.0339 | P19: 0.0178
A22: 적용기준
A23: 1. 간접노무비 | B23: (직노)x율; 적용=> 재료비 + 직접노무비 + 산출경비 (각 구분공사별 적용)
B24: 규모와 기간요율을 합산하여 평균요율 적용(공사기간:단위차수 공사기간)
A25: 2. 일반관리비 | B25: (재+노+경)x율; 적용=> 도급공사비(재료비 + 노무비 + 경비)의 합산금액
A26: 3. 이윤 | B26: (노+경+일)x율; 적용=>재료비 + 노무비 + 경비 + 일반관리비 (각 구분공사별 적용) (ex.이윤제외금액)
B27: 건축:설비포함, 기계:축로포함, 전기:통신포함
A28: 4. 산재보험료 | B28: (노+경+일)x율; 적용=> (직 + 간접 노무비) × 적용요율 (산업재해보상보험법 제 63조, 동법 시행령 제60조) :(고용노동부고시(안)2024- 호, 국토교통부 고시 제2021 - 905호)
B29: 산업재해보상보험요율표(2000년도 이후 노동부 고시에 의해 건설업 사업종류를 4종에서 1종으로 통합적용) 출퇴근 산재보험률 0.6%포함
