Workbook

Sheet 공사물량총량
A1: 산# 1. 공사물량 총량 집계
A2: 각 산출 시트(기본물량·제작·배관·도장·부대·가설)의 결과를 자동 집계합니다. 범례: 검정=자동 연동, 파란 글씨/노란 배경=입력(7-9 기타공사, 장비 매핑).
A4: 구 분 | B4: 내 용 | C4: 수 량 | D4: 단위 | E4: 집계 근거 | F4: 집계 장비명 (매핑)
A5: 1. 설치 공사
A6: - | B6: 강재류 | C6: =SUMIFS(기본물량산출!$G$6:$G$13,기본물량산출!$H$6:$H$13,"설치",기본물량산출!$J$6:$J$13,"강재류") -> 39.5 | D6: TON | E6: 기본물량산출
A7: - | B7: 강재 STAND | C7: =SUMIFS(기본물량산출!$G$6:$G$13,기본물량산출!$H$6:$H$13,"설치",기본물량산출!$J$6:$J$13,"강재 STAND") -> 0 | D7: TON | E7: 기본물량산출
A8: - | B8: 배관류 | C8: =SUMIF(배관집계!$B$7:$B$32,"설치",배관집계!$O$7:$O$32) -> 5.1341072 | D8: TON | E8: 배관집계(설치 T)
B9: 소 계 | C9: =SUM(C6:C8) -> 44.634107 | D9: TON
A11: 2. 이설 공사
A12: - | B12: 강재류 | C12: =SUMIFS(기본물량산출!$G$6:$G$13,기본물량산출!$H$6:$H$13,"이설",기본물량산출!$J$6:$J$13,"강재류") -> 45.986 | D12: TON | E12: 기본물량산출
A13: - | B13: 강재 STAND | C13: =SUMIFS(기본물량산출!$G$6:$G$13,기본물량산출!$H$6:$H$13,"이설",기본물량산출!$J$6:$J$13,"강재 STAND") -> 6.15 | D13: TON | E13: 기본물량산출
B14: 소 계 | C14: =SUM(C12:C13) -> 52.136 | D14: TON
A16: 3. 철거 공사
A17: - | B17: 기기강재류 철거 | C17: =SUMIFS(기본물량산출!$G$6:$G$13,기본물량산출!$H$6:$H$13,"철거") -> 39.5 | D17: TON | E17: 기본물량산출
A18: - | B18: 배관류 | C18: =SUMIF(배관집계!$B$7:$B$32,"철거",배관집계!$O$7:$O$32) -> 5.1341072 | D18: TON | E18: 배관집계(철거 T)
B19: 소 계 | C19: =SUM(C17:C18) -> 44.634107 | D19: TON
A21: 5. 부대 공사
A22: 1) 도 장
A23: - | B23: 바탕처리 1급 | C23: =도장면적집계!$I$13 -> 5.3531757 | D23: M2 | E23: 도장면적집계
A24: - | B24: 바탕처리 2급 | C24: =도장면적집계!$J$13 -> 192.68575 | D24: M2 | E24: 도장면적집계
A25: - | B25: EPOXY PRIMER 붓칠 1회 | C25: =도장면적집계!$K$13 -> 192.68575 | D25: M2 | E25: 도장면적집계
A26: - | B26: H.B SELF PRIMING EPOXY MASTIC 붓칠 1회 | C26: =도장면적집계!$L$13 -> 192.68575 | D26: M2 | E26: 도장면적집계
A27: - | B27: H.B EPOXY MASTIC 붓칠 1회 | C27: =도장면적집계!$M$13 -> 192.68575 | D27: M2 | E27: 도장면적집계
A28: - | B28: EPOXY PRIMER 뿜칠 1회 | C28: =도장면적집계!$N$13 -> 5.3531757 | D28: M2 | E28: 도장면적집계
A29: - | B29: H.B SELF PRIMING EPOXY MASTIC 뿜칠 1회 | C29: =도장면적집계!$O$13 -> 5.003 | D29: M2 | E29: 도장면적집계
A30: - | B30: H.B EPOXY MASTIC 뿜칠 1회 | C30: =도장면적집계!$P$13 -> 5.003 | D30: M2 | E30: 도장면적집계
A31: - | B31: 내화도료(PSM) 50MM | C31: =도장면적집계!$R$13 -> 20 | D31: M2 | E31: 도장면적집계
A32: - | B32: 내화도료(PSM) 100MM | C32: =도장면적집계!$S$13 -> 7 | D32: M2 | E32: 도장면적집계
A33: - | B33: 내화도료(PSM) 200MM | C33: =도장면적집계!$T$13 -> 45 | D33: M2 | E33: 도장면적집계
A34: 2) 용 접
A35: - | B35: WELDING ROD KSE 4301 | C35: =부대용접산소장비!$K$14 -> 178.6902 | D35: KG | E35: 부대 7-1
A36: - | B36: WELDING ROD KSE 4316 | C36: =부대용접산소장비!$L$14 -> 40.867493 | D36: KG | E36: 부대 7-1
A37: - | B37: WELDING ROD AWS E308-16 | C37: =부대용접산소장비!$M$14 -> 0 | D37: KG | E37: 부대 7-1
A38: - | B38: TIG WELDING WIRE (연강용) | C38: =부대용접산소장비!$N$14 -> 20.433747 | D38: KG | E38: 부대 7-1
A39: - | B39: TIG WELDING WIRE (STS용) | C39: =부대용접산소장비!$O$14 -> 0 | D39: KG | E39: 부대 7-1
A40: - | B40: OXYGEN GAS | C40: =부대용접산소장비!$F$33 -> 793 | D40: M3 | E40: 부대 7-2
A41: - | B41: ARGON GAS | C41: =배관ARGON!$G$28 -> 7 | D41: BT | E41: 배관 4-5
A42: - | B42: RT(15T이하) | C42: =배관부가물량!$L$42 -> 11 | D42: SH | E42: 배관 4-3 (촬영매수)
A43: - | B43: PT | C43: =배관부가물량!$N$42 -> 0.0068172561 | D43: M | E43: 배관 4-3
A44: 3) 부산물
...

Sheet 기본물량산출
A1: 포) 2제강 4전로 Hood 갱년교체 - 기본물량산출 (수정본)
A2: 범례: 파란 글씨=입력, 검정=수식, 노란 배경=확인/입력 필요. 수식 셀은 수정하지 마세요.
A3: 근거: 기계 적산 설계 MANUAL(2024.12) 3-7 장비공사, 3장 요주의 Work Code(W5931 A01/A02), 고소할증 C02
A5: NO | B5: 품명 | C5: 수량 | D5: 단위 | E5: 개당 설치단중(kg) | F5: 중량(kg) | G5: 중량(ton) | H5: 작업구분 | I5: 설비계열 | J5: 품종기본 | K5: 품종(자동판정) | L5: 장비명 | M5: TON/DAY | N5: 작업계수 | O5: 장비일수 | P5: 설치높이(m) | Q5: 고소방식 | R5: 고소할증 C02 | S5: 용접장 30M초과(Y/N) | T5: A01 (W5931) | U5: A02 (W5931) | V5: 운반적용(Y/N) | W5: 비고 | X5: 원본 장비일수 | Y5: 차이(수정-원본)
A6: 1 | B6: UPPER HOOD 설치 | C6: 1 | D6: 식 | E6: 38000 | F6: =C6*E6 -> 38000 | G6: =F6/1000 -> 38 | H6: 설치 | I6: 철골류 | J6: 강재류 | K6: =J6&IF(J6="강재류"," "&IF(E6<500,"0.5TON미만",IF(E6<1000,"0.5-1.0TON",IF(E6<5000,"1.0-5.0TON",IF(E6<10000,"5.0-10.0TON","10.0TON이상")))),"")&IF(H6="설치","",IF(H6="철거"," 철거"," 이설")) -> 강재류 10.0TON이상 | L6: OHC 운전 | M6: =IF(E6<=0,0,INDEX(기준표!$C$5:$E$16,MATCH(E6/1000-0.0001,기준표!$A$5:$A$16,1),MATCH(I6,기준표!$C$4:$E$4,0))) -> 28 | N6: =INDEX(기준표!$B$20:$B$22,MATCH(H6,기준표!$A$20:$A$22,0)) -> 1 | O6: =IF(M6=0,0,G6/M6*N6) -> 1.3571429 | Q6: 비계 | R6: =IF(N(P6)<=0,0,IF(Q6="비계",INDEX(기준표!$C$26:$C$34,MATCH(P6,기준표!$A$26:$A$34,1)),INDEX(기준표!$E$26:$E$34,MATCH(P6,기준표!$A$26:$A$34,1)))) -> 0 | S6: N | T6: =IF(OR(J6<>"강재류",H6="철거"),"-",IF(E6<500,IF(S6="Y",0.3,0),IF(E6<1000,0.15,IF(E6<5000,0,IF(E6<10000,-0.2,-0.3))))) -> -0.3 | U6: =IF(OR(J6<>"강재류",H6="철거"),"-",IF(AND(E6<500,S6="Y"),0.2,0)) -> 0 | V6: Y | X6: 1.36 | Y6: =ROUND(O6,2)-X6 -> 0
A7: 2 | B7: UPPER HOOD 철거 | C7: 1 | D7: 식 | E7: 38000 | F7: =C7*E7 -> 38000 | G7: =F7/1000 -> 38 | H7: 철거 | I7: 철골류 | J7: 강재류 | K7: =J7&IF(J7="강재류"," "&IF(E7<500,"0.5TON미만",IF(E7<1000,"0.5-1.0TON",IF(E7<5000,"1.0-5.0TON",IF(E7<10000,"5.0-10.0TON","10.0TON이상")))),"")&IF(H7="설치","",IF(H7="철거"," 철거"," 이설")) -> 강재류 10.0TON이상 철거 | L7: OHC 운전 | M7: =IF(E7<=0,0,INDEX(기준표!$C$5:$E$16,MATCH(E7/1000-0.0001,기준표!$A$5:$A$16,1),MATCH(I7,기준표!$C$4:$E$4,0))) -> 28 | N7: =INDEX(기준표!$B$20:$B$22,MATCH(H7,기준표!$A$20:$A$22,0)) -> 0.5 | O7: =IF(M7=0,0,G7/M7*N7) -> 0.67857143 | Q7: 비계 | R7: =IF(N(P7)<=0,0,IF(Q7="비계",INDEX(기준표!$C$26:$C$34,MATCH(P7,기준표!$A$26:$A$34,1)),INDEX(기준표!$E$26:$E$34,MATCH(P7,기준표!$A$26:$A$34,1)))) -> 0 | S7: N | T7: =IF(OR(J7<>"강재류",H7="철거"),"-",IF(E7<500,IF(S7="Y",0.3,0),IF(E7<1000,0.15,IF(E7<5000,0,IF(E7<10000,-0.2,-0.3))))) -> - | U7: =IF(OR(J7<>"강재류",H7="철거"),"-",IF(AND(E7<500,S7="Y"),0.2,0)) -> - | V7: N | W7: 철거재 운반: 폐기대상이면 Y (본 설비 철거는 SCRAP 공제 없음, 운반비만) | X7: 0.68 | Y7: =ROUND(O7,2)-X7 -> 0
A8: 3 | B8: LANCE PIPE (3EA) | C8: 3 | D8: EA | E8: 12056 | F8: =C8*E8 -> 36168 | G8: =F8/1000 -> 36.168 | H8: 이설 | I8: 철골류 | J8: 강재류 | K8: =J8&IF(J8="강재류"," "&IF(E8<500,"0.5TON미만",IF(E8<1000,"0.5-1.0TON",IF(E8<5000,"1.0-5.0TON",IF(E8<10000,"5.0-10.0TON","10.0TON이상")))),"")&IF(H8="설치","",IF(H8="철거"," 철거"," 이설")) -> 강재류 10.0TON이상 이설 | L8: OHC 운전 | M8: =IF(E8<=0,0,INDEX(기준표!$C$5:$E$16,MATCH(E8/1000-0.0001,기준표!$A$5:$A$16,1),MATCH(I8,기준표!$C$4:$E$4,0))) -> 28 | N8: =INDEX(기준표!$B$20:$B$22,MATCH(H8,기준표!$A$20:$A$22,0)) -> 1.25 | O8: =IF(M8=0,0,G8/M8*N8) -> 1.6146429 | Q8: 비계 | R8: =IF(N(P8)<=0,0,IF(Q8="비계",INDEX(기준표!$C$26:$C$34,MATCH(P8,기준표!$A$26:$A$34,1)),INDEX(기준표!$E$26:$E$34,MATCH(P8,기준표!$A$26:$A$34,1)))) -> 0 | S8: N | T8: =IF(OR(J8<>"강재류",H8="철거"),"-",IF(E8<500,IF(S8="Y",0.3,0),IF(E8<1000,0.15,IF(E8<5000,0,IF(E8<10000,-0.2,-0.3))))) -> -0.3 | U8: =IF(OR(J8<>"강재류",H8="철거"),"-",IF(AND(E8<500,S8="Y"),0.2,0)) -> 0 | V8: N | W8: 기기(수냉 Lance) 성격이면 설비계열=기기류 검토 | X8: 1.61 | Y8: =ROUND(O8,2)-X8 -> 0
A9: 4 | B9: MOVEABLE DECK - DECK | C9: 1 | D9: 식 | E9: 6150 | F9: =C9*E9 -> 6150 | G9: =F9/1000 -> 6.15 | H9: 이설 | I9: 철골류 | J9: 강재 STAND | K9: =J9&IF(J9="강재류"," "&IF(E9<500,"0.5TON미만",IF(E9<1000,"0.5-1.0TON",IF(E9<5000,"1.0-5.0TON",IF(E9<10000,"5.0-10.0TON","10.0TON이상")))),"")&IF(H9="설치","",IF(H9="철거"," 철거"," 이설")) -> 강재 STAND 이설 | L9: OHC 운전 | M9: =IF(E9<=0,0,INDEX(기준표!$C$5:$E$16,MATCH(E9/1000-0.0001,기준표!$A$5:$A$16,1),MATCH(I9,기준표!$C$4:$E$4,0))) -> 23 | N9: =INDEX(기준표!$B$20:$B$22,MATCH(H9,기준표!$A$20:$A$22,0)) -> 1.25 | O9: =IF(M9=0,0,G9/M9*N9) -> 0.33423913 | Q9: 비계 | R9: =IF(N(P9)<=0,0,IF(Q9="비계",INDEX(기준표!$C$26:$C$34,MATCH(P9,기준표!$A$26:$A$34,1)),INDEX(기준표!$E$26:$E$34,MATCH(P9,기준표!$A$26:$A$34,1)))) -> 0 | S9: N | T9: =IF(OR(J9<>"강재류",H9="철거"),"-",IF(E9<500,IF(S9="Y",0.3,0),IF(E9<1000,0.15,IF(E9<5000,0,IF(E9<10000,-0.2,-0.3))))) -> - | U9: =IF(OR(J9<>"강재류",H9="철거"),"-",IF(AND(E9<500,S9="Y"),0.2,0)) -> - | V9: N | X9: 0.33 | Y9: =ROUND(O9,2)-X9 -> 0
A10: 5 | B10: MOVEABLE DECK - DECK SUPPORT | C10: 1 | D10: 식 | E10: 8318 | F10: =C10*E10 -> 8318 | G10: =F10/1000 -> 8.318 | H10: 이설 | I10: 철골류 | J10: 강재류 | K10: =J10&IF(J10="강재류"," "&IF(E10<500,"0.5TON미만",IF(E10<1000,"0.5-1.0TON",IF(E10<5000,"1.0-5.0TON",IF(E10<10000,"5.0-10.0TON","10.0TON이상")))),"")&IF(H10="설치","",IF(H10="철거"," 철거"," 이설")) -> 강재류 5.0-10.0TON 이설 | L10: OHC 운전 | M10: =IF(E10<=0,0,INDEX(기준표!$C$5:$E$16,MATCH(E10/1000-0.0001,기준표!$A$5:$A$16,1),MATCH(I10,기준표!$C$4:$E$4,0))) -> 23 | N10: =INDEX(기준표!$B$20:$B$22,MATCH(H10,기준표!$A$20:$A$22,0)) -> 1.25 | O10: =IF(M10=0,0,G10/M10*N10) -> 0.45206522 | Q10: 비계 | R10: =IF(N(P10)<=0,0,IF(Q10="비계",INDEX(기준표!$C$26:$C$34,MATCH(P10,기준표!$A$26:$A$34,1)),INDEX(기준표!$E$26:$E$34,MATCH(P10,기준표!$A$26:$A$34,1)))) -> 0 | S10: N | T10: =IF(OR(J10<>"강재류",H10="철거"),"-",IF(E10<500,IF(S10="Y",0.3,0),IF(E10<1000,0.15,IF(E10<5000,0,IF(E10<10000,-0.2,-0.3))))) -> -0.2 | U10: =IF(OR(J10<>"강재류",H10="철거"),"-",IF(AND(E10<500,S10="Y"),0.2,0)) -> 0 | V10: N | W10: 원본 '1.0-5.0TON'은 오분류 → 5.0-10.0TON 자동 정정 | X10: 0.45 | Y10: =ROUND(O10,2)-X10 -> 0
A11: 6 | B11: 철골류(설치) | C11: 4 | D11: EA | E11: 375 | F11: =C11*E11 -> 1500 | G11: =F11/1000 -> 1.5 | H11: 설치 | I11: 철골류 | J11: 강재류 | K11: =J11&IF(J11="강재류"," "&IF(E11<500,"0.5TON미만",IF(E11<1000,"0.5-1.0TON",IF(E11<5000,"1.0-5.0TON",IF(E11<10000,"5.0-10.0TON","10.0TON이상")))),"")&IF(H11="설치","",IF(H11="철거"," 철거"," 이설")) -> 강재류 0.5TON미만 | L11: OHC 운전 | M11: =IF(E11<=0,0,INDEX(기준표!$C$5:$E$16,MATCH(E11/1000-0.0001,기준표!$A$5:$A$16,1),MATCH(I11,기준표!$C$4:$E$4,0))) -> 3 | N11: =INDEX(기준표!$B$20:$B$22,MATCH(H11,기준표!$A$20:$A$22,0)) -> 1 | O11: =IF(M11=0,0,G11/M11*N11) -> 0.5 | Q11: 비계 | R11: =IF(N(P11)<=0,0,IF(Q11="비계",INDEX(기준표!$C$26:$C$34,MATCH(P11,기준표!$A$26:$A$34,1)),INDEX(기준표!$E$26:$E$34,MATCH(P11,기준표!$A$26:$A$34,1)))) -> 0 | S11: N | T11: =IF(OR(J11<>"강재류",H11="철거"),"-",IF(E11<500,IF(S11="Y",0.3,0),IF(E11<1000,0.15,IF(E11<5000,0,IF(E11<10000,-0.2,-0.3))))) -> 0 | U11: =IF(OR(J11<>"강재류",H11="철거"),"-",IF(AND(E11<500,S11="Y"),0.2,0)) -> 0 | V11: N | W11: 성품하차/구내운반 반영 여부 확인 | X11: 0.5 | Y11: =ROUND(O11,2)-X11 -> 0
A12: 7 | B12: 철골류(철거) | C12: 4 | D12: EA | E12: 375 | F12: =C12*E12 -> 1500 | G12: =F12/1000 -> 1.5 | H12: 철거 | I12: 철골류 | J12: 강재류 | K12: =J12&IF(J12="강재류"," "&IF(E12<500,"0.5TON미만",IF(E12<1000,"0.5-1.0TON",IF(E12<5000,"1.0-5.0TON",IF(E12<10000,"5.0-10.0TON","10.0TON이상")))),"")&IF(H12="설치","",IF(H12="철거"," 철거"," 이설")) -> 강재류 0.5TON미만 철거 | L12: OHC 운전 | M12: =IF(E12<=0,0,INDEX(기준표!$C$5:$E$16,MATCH(E12/1000-0.0001,기준표!$A$5:$A$16,1),MATCH(I12,기준표!$C$4:$E$4,0))) -> 3 | N12: =INDEX(기준표!$B$20:$B$22,MATCH(H12,기준표!$A$20:$A$22,0)) -> 0.5 | O12: =IF(M12=0,0,G12/M12*N12) -> 0.25 | Q12: 비계 | R12: =IF(N(P12)<=0,0,IF(Q12="비계",INDEX(기준표!$C$26:$C$34,MATCH(P12,기준표!$A$26:$A$34,1)),INDEX(기준표!$E$26:$E$34,MATCH(P12,기준표!$A$26:$A$34,1)))) -> 0 | S12: N | T12: =IF(OR(J12<>"강재류",H12="철거"),"-",IF(E12<500,IF(S12="Y",0.3,0),IF(E12<1000,0.15,IF(E12<5000,0,IF(E12<10000,-0.2,-0.3))))) -> - | U12: =IF(OR(J12<>"강재류",H12="철거"),"-",IF(AND(E12<500,S12="Y"),0.2,0)) -> - | V12: N | X12: 0.25 | Y12: =ROUND(O12,2)-X12 -> 0
A13: 8 | B13: 철골류(이설) | C13: 4 | D13: EA | E13: 375 | F13: =C13*E13 -> 1500 | G13: =F13/1000 -> 1.5 | H13: 이설 | I13: 철골류 | J13: 강재류 | K13: =J13&IF(J13="강재류"," "&IF(E13<500,"0.5TON미만",IF(E13<1000,"0.5-1.0TON",IF(E13<5000,"1.0-5.0TON",IF(E13<10000,"5.0-10.0TON","10.0TON이상")))),"")&IF(H13="설치","",IF(H13="철거"," 철거"," 이설")) -> 강재류 0.5TON미만 이설 | L13: OHC 운전 | M13: =IF(E13<=0,0,INDEX(기준표!$C$5:$E$16,MATCH(E13/1000-0.0001,기준표!$A$5:$A$16,1),MATCH(I13,기준표!$C$4:$E$4,0))) -> 3 | N13: =INDEX(기준표!$B$20:$B$22,MATCH(H13,기준표!$A$20:$A$22,0)) -> 1.25 | O13: =IF(M13=0,0,G13/M13*N13) -> 0.625 | Q13: 비계 | R13: =IF(N(P13)<=0,0,IF(Q13="비계",INDEX(기준표!$C$26:$C$34,MATCH(P13,기준표!$A$26:$A$34,1)),INDEX(기준표!$E$26:$E$34,MATCH(P13,기준표!$A$26:$A$34,1)))) -> 0 | S13: N | T13: =IF(OR(J13<>"강재류",H13="철거"),"-",IF(E13<500,IF(S13="Y",0.3,0),IF(E13<1000,0.15,IF(E13<5000,0,IF(E13<10000,-0.2,-0.3))))) -> 0 | U13: =IF(OR(J13<>"강재류",H13="철거"),"-",IF(AND(E13<500,S13="Y"),0.2,0)) -> 0 | V13: N | X13: 0.63 | Y13: =ROUND(O13,2)-X13 -> 0
B14: 계 | F14: =SUM(F6:F13) -> 131136 | G14: =SUM(G6:G13) -> 131.136 | O14: =SUM(O6:O13) -> 5.8116615 | X14: =SUM(X6:X13) -> 5.81 | Y14: =ROUND(O14,2)-X14 -> 0
A16: ※ 열 X(원본 장비일수)는 원본 시트 값을 그대로 옮긴 검증용 입력이며, 열 Y가 0이면 수정본 수식이 원본과 일치.
A17: ※ 설치높이(P열)는 도면 확인 후 입력(공란=고소할증 없음). 10m 미만은 C02 0.
A18: ※ T·U열: W5931(강재류 조립설치) 요주의 Factor. 0.5TON 미만은 용접장 30M 초과(S열=Y)일 때만 A01=0.3, A02=0.2 적용. 철거(W5944)는 해당없음(-).

Sheet 집계
A1: 집계 (기본물량산출 연동)
A3: ① 장비사용시간 집계
A4: 장비명 | B4: 합계 일수 | C4: 적용 일수(올림) | D4: 일일 사용시간(HR) | E4: 적용 시간(HR) | F4: 비고
A5: OHC 운전 | B5: =SUMIF(기본물량산출!$L$6:$L$13,A5,기본물량산출!$O$6:$O$13) -> 5.8116615 | C5: =ROUNDUP(B5,0) -> 6 | D5: =기준표!$B$38 -> 8 | E5: =IF(C5=0,0,MAX(C5*D5,기준표!$B$39)) -> 48 | F5: 원본: 6.00일 x 8HR = 48HR
A6: 100T Crane | B6: =SUMIF(기본물량산출!$L$6:$L$13,A6,기본물량산출!$O$6:$O$13) -> 0 | C6: =ROUNDUP(B6,0) -> 0 | D6: =기준표!$B$38 -> 8 | E6: =IF(C6=0,0,MAX(C6*D6,기준표!$B$39)) -> 0
A7: 25T Crane | B7: =SUMIF(기본물량산출!$L$6:$L$13,A7,기본물량산출!$O$6:$O$13) -> 0 | C7: =ROUNDUP(B7,0) -> 0 | D7: =기준표!$B$38 -> 8 | E7: =IF(C7=0,0,MAX(C7*D7,기준표!$B$39)) -> 0
A8: 15T Crane | B8: =SUMIF(기본물량산출!$L$6:$L$13,A8,기본물량산출!$O$6:$O$13) -> 0 | C8: =ROUNDUP(B8,0) -> 0 | D8: =기준표!$B$38 -> 8 | E8: =IF(C8=0,0,MAX(C8*D8,기준표!$B$39)) -> 0
A9: 지게차 7Ton | B9: =SUMIF(기본물량산출!$L$6:$L$13,A9,기본물량산출!$O$6:$O$13) -> 0 | C9: =ROUNDUP(B9,0) -> 0 | D9: =기준표!$B$38 -> 8 | E9: =IF(C9=0,0,MAX(C9*D9,기준표!$B$39)) -> 0
A11: ② 품종별 중량 집계 (kg)
A12: 품종 | B12: 중량(kg) | C12: 중량(ton)
A13: 강재류 0.5TON미만 | B13: =SUMIF(기본물량산출!$K$6:$K$13,A13,기본물량산출!$F$6:$F$13) -> 1500 | C13: =B13/1000 -> 1.5
A14: 강재류 0.5-1.0TON | B14: =SUMIF(기본물량산출!$K$6:$K$13,A14,기본물량산출!$F$6:$F$13) -> 0 | C14: =B14/1000 -> 0
A15: 강재류 1.0-5.0TON | B15: =SUMIF(기본물량산출!$K$6:$K$13,A15,기본물량산출!$F$6:$F$13) -> 0 | C15: =B15/1000 -> 0
A16: 강재류 5.0-10.0TON | B16: =SUMIF(기본물량산출!$K$6:$K$13,A16,기본물량산출!$F$6:$F$13) -> 0 | C16: =B16/1000 -> 0
A17: 강재류 10.0TON이상 | B17: =SUMIF(기본물량산출!$K$6:$K$13,A17,기본물량산출!$F$6:$F$13) -> 38000 | C17: =B17/1000 -> 38
A18: 강재 STAND | B18: =SUMIF(기본물량산출!$K$6:$K$13,A18,기본물량산출!$F$6:$F$13) -> 0 | C18: =B18/1000 -> 0
A19: 강재류 0.5TON미만 철거 | B19: =SUMIF(기본물량산출!$K$6:$K$13,A19,기본물량산출!$F$6:$F$13) -> 1500 | C19: =B19/1000 -> 1.5
A20: 강재류 0.5-1.0TON 철거 | B20: =SUMIF(기본물량산출!$K$6:$K$13,A20,기본물량산출!$F$6:$F$13) -> 0 | C20: =B20/1000 -> 0
A21: 강재류 1.0-5.0TON 철거 | B21: =SUMIF(기본물량산출!$K$6:$K$13,A21,기본물량산출!$F$6:$F$13) -> 0 | C21: =B21/1000 -> 0
A22: 강재류 5.0-10.0TON 철거 | B22: =SUMIF(기본물량산출!$K$6:$K$13,A22,기본물량산출!$F$6:$F$13) -> 0 | C22: =B22/1000 -> 0
A23: 강재류 10.0TON이상 철거 | B23: =SUMIF(기본물량산출!$K$6:$K$13,A23,기본물량산출!$F$6:$F$13) -> 38000 | C23: =B23/1000 -> 38
A24: 강재 STAND 철거 | B24: =SUMIF(기본물량산출!$K$6:$K$13,A24,기본물량산출!$F$6:$F$13) -> 0 | C24: =B24/1000 -> 0
... A30: 강재 STAND 이설 | B30: =SUMIF(기본물량산출!$K$6:$K$13,A30,기본물량산출!$F$6:$F$13) -> 6150 | C30: =B30/1000 -> 6.15
A31: 계 | B31: =SUM(B13:B30) -> 131136 | C31: =B31/1000 -> 131.136
A32: 검증(기본물량 총중량과 차이) | B32: =B31-기본물량산출!F14 -> 0
A34: ③ 운반 물량 집계 (운반적용=Y 행)
A35: 구분 | B35: 물량(ton) | C35: 비고
A36: 성품하차 (설치물량) | B36: =SUMIFS(기본물량산출!$G$6:$G$13,기본물량산출!$H$6:$H$13,"설치",기본물량산출!$V$6:$V$13,"Y") -> 38 | C36: 원본 38.0ton
A37: 구내운반 (성품현장소운반 70%) | B37: =B36*기준표!$B$37 -> 26.6 | C37: 원본 26.6ton
A38: 철거재 운반 (폐기대상) | B38: =SUMIFS(기본물량산출!$G$6:$G$13,기본물량산출!$H$6:$H$13,"철거",기본물량산출!$V$6:$V$13,"Y") -> 0 | C38: 폐기대상만 Y 지정

Sheet 제작물량산출
A1: 제작물량산출 (공장/현장 제작) - 포) 2제강 4전로 Hood 갱년교체
A2: 범례: 파란 글씨=입력, 검정=수식, 노란 배경=입력 필요. 제작품(G~L열)별 '세트당 소요량'을 입력하면 TOTAL·도장면적·적용 품셈이 자동 산출됩니다. (형강류 단위 KG)
A3: 근거: 제작물량 산출 양식, MANUAL 3-5 다.(도장면적), 일반사항 5.(할증율), 3-4 사.(용접), 6-3(SCRAP), 555 제작공사 입력SHEET(W6151)
B5: 제작품명 | G5: LANCE PIPE SUPPORT | H5: LIFTING LUG
B6: 제작분류 (공장/현장) | G6: 공장 | H6: 공장
B7: 적용품종 | G7: 지주류 | H7: 지주류
B8: 제작수량 (SET) | G8: 3 | H8: 1
B9: 제작단중 (KG/SET) | G9: =IF(G$5="",0,SUMIF($F$20:$F$39,"KG",G20:G39)) -> 0 | H9: =IF(H$5="",0,SUMIF($F$20:$F$39,"KG",H20:H39)) -> 0 | I9: =IF(I$5="",0,SUMIF($F$20:$F$39,"KG",I20:I39)) -> 0 | J9: =IF(J$5="",0,SUMIF($F$20:$F$39,"KG",J20:J39)) -> 0 | K9: =IF(K$5="",0,SUMIF($F$20:$F$39,"KG",K20:K39)) -> 0 | L9: =IF(L$5="",0,SUMIF($F$20:$F$39,"KG",L20:L39)) -> 0
B10: 제작중량 (KG) | G10: =G9*G8 -> 0 | H10: =H9*H8 -> 0 | I10: =I9*I8 -> 0 | J10: =J9*J8 -> 0 | K10: =K9*K8 -> 0 | L10: =L9*L8 -> 0
B11: 중량구분 | G11: =IF(G$5="","",IF(G9<=500,"0.5TON 이하",IF(G9<=2500,"0.5~2.5TON",IF(G9<=5000,"2.5~5TON","5TON 이상")))) -> 0.5TON 이하 | H11: =IF(H$5="","",IF(H9<=500,"0.5TON 이하",IF(H9<=2500,"0.5~2.5TON",IF(H9<=5000,"2.5~5TON","5TON 이상")))) -> 0.5TON 이하 | I11: =IF(I$5="","",IF(I9<=500,"0.5TON 이하",IF(I9<=2500,"0.5~2.5TON",IF(I9<=5000,"2.5~5TON","5TON 이상")))) | J11: =IF(J$5="","",IF(J9<=500,"0.5TON 이하",IF(J9<=2500,"0.5~2.5TON",IF(J9<=5000,"2.5~5TON","5TON 이상")))) | K11: =IF(K$5="","",IF(K9<=500,"0.5TON 이하",IF(K9<=2500,"0.5~2.5TON",IF(K9<=5000,"2.5~5TON","5TON 이상")))) | L11: =IF(L$5="","",IF(L9<=500,"0.5TON 이하",IF(L9<=2500,"0.5~2.5TON",IF(L9<=5000,"2.5~5TON","5TON 이상"))))
B12: 적용 품셈코드 (W6151) | G12: =IF(OR(G$5="",G$7=""),"",IFERROR(INDEX('555 입력SHEET'!$E$2:$E$69,MATCH(G$7&"|"&IF(G9<=500,1,IF(G9<=2500,2,IF(G9<=5000,3,4))),'555 입력SHEET'!$V$2:$V$69,0)),"품종확인")) -> W6151101 | H12: =IF(OR(H$5="",H$7=""),"",IFERROR(INDEX('555 입력SHEET'!$E$2:$E$69,MATCH(H$7&"|"&IF(H9<=500,1,IF(H9<=2500,2,IF(H9<=5000,3,4))),'555 입력SHEET'!$V$2:$V$69,0)),"품종확인")) -> W6151101 | I12: =IF(OR(I$5="",I$7=""),"",IFERROR(INDEX('555 입력SHEET'!$E$2:$E$69,MATCH(I$7&"|"&IF(I9<=500,1,IF(I9<=2500,2,IF(I9<=5000,3,4))),'555 입력SHEET'!$V$2:$V$69,0)),"품종확인")) | J12: =IF(OR(J$5="",J$7=""),"",IFERROR(INDEX('555 입력SHEET'!$E$2:$E$69,MATCH(J$7&"|"&IF(J9<=500,1,IF(J9<=2500,2,IF(J9<=5000,3,4))),'555 입력SHEET'!$V$2:$V$69,0)),"품종확인")) | K12: =IF(OR(K$5="",K$7=""),"",IFERROR(INDEX('555 입력SHEET'!$E$2:$E$69,MATCH(K$7&"|"&IF(K9<=500,1,IF(K9<=2500,2,IF(K9<=5000,3,4))),'555 입력SHEET'!$V$2:$V$69,0)),"품종확인")) | L12: =IF(OR(L$5="",L$7=""),"",IFERROR(INDEX('555 입력SHEET'!$E$2:$E$69,MATCH(L$7&"|"&IF(L9<=500,1,IF(L9<=2500,2,IF(L9<=5000,3,4))),'555 입력SHEET'!$V$2:$V$69,0)),"품종확인"))
B13: 적용 품셈명칭 | G13: =IF(G12="","",IFERROR(INDEX('555 입력SHEET'!$G$2:$G$69,MATCH(G12,'555 입력SHEET'!$E$2:$E$69,0)),"")) -> 지주류 공장 제작 0.5 TON 이하 | H13: =IF(H12="","",IFERROR(INDEX('555 입력SHEET'!$G$2:$G$69,MATCH(H12,'555 입력SHEET'!$E$2:$E$69,0)),"")) -> 지주류 공장 제작 0.5 TON 이하 | I13: =IF(I12="","",IFERROR(INDEX('555 입력SHEET'!$G$2:$G$69,MATCH(I12,'555 입력SHEET'!$E$2:$E$69,0)),"")) | J13: =IF(J12="","",IFERROR(INDEX('555 입력SHEET'!$G$2:$G$69,MATCH(J12,'555 입력SHEET'!$E$2:$E$69,0)),"")) | K13: =IF(K12="","",IFERROR(INDEX('555 입력SHEET'!$G$2:$G$69,MATCH(K12,'555 입력SHEET'!$E$2:$E$69,0)),"")) | L13: =IF(L12="","",IFERROR(INDEX('555 입력SHEET'!$G$2:$G$69,MATCH(L12,'555 입력SHEET'!$E$2:$E$69,0)),""))
B14: 용접봉 소요량 (KG) | G14: =IFERROR(G10/1000*INDEX('555 입력SHEET'!$P$2:$P$69,MATCH(G12,'555 입력SHEET'!$E$2:$E$69,0))/제작기준!$L$5*제작기준!$L$6,0) -> 0 | H14: =IFERROR(H10/1000*INDEX('555 입력SHEET'!$P$2:$P$69,MATCH(H12,'555 입력SHEET'!$E$2:$E$69,0))/제작기준!$L$5*제작기준!$L$6,0) -> 0 | I14: =IFERROR(I10/1000*INDEX('555 입력SHEET'!$P$2:$P$69,MATCH(I12,'555 입력SHEET'!$E$2:$E$69,0))/제작기준!$L$5*제작기준!$L$6,0) -> 0 | J14: =IFERROR(J10/1000*INDEX('555 입력SHEET'!$P$2:$P$69,MATCH(J12,'555 입력SHEET'!$E$2:$E$69,0))/제작기준!$L$5*제작기준!$L$6,0) -> 0 | K14: =IFERROR(K10/1000*INDEX('555 입력SHEET'!$P$2:$P$69,MATCH(K12,'555 입력SHEET'!$E$2:$E$69,0))/제작기준!$L$5*제작기준!$L$6,0) -> 0 | L14: =IFERROR(L10/1000*INDEX('555 입력SHEET'!$P$2:$P$69,MATCH(L12,'555 입력SHEET'!$E$2:$E$69,0))/제작기준!$L$5*제작기준!$L$6,0) -> 0
B15: 용접공 (MD) | G15: =IFERROR(G10/1000*INDEX('555 입력SHEET'!$N$2:$N$69,MATCH(G12,'555 입력SHEET'!$E$2:$E$69,0)),0) -> 0 | H15: =IFERROR(H10/1000*INDEX('555 입력SHEET'!$N$2:$N$69,MATCH(H12,'555 입력SHEET'!$E$2:$E$69,0)),0) -> 0 | I15: =IFERROR(I10/1000*INDEX('555 입력SHEET'!$N$2:$N$69,MATCH(I12,'555 입력SHEET'!$E$2:$E$69,0)),0) -> 0 | J15: =IFERROR(J10/1000*INDEX('555 입력SHEET'!$N$2:$N$69,MATCH(J12,'555 입력SHEET'!$E$2:$E$69,0)),0) -> 0 | K15: =IFERROR(K10/1000*INDEX('555 입력SHEET'!$N$2:$N$69,MATCH(K12,'555 입력SHEET'!$E$2:$E$69,0)),0) -> 0 | L15: =IFERROR(L10/1000*INDEX('555 입력SHEET'!$N$2:$N$69,MATCH(L12,'555 입력SHEET'!$E$2:$E$69,0)),0) -> 0
B16: 특별인부 (MD) | G16: =IFERROR(G10/1000*INDEX('555 입력SHEET'!$O$2:$O$69,MATCH(G12,'555 입력SHEET'!$E$2:$E$69,0)),0) -> 0 | H16: =IFERROR(H10/1000*INDEX('555 입력SHEET'!$O$2:$O$69,MATCH(H12,'555 입력SHEET'!$E$2:$E$69,0)),0) -> 0 | I16: =IFERROR(I10/1000*INDEX('555 입력SHEET'!$O$2:$O$69,MATCH(I12,'555 입력SHEET'!$E$2:$E$69,0)),0) -> 0 | J16: =IFERROR(J10/1000*INDEX('555 입력SHEET'!$O$2:$O$69,MATCH(J12,'555 입력SHEET'!$E$2:$E$69,0)),0) -> 0 | K16: =IFERROR(K10/1000*INDEX('555 입력SHEET'!$O$2:$O$69,MATCH(K12,'555 입력SHEET'!$E$2:$E$69,0)),0) -> 0 | L16: =IFERROR(L10/1000*INDEX('555 입력SHEET'!$O$2:$O$69,MATCH(L12,'555 입력SHEET'!$E$2:$E$69,0)),0) -> 0
B17: 전력량 (KWH) | G17: =IFERROR(G10/1000*INDEX('555 입력SHEET'!$P$2:$P$69,MATCH(G12,'555 입력SHEET'!$E$2:$E$69,0)),0) -> 0 | H17: =IFERROR(H10/1000*INDEX('555 입력SHEET'!$P$2:$P$69,MATCH(H12,'555 입력SHEET'!$E$2:$E$69,0)),0) -> 0 | I17: =IFERROR(I10/1000*INDEX('555 입력SHEET'!$P$2:$P$69,MATCH(I12,'555 입력SHEET'!$E$2:$E$69,0)),0) -> 0 | J17: =IFERROR(J10/1000*INDEX('555 입력SHEET'!$P$2:$P$69,MATCH(J12,'555 입력SHEET'!$E$2:$E$69,0)),0) -> 0 | K17: =IFERROR(K10/1000*INDEX('555 입력SHEET'!$P$2:$P$69,MATCH(K12,'555 입력SHEET'!$E$2:$E$69,0)),0) -> 0 | L17: =IFERROR(L10/1000*INDEX('555 입력SHEET'!$P$2:$P$69,MATCH(L12,'555 입력SHEET'!$E$2:$E$69,0)),0) -> 0
G18: 세트당 소요량 (제작 1SET 기준) | M18: TOTAL | O18: 도장면적
A19: NO | B19: 구 분 | C19: 규 격 | D19: 규격키(DB) | E19: 재질 | F19: 단위 | G19: =IF(G5="","제작품1",G5) -> LANCE PIPE SUPPORT | H19: =IF(H5="","제작품2",H5) -> LIFTING LUG | I19: =IF(I5="","제작품3",I5) -> 제작품3 | J19: =IF(J5="","제작품4",J5) -> 제작품4 | K19: =IF(K5="","제작품5",K5) -> 제작품5 | L19: =IF(L5="","제작품6",L5) -> 제작품6 | M19: TOTAL NET | N19: TOTAL GROSS | O19: 기준량 (㎡/TON) | P19: 도장 NET (㎡) | Q19: 도장 GROSS (㎡) | R19: 할증 구분 | S19: 할증율 | T19: 비 고
A20: 1 | B20: H-BEAM | C20: H-150 x 150 x 7 x 10 | D20: 150X150X7X10 | E20: SS275 | F20: KG | M20: =IF($B20="","",SUMPRODUCT(G20:L20,$G$8:$L$8)) -> 0 | N20: =IF($B20="","",M20*(1+S20)) -> 0 | O20: =IF(OR($B20="",$F20<>"KG"),"",IFERROR(IF($B20="PLATE",ROUND(2000/($D20*제작기준!$L$8),3),IF($B20="ROUND BAR",ROUND(4000/($D20*제작기준!$L$8),3),INDEX(제작기준!$H$5:$H$175,MATCH($B20&"|"&$D20,제작기준!$I$5:$I$175,0)))),"DB확인")) -> 27.52 | P20: =IF(ISNUMBER(O20),M20/1000*O20,"") -> 0 | Q20: =IF(ISNUMBER(O20),N20/1000*O20,"") -> 0 | R20: 대형형강(100mm이상) | S20: =IF(R20="","",IFERROR(INDEX(제작기준!$B$5:$B$30,MATCH(R20,제작기준!$A$5:$A$30,0)),"확인")) -> 0.035
A21: 2 | B21: H-BEAM | C21: H-200 x 200 x 8 x 12 | D21: 200X200X8X12 | E21: SS275 | F21: KG | M21: =IF($B21="","",SUMPRODUCT(G21:L21,$G$8:$L$8)) -> 0 | N21: =IF($B21="","",M21*(1+S21)) -> 0 | O21: =IF(OR($B21="",$F21<>"KG"),"",IFERROR(IF($B21="PLATE",ROUND(2000/($D21*제작기준!$L$8),3),IF($B21="ROUND BAR",ROUND(4000/($D21*제작기준!$L$8),3),INDEX(제작기준!$H$5:$H$175,MATCH($B21&"|"&$D21,제작기준!$I$5:$I$175,0)))),"DB확인")) -> 23.293 | P21: =IF(ISNUMBER(O21),M21/1000*O21,"") -> 0 | Q21: =IF(ISNUMBER(O21),N21/1000*O21,"") -> 0 | R21: 대형형강(100mm이상) | S21: =IF(R21="","",IFERROR(INDEX(제작기준!$B$5:$B$30,MATCH(R21,제작기준!$A$5:$A$30,0)),"확인")) -> 0.035
A22: 3 | B22: CHANNEL | C22: C-150 x 75 x 6.5 x 10 | D22: 150X75X6.5X10 | E22: SS275 | F22: KG | M22: =IF($B22="","",SUMPRODUCT(G22:L22,$G$8:$L$8)) -> 0 | N22: =IF($B22="","",M22*(1+S22)) -> 0 | O22: =IF(OR($B22="",$F22<>"KG"),"",IFERROR(IF($B22="PLATE",ROUND(2000/($D22*제작기준!$L$8),3),IF($B22="ROUND BAR",ROUND(4000/($D22*제작기준!$L$8),3),INDEX(제작기준!$H$5:$H$175,MATCH($B22&"|"&$D22,제작기준!$I$5:$I$175,0)))),"DB확인")) -> 30.58 | P22: =IF(ISNUMBER(O22),M22/1000*O22,"") -> 0 | Q22: =IF(ISNUMBER(O22),N22/1000*O22,"") -> 0 | R22: 대형형강(100mm이상) | S22: =IF(R22="","",IFERROR(INDEX(제작기준!$B$5:$B$30,MATCH(R22,제작기준!$A$5:$A$30,0)),"확인")) -> 0.035
A23: 4 | B23: CHANNEL | C23: C-150 x 75 x 9 x 12.5 | D23: 150X75X9X12.5 | E23: SS275 | F23: KG | M23: =IF($B23="","",SUMPRODUCT(G23:L23,$G$8:$L$8)) -> 0 | N23: =IF($B23="","",M23*(1+S23)) -> 0 | O23: =IF(OR($B23="",$F23<>"KG"),"",IFERROR(IF($B23="PLATE",ROUND(2000/($D23*제작기준!$L$8),3),IF($B23="ROUND BAR",ROUND(4000/($D23*제작기준!$L$8),3),INDEX(제작기준!$H$5:$H$175,MATCH($B23&"|"&$D23,제작기준!$I$5:$I$175,0)))),"DB확인")) -> 23.424 | P23: =IF(ISNUMBER(O23),M23/1000*O23,"") -> 0 | Q23: =IF(ISNUMBER(O23),N23/1000*O23,"") -> 0 | R23: 대형형강(100mm이상) | S23: =IF(R23="","",IFERROR(INDEX(제작기준!$B$5:$B$30,MATCH(R23,제작기준!$A$5:$A$30,0)),"확인")) -> 0.035
A24: 5 | B24: CHANNEL | C24: C-200 x 80 x 7.5 x 11 | D24: 200X80X7.5X11 | E24: SS275 | F24: KG | M24: =IF($B24="","",SUMPRODUCT(G24:L24,$G$8:$L$8)) -> 0 | N24: =IF($B24="","",M24*(1+S24)) -> 0 | O24: =IF(OR($B24="",$F24<>"KG"),"",IFERROR(IF($B24="PLATE",ROUND(2000/($D24*제작기준!$L$8),3),IF($B24="ROUND BAR",ROUND(4000/($D24*제작기준!$L$8),3),INDEX(제작기준!$H$5:$H$175,MATCH($B24&"|"&$D24,제작기준!$I$5:$I$175,0)))),"DB확인")) -> 27.888 | P24: =IF(ISNUMBER(O24),M24/1000*O24,"") -> 0 | Q24: =IF(ISNUMBER(O24),N24/1000*O24,"") -> 0 | R24: 대형형강(100mm이상) | S24: =IF(R24="","",IFERROR(INDEX(제작기준!$B$5:$B$30,MATCH(R24,제작기준!$A$5:$A$30,0)),"확인")) -> 0.035
A25: 6 | B25: ANGLE | C25: L-65 x 65 x 6 | D25: 65X6 | E25: SS275 | F25: KG | M25: =IF($B25="","",SUMPRODUCT(G25:L25,$G$8:$L$8)) -> 0 | N25: =IF($B25="","",M25*(1+S25)) -> 0 | O25: =IF(OR($B25="",$F25<>"KG"),"",IFERROR(IF($B25="PLATE",ROUND(2000/($D25*제작기준!$L$8),3),IF($B25="ROUND BAR",ROUND(4000/($D25*제작기준!$L$8),3),INDEX(제작기준!$H$5:$H$175,MATCH($B25&"|"&$D25,제작기준!$I$5:$I$175,0)))),"DB확인")) -> 42.81 | P25: =IF(ISNUMBER(O25),M25/1000*O25,"") -> 0 | Q25: =IF(ISNUMBER(O25),N25/1000*O25,"") -> 0 | R25: 소형형강 | S25: =IF(R25="","",IFERROR(INDEX(제작기준!$B$5:$B$30,MATCH(R25,제작기준!$A$5:$A$30,0)),"확인")) -> 0.025
A26: 7 | B26: ANGLE | C26: L-75 x 75 x 9 | D26: 75X9 | E26: SS275 | F26: KG | M26: =IF($B26="","",SUMPRODUCT(G26:L26,$G$8:$L$8)) -> 0 | N26: =IF($B26="","",M26*(1+S26)) -> 0 | O26: =IF(OR($B26="",$F26<>"KG"),"",IFERROR(IF($B26="PLATE",ROUND(2000/($D26*제작기준!$L$8),3),IF($B26="ROUND BAR",ROUND(4000/($D26*제작기준!$L$8),3),INDEX(제작기준!$H$5:$H$175,MATCH($B26&"|"&$D26,제작기준!$I$5:$I$175,0)))),"DB확인")) -> 29.231 | P26: =IF(ISNUMBER(O26),M26/1000*O26,"") -> 0 | Q26: =IF(ISNUMBER(O26),N26/1000*O26,"") -> 0 | R26: 소형형강 | S26: =IF(R26="","",IFERROR(INDEX(제작기준!$B$5:$B$30,MATCH(R26,제작기준!$A$5:$A$30,0)),"확인")) -> 0.025
A27: 8 | B27: PLATE | C27: 9T | D27: 9 | E27: SS275 | F27: KG | M27: =IF($B27="","",SUMPRODUCT(G27:L27,$G$8:$L$8)) -> 0 | N27: =IF($B27="","",M27*(1+S27)) -> 0 | O27: =IF(OR($B27="",$F27<>"KG"),"",IFERROR(IF($B27="PLATE",ROUND(2000/($D27*제작기준!$L$8),3),IF($B27="ROUND BAR",ROUND(4000/($D27*제작기준!$L$8),3),INDEX(제작기준!$H$5:$H$175,MATCH($B27&"|"&$D27,제작기준!$I$5:$I$175,0)))),"DB확인")) -> 28.309 | P27: =IF(ISNUMBER(O27),M27/1000*O27,"") -> 0 | Q27: =IF(ISNUMBER(O27),N27/1000*O27,"") -> 0 | R27: 강판(PLATE) | S27: =IF(R27="","",IFERROR(INDEX(제작기준!$B$5:$B$30,MATCH(R27,제작기준!$A$5:$A$30,0)),"확인")) -> 0.05
A28: 9 | B28: PLATE | C28: 12T | D28: 12 | E28: SS275 | F28: KG | M28: =IF($B28="","",SUMPRODUCT(G28:L28,$G$8:$L$8)) -> 0 | N28: =IF($B28="","",M28*(1+S28)) -> 0 | O28: =IF(OR($B28="",$F28<>"KG"),"",IFERROR(IF($B28="PLATE",ROUND(2000/($D28*제작기준!$L$8),3),IF($B28="ROUND BAR",ROUND(4000/($D28*제작기준!$L$8),3),INDEX(제작기준!$H$5:$H$175,MATCH($B28&"|"&$D28,제작기준!$I$5:$I$175,0)))),"DB확인")) -> 21.231 | P28: =IF(ISNUMBER(O28),M28/1000*O28,"") -> 0 | Q28: =IF(ISNUMBER(O28),N28/1000*O28,"") -> 0 | R28: 강판(PLATE) | S28: =IF(R28="","",IFERROR(INDEX(제작기준!$B$5:$B$30,MATCH(R28,제작기준!$A$5:$A$30,0)),"확인")) -> 0.05
A29: 10 | B29: PLATE | C29: 16T | D29: 16 | E29: SS275 | F29: KG | M29: =IF($B29="","",SUMPRODUCT(G29:L29,$G$8:$L$8)) -> 0 | N29: =IF($B29="","",M29*(1+S29)) -> 0 | O29: =IF(OR($B29="",$F29<>"KG"),"",IFERROR(IF($B29="PLATE",ROUND(2000/($D29*제작기준!$L$8),3),IF($B29="ROUND BAR",ROUND(4000/($D29*제작기준!$L$8),3),INDEX(제작기준!$H$5:$H$175,MATCH($B29&"|"&$D29,제작기준!$I$5:$I$175,0)))),"DB확인")) -> 15.924 | P29: =IF(ISNUMBER(O29),M29/1000*O29,"") -> 0 | Q29: =IF(ISNUMBER(O29),N29/1000*O29,"") -> 0 | R29: 강판(PLATE) | S29: =IF(R29="","",IFERROR(INDEX(제작기준!$B$5:$B$30,MATCH(R29,제작기준!$A$5:$A$30,0)),"확인")) -> 0.05 | T29: 원본 양식 기준량 16.924 → 매뉴얼 15.924로 정정
A30: 11 | B30: PIPE | C30: 25A | D30: 25A | E30: SPP | F30: KG | M30: =IF($B30="","",SUMPRODUCT(G30:L30,$G$8:$L$8)) -> 0 | N30: =IF($B30="","",M30*(1+S30)) -> 0 | O30: =IF(OR($B30="",$F30<>"KG"),"",IFERROR(IF($B30="PLATE",ROUND(2000/($D30*제작기준!$L$8),3),IF($B30="ROUND BAR",ROUND(4000/($D30*제작기준!$L$8),3),INDEX(제작기준!$H$5:$H$175,MATCH($B30&"|"&$D30,제작기준!$I$5:$I$175,0)))),"DB확인")) -> 43.598 | P30: =IF(ISNUMBER(O30),M30/1000*O30,"") -> 0 | Q30: =IF(ISNUMBER(O30),N30/1000*O30,"") -> 0 | R30: 강관(50A이하) | S30: =IF(R30="","",IFERROR(INDEX(제작기준!$B$5:$B$30,MATCH(R30,제작기준!$A$5:$A$30,0)),"확인")) -> 0.05 | T30: SPP 2.45 KG/M (단중표)
A31: 12 | B31: GRATING | C31: I-25 | E31: SS275 | F31: M2 | M31: =IF($B31="","",SUMPRODUCT(G31:L31,$G$8:$L$8)) -> 0 | N31: =IF($B31="","",M31*(1+S31)) -> 0 | O31: =IF(OR($B31="",$F31<>"KG"),"",IFERROR(IF($B31="PLATE",ROUND(2000/($D31*제작기준!$L$8),3),IF($B31="ROUND BAR",ROUND(4000/($D31*제작기준!$L$8),3),INDEX(제작기준!$H$5:$H$175,MATCH($B31&"|"&$D31,제작기준!$I$5:$I$175,0)))),"DB확인")) | P31: =IF(ISNUMBER(O31),M31/1000*O31,"") | Q31: =IF(ISNUMBER(O31),N31/1000*O31,"") | R31: 강판(PLATE) | S31: =IF(R31="","",IFERROR(INDEX(제작기준!$B$5:$B$30,MATCH(R31,제작기준!$A$5:$A$30,0)),"확인")) -> 0.05
A32: 13 | B32: STAIR TREAD | C32: F.B-25x245x600 | E32: SS275 | F32: SET | M32: =IF($B32="","",SUMPRODUCT(G32:L32,$G$8:$L$8)) -> 0 | N32: =IF($B32="","",M32*(1+S32)) -> 0 | O32: =IF(OR($B32="",$F32<>"KG"),"",IFERROR(IF($B32="PLATE",ROUND(2000/($D32*제작기준!$L$8),3),IF($B32="ROUND BAR",ROUND(4000/($D32*제작기준!$L$8),3),INDEX(제작기준!$H$5:$H$175,MATCH($B32&"|"&$D32,제작기준!$I$5:$I$175,0)))),"DB확인")) | P32: =IF(ISNUMBER(O32),M32/1000*O32,"") | Q32: =IF(ISNUMBER(O32),N32/1000*O32,"") | R32: 강판(PLATE) | S32: =IF(R32="","",IFERROR(INDEX(제작기준!$B$5:$B$30,MATCH(R32,제작기준!$A$5:$A$30,0)),"확인")) -> 0.05
A33: 14 | B33: HEX BOLT,NUT | C33: M12x25L | E33: 4T | F33: SET | M33: =IF($B33="","",SUMPRODUCT(G33:L33,$G$8:$L$8)) -> 0 | N33: =IF($B33="","",M33*(1+S33)) -> 0 | O33: =IF(OR($B33="",$F33<>"KG"),"",IFERROR(IF($B33="PLATE",ROUND(2000/($D33*제작기준!$L$8),3),IF($B33="ROUND BAR",ROUND(4000/($D33*제작기준!$L$8),3),INDEX(제작기준!$H$5:$H$175,MATCH($B33&"|"&$D33,제작기준!$I$5:$I$175,0)))),"DB확인")) | P33: =IF(ISNUMBER(O33),M33/1000*O33,"") | Q33: =IF(ISNUMBER(O33),N33/1000*O33,"") | R33: 일반볼트 | S33: =IF(R33="","",IFERROR(INDEX(제작기준!$B$5:$B$30,MATCH(R33,제작기준!$A$5:$A$30,0)),"확인")) -> 0.05
A34: 15 | B34: H.T BOLT,NUT,2P/W | C34: M16x55L | E34: F10T | F34: SET | M34: =IF($B34="","",SUMPRODUCT(G34:L34,$G$8:$L$8)) -> 0 | N34: =IF($B34="","",M34*(1+S34)) -> 0 | O34: =IF(OR($B34="",$F34<>"KG"),"",IFERROR(IF($B34="PLATE",ROUND(2000/($D34*제작기준!$L$8),3),IF($B34="ROUND BAR",ROUND(4000/($D34*제작기준!$L$8),3),INDEX(제작기준!$H$5:$H$175,MATCH($B34&"|"&$D34,제작기준!$I$5:$I$175,0)))),"DB확인")) | P34: =IF(ISNUMBER(O34),M34/1000*O34,"") | Q34: =IF(ISNUMBER(O34),N34/1000*O34,"") | R34: 고장력볼트 | S34: =IF(R34="","",IFERROR(INDEX(제작기준!$B$5:$B$30,MATCH(R34,제작기준!$A$5:$A$30,0)),"확인")) -> 0.03 | T34: 원본 양식 '일반볼트 5%' → 매뉴얼 고장력볼트 3%로 정정
A35: 16 | B35: HANDRAIL 제작,설치(WALKWAY용) | F35: M | M35: =IF($B35="","",SUMPRODUCT(G35:L35,$G$8:$L$8)) -> 0 | N35: =IF($B35="","",M35*(1+S35)) -> 0 | O35: =IF(OR($B35="",$F35<>"KG"),"",IFERROR(IF($B35="PLATE",ROUND(2000/($D35*제작기준!$L$8),3),IF($B35="ROUND BAR",ROUND(4000/($D35*제작기준!$L$8),3),INDEX(제작기준!$H$5:$H$175,MATCH($B35&"|"&$D35,제작기준!$I$5:$I$175,0)))),"DB확인")) | P35: =IF(ISNUMBER(O35),M35/1000*O35,"") | Q35: =IF(ISNUMBER(O35),N35/1000*O35,"") | R35: 없음 | S35: =IF(R35="","",IFERROR(INDEX(제작기준!$B$5:$B$30,MATCH(R35,제작기준!$A$5:$A$30,0)),"확인")) -> 0 | T35: S3624 (품셈 별도)
A36: 17 | B36: HANDRAIL 제작,설치(STAIR용) | F36: M | M36: =IF($B36="","",SUMPRODUCT(G36:L36,$G$8:$L$8)) -> 0 | N36: =IF($B36="","",M36*(1+S36)) -> 0 | O36: =IF(OR($B36="",$F36<>"KG"),"",IFERROR(IF($B36="PLATE",ROUND(2000/($D36*제작기준!$L$8),3),IF($B36="ROUND BAR",ROUND(4000/($D36*제작기준!$L$8),3),INDEX(제작기준!$H$5:$H$175,MATCH($B36&"|"&$D36,제작기준!$I$5:$I$175,0)))),"DB확인")) | P36: =IF(ISNUMBER(O36),M36/1000*O36,"") | Q36: =IF(ISNUMBER(O36),N36/1000*O36,"") | R36: 없음 | S36: =IF(R36="","",IFERROR(INDEX(제작기준!$B$5:$B$30,MATCH(R36,제작기준!$A$5:$A$30,0)),"확인")) -> 0 | T36: S3623 (품셈 별도)
M37: =IF($B37="","",SUMPRODUCT(G37:L37,$G$8:$L$8)) | N37: =IF($B37="","",M37*(1+S37)) | O37: =IF(OR($B37="",$F37<>"KG"),"",IFERROR(IF($B37="PLATE",ROUND(2000/($D37*제작기준!$L$8),3),IF($B37="ROUND BAR",ROUND(4000/($D37*제작기준!$L$8),3),INDEX(제작기준!$H$5:$H$175,MATCH($B37&"|"&$D37,제작기준!$I$5:$I$175,0)))),"DB확인")) | P37: =IF(ISNUMBER(O37),M37/1000*O37,"") | Q37: =IF(ISNUMBER(O37),N37/1000*O37,"") | S37: =IF(R37="","",IFERROR(INDEX(제작기준!$B$5:$B$30,MATCH(R37,제작기준!$A$5:$A$30,0)),"확인"))
M38: =IF($B38="","",SUMPRODUCT(G38:L38,$G$8:$L$8)) | N38: =IF($B38="","",M38*(1+S38)) | O38: =IF(OR($B38="",$F38<>"KG"),"",IFERROR(IF($B38="PLATE",ROUND(2000/($D38*제작기준!$L$8),3),IF($B38="ROUND BAR",ROUND(4000/($D38*제작기준!$L$8),3),INDEX(제작기준!$H$5:$H$175,MATCH($B38&"|"&$D38,제작기준!$I$5:$I$175,0)))),"DB확인")) | P38: =IF(ISNUMBER(O38),M38/1000*O38,"") | Q38: =IF(ISNUMBER(O38),N38/1000*O38,"") | S38: =IF(R38="","",IFERROR(INDEX(제작기준!$B$5:$B$30,MATCH(R38,제작기준!$A$5:$A$30,0)),"확인"))
M39: =IF($B39="","",SUMPRODUCT(G39:L39,$G$8:$L$8)) | N39: =IF($B39="","",M39*(1+S39)) | O39: =IF(OR($B39="",$F39<>"KG"),"",IFERROR(IF($B39="PLATE",ROUND(2000/($D39*제작기준!$L$8),3),IF($B39="ROUND BAR",ROUND(4000/($D39*제작기준!$L$8),3),INDEX(제작기준!$H$5:$H$175,MATCH($B39&"|"&$D39,제작기준!$I$5:$I$175,0)))),"DB확인")) | P39: =IF(ISNUMBER(O39),M39/1000*O39,"") | Q39: =IF(ISNUMBER(O39),N39/1000*O39,"") | S39: =IF(R39="","",IFERROR(INDEX(제작기준!$B$5:$B$30,MATCH(R39,제작기준!$A$5:$A$30,0)),"확인"))
B40: 계 (단위 KG 소재) | G40: =SUMIF($F$20:$F$39,"KG",G20:G39) -> 0 | H40: =SUMIF($F$20:$F$39,"KG",H20:H39) -> 0 | I40: =SUMIF($F$20:$F$39,"KG",I20:I39) -> 0 | J40: =SUMIF($F$20:$F$39,"KG",J20:J39) -> 0 | K40: =SUMIF($F$20:$F$39,"KG",K20:K39) -> 0 | L40: =SUMIF($F$20:$F$39,"KG",L20:L39) -> 0 | M40: =SUMIF($F$20:$F$39,"KG",M20:M39) -> 0 | N40: =SUMIF($F$20:$F$39,"KG",N20:N39) -> 0 | P40: =SUM(P20:P39) -> 0 | Q40: =SUM(Q20:Q39) -> 0
B42: SCRAP량 (KG) = (소재 GROSS - 제작 NET) x 70% | G42: =(N40-M40)*제작기준!$L$7 -> 0
...

Sheet 555 입력SHEET
A1: 공종 | B1: 구분 | C1: 순번 | D1: 비목 | E1: 코드 | F1: 사도 | G1: 명칭 | H1: 단위 | I1: 수량(TON) | J1: 단가 | K1: 적용변수 | L1: F01 | M1: F02 | N1: F03 | O1: F04 | P1: F06 | Q1: Q08 | R1: Q09 | S1: C04 | T1: 품종(키) | U1: 구간 | V1: 검색키
A2: 555 | B2: M | C2: 100 | D2: X | E2: W6151101 | G2: 지주류 공장 제작 0.5 TON 이하 | H2: TON | I2: =SUMPRODUCT((제작물량산출!$G$12:$L$12=E2)*(제작물량산출!$G$6:$L$6="공장")*제작물량산출!$G$10:$L$10)/1000 -> 0 | K2: ="F01="&L2&",F02="&M2&",F03="&N2&",F04="&O2&",F06="&P2&",Q08="&Q2&",Q09="&R2&",C04="&S2&"," -> F01=0.7,F02=0,F03=1.4,F04=0.37,F06=85.5,Q08=0,Q09=0,C04=0.1, | L2: 0.7 | M2: 0 | N2: 1.4 | O2: 0.37 | P2: 85.5 | Q2: 0 | R2: 0 | S2: 0.1 | T2: 지주류 | U2: 1 | V2: =T2&"|"&U2 -> 지주류|1
A3: 555 | B3: M | C3: 200 | D3: X | E3: W6151102 | G3: 지주류 공장 제작 0.5~2.5 TON | H3: TON | I3: =SUMPRODUCT((제작물량산출!$G$12:$L$12=E3)*(제작물량산출!$G$6:$L$6="공장")*제작물량산출!$G$10:$L$10)/1000 -> 0 | K3: ="F01="&L3&",F02="&M3&",F03="&N3&",F04="&O3&",F06="&P3&",Q08="&Q3&",Q09="&R3&",C04="&S3&"," -> F01=0.5,F02=0,F03=1.4,F04=0.37,F06=85.5,Q08=0,Q09=0,C04=0.1, | L3: 0.5 | M3: 0 | N3: 1.4 | O3: 0.37 | P3: 85.5 | Q3: 0 | R3: 0 | S3: 0.1 | T3: 지주류 | U3: 2 | V3: =T3&"|"&U3 -> 지주류|2
A4: 555 | B4: M | C4: 300 | D4: X | E4: W6151103 | G4: 지주류 공장 제작 2.5~5 TON | H4: TON | I4: =SUMPRODUCT((제작물량산출!$G$12:$L$12=E4)*(제작물량산출!$G$6:$L$6="공장")*제작물량산출!$G$10:$L$10)/1000 -> 0 | K4: ="F01="&L4&",F02="&M4&",F03="&N4&",F04="&O4&",F06="&P4&",Q08="&Q4&",Q09="&R4&",C04="&S4&"," -> F01=0.4,F02=0,F03=1.4,F04=0.37,F06=85.5,Q08=0,Q09=0,C04=0.1, | L4: 0.4 | M4: 0 | N4: 1.4 | O4: 0.37 | P4: 85.5 | Q4: 0 | R4: 0 | S4: 0.1 | T4: 지주류 | U4: 3 | V4: =T4&"|"&U4 -> 지주류|3
A5: 555 | B5: M | C5: 400 | D5: X | E5: W6151104 | G5: 지주류 공장 제작 5 TON 이상 | H5: TON | I5: =SUMPRODUCT((제작물량산출!$G$12:$L$12=E5)*(제작물량산출!$G$6:$L$6="공장")*제작물량산출!$G$10:$L$10)/1000 -> 0 | K5: ="F01="&L5&",F02="&M5&",F03="&N5&",F04="&O5&",F06="&P5&",Q08="&Q5&",Q09="&R5&",C04="&S5&"," -> F01=0,F02=0,F03=1.4,F04=0.37,F06=85.5,Q08=0,Q09=0,C04=0.1, | L5: 0 | M5: 0 | N5: 1.4 | O5: 0.37 | P5: 85.5 | Q5: 0 | R5: 0 | S5: 0.1 | T5: 지주류 | U5: 4 | V5: =T5&"|"&U5 -> 지주류|4
A6: 555 | B6: M | C6: 500 | D6: X | E6: W6151111 | G6: 프레임류 공장 제작 0.5 TON 이하 | H6: TON | I6: =SUMPRODUCT((제작물량산출!$G$12:$L$12=E6)*(제작물량산출!$G$6:$L$6="공장")*제작물량산출!$G$10:$L$10)/1000 -> 0 | K6: ="F01="&L6&",F02="&M6&",F03="&N6&",F04="&O6&",F06="&P6&",Q08="&Q6&",Q09="&R6&",C04="&S6&"," -> F01=0.7,F02=0.2,F03=1.43,F04=0.36,F06=94.5,Q08=0,Q09=0,C04=0.1, | L6: 0.7 | M6: 0.2 | N6: 1.43 | O6: 0.36 | P6: 94.5 | Q6: 0 | R6: 0 | S6: 0.1 | T6: 프레임류 | U6: 1 | V6: =T6&"|"&U6 -> 프레임류|1
A7: 555 | B7: M | C7: 600 | D7: X | E7: W6151112 | G7: 프레임류 공장 제작 0.5~2.5 TON | H7: TON | I7: =SUMPRODUCT((제작물량산출!$G$12:$L$12=E7)*(제작물량산출!$G$6:$L$6="공장")*제작물량산출!$G$10:$L$10)/1000 -> 0 | K7: ="F01="&L7&",F02="&M7&",F03="&N7&",F04="&O7&",F06="&P7&",Q08="&Q7&",Q09="&R7&",C04="&S7&"," -> F01=0.5,F02=0.2,F03=1.43,F04=0.36,F06=94.5,Q08=0,Q09=0,C04=0.1, | L7: 0.5 | M7: 0.2 | N7: 1.43 | O7: 0.36 | P7: 94.5 | Q7: 0 | R7: 0 | S7: 0.1 | T7: 프레임류 | U7: 2 | V7: =T7&"|"&U7 -> 프레임류|2
A8: 555 | B8: M | C8: 700 | D8: X | E8: W6151113 | G8: 프레임류 공장 제작 2.5~5 TON | H8: TON | I8: =SUMPRODUCT((제작물량산출!$G$12:$L$12=E8)*(제작물량산출!$G$6:$L$6="공장")*제작물량산출!$G$10:$L$10)/1000 -> 0 | K8: ="F01="&L8&",F02="&M8&",F03="&N8&",F04="&O8&",F06="&P8&",Q08="&Q8&",Q09="&R8&",C04="&S8&"," -> F01=0.4,F02=0.2,F03=1.43,F04=0.36,F06=94.5,Q08=0,Q09=0,C04=0.1, | L8: 0.4 | M8: 0.2 | N8: 1.43 | O8: 0.36 | P8: 94.5 | Q8: 0 | R8: 0 | S8: 0.1 | T8: 프레임류 | U8: 3 | V8: =T8&"|"&U8 -> 프레임류|3
A9: 555 | B9: M | C9: 800 | D9: X | E9: W6151114 | G9: 프레임류 공장 제작 5 TON 이상 | H9: TON | I9: =SUMPRODUCT((제작물량산출!$G$12:$L$12=E9)*(제작물량산출!$G$6:$L$6="공장")*제작물량산출!$G$10:$L$10)/1000 -> 0 | K9: ="F01="&L9&",F02="&M9&",F03="&N9&",F04="&O9&",F06="&P9&",Q08="&Q9&",Q09="&R9&",C04="&S9&"," -> F01=0,F02=0.2,F03=1.43,F04=0.36,F06=94.5,Q08=0,Q09=0,C04=0.1, | L9: 0 | M9: 0.2 | N9: 1.43 | O9: 0.36 | P9: 94.5 | Q9: 0 | R9: 0 | S9: 0.1 | T9: 프레임류 | U9: 4 | V9: =T9&"|"&U9 -> 프레임류|4
A10: 555 | B10: M | C10: 900 | D10: X | E10: W6151121 | G10: 조립곡면 또는 특수 입체 트러스 0.5 TON 이하 | H10: TON | I10: =SUMPRODUCT((제작물량산출!$G$12:$L$12=E10)*(제작물량산출!$G$6:$L$6="공장")*제작물량산출!$G$10:$L$10)/1000 -> 0 | K10: ="F01="&L10&",F02="&M10&",F03="&N10&",F04="&O10&",F06="&P10&",Q08="&Q10&",Q09="&R10&",C04="&S10&"," -> F01=0.7,F02=0.5,F03=1.43,F04=0.36,F06=94.5,Q08=0,Q09=0,C04=0.1, | L10: 0.7 | M10: 0.5 | N10: 1.43 | O10: 0.36 | P10: 94.5 | Q10: 0 | R10: 0 | S10: 0.1 | T10: 조립곡면 또는 특수 입체 트러스 | U10: 1 | V10: =T10&"|"&U10 -> 조립곡면 또는 특수 입체 트러스|1
A11: 555 | B11: M | C11: 1000 | D11: X | E11: W6151122 | G11: 조립곡면 또는 특수 입체 트러스 0.5~2.5 TON | H11: TON | I11: =SUMPRODUCT((제작물량산출!$G$12:$L$12=E11)*(제작물량산출!$G$6:$L$6="공장")*제작물량산출!$G$10:$L$10)/1000 -> 0 | K11: ="F01="&L11&",F02="&M11&",F03="&N11&",F04="&O11&",F06="&P11&",Q08="&Q11&",Q09="&R11&",C04="&S11&"," -> F01=0.5,F02=0.5,F03=1.43,F04=0.36,F06=94.5,Q08=0,Q09=0,C04=0.1, | L11: 0.5 | M11: 0.5 | N11: 1.43 | O11: 0.36 | P11: 94.5 | Q11: 0 | R11: 0 | S11: 0.1 | T11: 조립곡면 또는 특수 입체 트러스 | U11: 2 | V11: =T11&"|"&U11 -> 조립곡면 또는 특수 입체 트러스|2
A12: 555 | B12: M | C12: 1100 | D12: X | E12: W6151123 | G12: 조립곡면 또는 특수 입체 트러스 2.5~5 TON | H12: TON | I12: =SUMPRODUCT((제작물량산출!$G$12:$L$12=E12)*(제작물량산출!$G$6:$L$6="공장")*제작물량산출!$G$10:$L$10)/1000 -> 0 | K12: ="F01="&L12&",F02="&M12&",F03="&N12&",F04="&O12&",F06="&P12&",Q08="&Q12&",Q09="&R12&",C04="&S12&"," -> F01=0.4,F02=0.5,F03=1.43,F04=0.36,F06=94.5,Q08=0,Q09=0,C04=0.1, | L12: 0.4 | M12: 0.5 | N12: 1.43 | O12: 0.36 | P12: 94.5 | Q12: 0 | R12: 0 | S12: 0.1 | T12: 조립곡면 또는 특수 입체 트러스 | U12: 3 | V12: =T12&"|"&U12 -> 조립곡면 또는 특수 입체 트러스|3
A13: 555 | B13: M | C13: 1200 | D13: X | E13: W6151124 | G13: 조립곡면 또는 특수 입체 트러스 5 TON 이상 | H13: TON | I13: =SUMPRODUCT((제작물량산출!$G$12:$L$12=E13)*(제작물량산출!$G$6:$L$6="공장")*제작물량산출!$G$10:$L$10)/1000 -> 0 | K13: ="F01="&L13&",F02="&M13&",F03="&N13&",F04="&O13&",F06="&P13&",Q08="&Q13&",Q09="&R13&",C04="&S13&"," -> F01=0,F02=0.5,F03=1.43,F04=0.36,F06=94.5,Q08=0,Q09=0,C04=0.1, | L13: 0 | M13: 0.5 | N13: 1.43 | O13: 0.36 | P13: 94.5 | Q13: 0 | R13: 0 | S13: 0.1 | T13: 조립곡면 또는 특수 입체 트러스 | U13: 4 | V13: =T13&"|"&U13 -> 조립곡면 또는 특수 입체 트러스|4
... A69: 555 | B69: M | C69: 6800 | D69: X | E69: W6151264 | G69: 베이스 플레이트류 5 TON 이상 | H69: TON | I69: =SUMPRODUCT((제작물량산출!$G$12:$L$12=E69)*(제작물량산출!$G$6:$L$6="공장")*제작물량산출!$G$10:$L$10)/1000 -> 0 | K69: ="F01="&L69&",F02="&M69&",F03="&N69&",F04="&O69&",F06="&P69&",Q08="&Q69&",Q09="&R69&",C04="&S69&"," -> F01=0,F02=0.35,F03=2.59,F04=0.65,F06=159.75,Q08=0,Q09=0,C04=0.1, | L69: 0 | M69: 0.35 | N69: 2.59 | O69: 0.65 | P69: 159.75 | Q69: 0 | R69: 0 | S69: 0.1 | T69: 베이스 플레이트류 | U69: 4 | V69: =T69&"|"&U69 -> 베이스 플레이트류|4
A71: ※ 원본 '555 제작공사 입력SHEET'의 구조(공종~C04)를 유지하고 수량(I열)을 제작물량산출에서 자동 연동(제작분류=공장인 제작품만). 파란 글씨=원본 값.

Sheet 제작기준
A1: 제작기준 (재료 할증율 / 도장면적 원단위 DB / 용접 상수) - 기계 적산 설계 MANUAL 근거
A2: 파란 글씨=매뉴얼 기준값. 3-5 다. 도장소요 면적표, 일반사항 5. 재료의 할증율, 3-4 용접공사 사).
A4: 할증 구분 | B4: 할증율 | E4: 형강류 구분 | F4: 규격키 | G4: ㎡/m | H4: ㎡/TON | I4: 검색키 | K4: 적용 상수 | L4: 값 | M4: 근거 | N4: 품종 목록
A5: 원형철근 | B5: 0.05 | E5: PIPE | F5: 6A | G5: 0.03299 | H5: 78.727 | I5: =E5&"|"&F5 -> PIPE|6A | K5: 용접 전력량(KWH/M) | L5: 2.25 | M5: 3-4 사) 제작공사 평균공량 | N5: 지주류
A6: 이형철근 | B6: 0.045 | E6: PIPE | F6: 8A | G6: 0.04335 | H6: 65.292 | I6: =E6&"|"&F6 -> PIPE|8A | K6: 용접봉량(KG/M) | L6: 0.33 | M6: 3-4 사) | N6: 프레임류
A7: 일반볼트 | B7: 0.05 | E7: PIPE | F7: 10A | G7: 0.05435 | H7: 62.759 | I7: =E7&"|"&F7 -> PIPE|10A | K7: SCRAP 공제율 | L7: 0.7 | M7: 6-3 (소재중량-제작중량)x70% | N7: 조립곡면 또는 특수 입체 트러스
A8: 고장력볼트 | B8: 0.03 | E8: PIPE | F8: 15A | G8: 0.06817 | H8: 54.538 | I8: =E8&"|"&F8 -> PIPE|15A | K8: 강재 비중(ton/㎥) | L8: 7.85 | M8: 도장면적 PLATE·ROUND BAR 산식 | N8: 대차 프레임류
A9: 강판(PLATE) | B9: 0.05 | E9: PIPE | F9: 20A | G9: 0.08545 | H9: 53.407 | I9: =E9&"|"&F9 -> PIPE|20A | N9: 모터베드류
A10: 강관(50A이하) | B10: 0.05 | E10: PIPE | F10: 25A | G10: 0.10681 | H10: 43.598 | I10: =E10&"|"&F10 -> PIPE|25A | K10: ※ PLATE(양면)㎡/TON = 2000/(두께mm x 7.85), ROUND BAR ㎡/TON = 4000/(직경mm x 7.85) → 매뉴얼 표와 일치, 수식 처리. | N10: 각호퍼류
A11: 강관(50A초과) | B11: 0.025 | E11: PIPE | F11: 32A | G11: 0.13415 | H11: 42.451 | I11: =E11&"|"&F11 -> PIPE|32A | K11: ※ 원본 표의 오기 정정: 344X348X10X16 '20257.'→2.0257, 594X302X14X23 '2.23199'→2.3199, 482X300X11X15 '8.36'→18.36, '194X398X11X18'→394X398X11X18, '15X70X6X8.5'→150X70X6X8.5, 198X99X4.5X7 '42.'→42.0 | N11: 각 탱크류
A12: STS 강판 | B12: 0.1 | E12: PIPE | F12: 40A | G12: 0.15268 | H12: 42.061 | I12: =E12&"|"&F12 -> PIPE|40A | N12: 환 호퍼류
A13: STS 강관 | B13: 0.05 | E13: PIPE | F13: 50A | G13: 0.19007 | H13: 37.122 | I13: =E13&"|"&F13 -> PIPE|50A | N13: 각 슈트류
A14: 동판 | B14: 0.05 | E14: PIPE | F14: 65A | G14: 0.2397 | H14: 37.808 | I14: =E14&"|"&F14 -> PIPE|65A | N14: 환 슈트류
A15: 동관 | B15: 0.025 | E15: PIPE | F15: 80A | G15: 0.27992 | H15: 32.97 | I15: =E15&"|"&F15 -> PIPE|80A | N15: 호퍼라이너(곡관)
A16: 대형형강(100mm이상) | B16: 0.035 | E16: PIPE | F16: 90A | G16: 0.3192 | H16: 32.771 | I16: =E16&"|"&F16 -> PIPE|90A | N16: 호퍼라이너(평판)
A17: 소형형강 | B17: 0.025 | E17: PIPE | F17: 100A | G17: 0.3591 | H17: 29.433 | I17: =E17&"|"&F17 -> PIPE|100A | N17: 계단류
A18: 경량 형강, 각 파이프 | B18: 0.025 | E18: PIPE | F18: 125A | G18: 0.4392 | H18: 27.279 | I18: =E18&"|"&F18 -> PIPE|125A | N18: DECK류
A19: 봉강 | B19: 0.025 | E19: PIPE | F19: 150A | G19: 0.519 | H19: 27.031 | I19: =E19&"|"&F19 -> PIPE|150A | N19: 철피연돌류
A20: 평강대강 | B20: 0.025 | E20: PIPE | F20: 175A | G20: 0.5991 | H20: 22.16 | I20: =E20&"|"&F20 -> PIPE|175A | N20: 철피연돌류 가조립
A21: 리벳(제품) | B21: 0.05 | E21: PIPE | F21: 200A | G21: 0.6795 | H21: 22.353 | I21: =E21&"|"&F21 -> PIPE|200A | N21: 베이스 플레이트류
A22: 프레스 접합식 STS 강관 | B22: 0.025 | E22: PIPE | F22: 225A | G22: 0.7596 | H22: 21.101 | I22: =E22&"|"&F22 -> PIPE|225A
A23: 배관 FITTING류(VALVE 外) | B23: 0.015 | E23: PIPE | F23: 250A | G23: 0.8401 | H23: 20.39 | I23: =E23&"|"&F23 -> PIPE|250A
A24: 보온재(PIPE COVER) | B24: 0 | E24: PIPE | F24: 300A | G24: 1.0006 | H24: 18.598 | I24: =E24&"|"&F24 -> PIPE|300A
A25: 보온재(BOARD) | B25: 0.035 | E25: PIPE | F25: 350A | G25: 1.1172 | H25: 17.134 | I25: =E25&"|"&F25 -> PIPE|350A
A26: 조립식 PIPE SHEET | B26: 0.025 | E26: PIPE | F26: 400A | G26: 1.2767 | H26: 16.453 | I26: =E26&"|"&F26 -> PIPE|400A
A27: 조립식 PIPE FITTING(VALVE 外) | B27: 0.05 | E27: PIPE | F27: 450A | G27: 1.4363 | H27: 16.415 | I27: =E27&"|"&F27 -> PIPE|450A
A28: 내화 벽돌(정형) | B28: 0.03 | E28: PIPE | F28: 500A | G28: 1.5959 | H28: 16.385 | I28: =E28&"|"&F28 -> PIPE|500A
A29: 부정형내화물(CASTABLE 포함) | B29: 0.1 | E29: ANGLE | F29: 20X3 | G29: 0.07657 | H29: 86.53 | I29: =E29&"|"&F29 -> ANGLE|20X3
A30: 없음 | B30: 0 | E30: ANGLE | F30: 25X3 | G30: 0.09657 | H30: 86.19 | I30: =E30&"|"&F30 -> ANGLE|25X3
E31: ANGLE | F31: 30X3 | G31: 0.11657 | H31: 85.97 | I31: =E31&"|"&F31 -> ANGLE|30X3
E32: ANGLE | F32: 30X5 | G32: 0.11571 | H32: 53.68 | I32: =E32&"|"&F32 -> ANGLE|30X5
E33: ANGLE | F33: 35X3 | G33: 0.13635 | H33: 85.3 | I33: =E33&"|"&F33 -> ANGLE|35X3
E34: ANGLE | F34: 35X5 | G34: 0.13549 | H34: 53.03 | I34: =E34&"|"&F34 -> ANGLE|35X5
E35: ANGLE | F35: 40X3 | G35: 0.15635 | H35: 85.25 | I35: =E35&"|"&F35 -> ANGLE|40X3
E36: ANGLE | F36: 40X5 | G36: 0.15549 | H36: 52.75 | I36: =E36&"|"&F36 -> ANGLE|40X5
E37: ANGLE | F37: 45X3 | G37: 0.17463 | H37: 83.57 | I37: =E37&"|"&F37 -> ANGLE|45X3
E38: ANGLE | F38: 45X4 | G38: 0.17463 | H38: 63.71 | I38: =E38&"|"&F38 -> ANGLE|45X4
E39: ANGLE | F39: 45X6 | G39: 0.17335 | H39: 43.78 | I39: =E39&"|"&F39 -> ANGLE|45X6
E40: ANGLE | F40: 45X8 | G40: 0.17335 | H40: 33.64 | I40: =E40&"|"&F40 -> ANGLE|45X8
E41: ANGLE | F41: 50X4 | G41: 0.19463 | H41: 63.71 | I41: =E41&"|"&F41 -> ANGLE|50X4
...

Sheet 배관기본물량
A1: 4-2. 배관 공사 기본 물량 산출 (소재 내역)
A2: 범례: 파란 글씨=입력, 검정=수식, 노란 배경=입력 필요. PIPE는 구경·SCH로 단중 자동(배관기준). FITTING/VALVE는 개당 단중 입력. 집계값만 있으면 '직접중량(kg)'에 입력(수량x단중 대체).
A3: 근거: MANUAL 3-2 배관공사 (PIPE/FITTING 단위중량, FITTING류 길이 공제는 50A 이상 2D 도면 산출 시).
W5: ▼ 배관집계(4-1) FLAG 자동 조회
A6: NO | B6: 구분 | C6: 설치장소 | D6: 유체 | E6: 적용압력 | F6: 재질 | G6: 품목 | H6: 품명 / 규격 | I6: 구경(A) | J6: SCH | K6: 단위 | L6: 수량 | M6: 단중-PIPE(DB) (KG/M) | N6: 단중-입력 (KG/EA) | O6: 직접중량 (KG) | P6: 중량(KG) | Q6: P/F | R6: PIPE 길이(M) | S6: 도장적용 (자동) | T6: 비 고 | U6: 4-1 집계재질 | V6: 할증 품종 (수동) | W6: 보온 | X6: N.D.T | Y6: 산세 | Z6: FLUSHING | AA6: PAINT | AB6: SUPPLY | AC6: 4-1 키 | AD6: 보온 구분 | AE6: ELBOW 각도(°) | AF6: 비규격EL 길이(M) | AG6: 무도장 (Y/N)
A7: 1 | B7: 설치 | C7: 옥외 | D7: WATER | E7: 5kg/cm2이상 | F7: STPG370S | G7: PIPE | H7: PIPE | I7: 15 | J7: SCH40 | K7: M | L7: 1.837 | M7: =IF($G7<>"PIPE","",IFERROR(1/(1/INDEX(배관단중표!$B$7:$W$41,MATCH($I7,배관단중표!$A$7:$A$41,0),MATCH(IF($J7="SPP","SPP",IF(LEFT($F7,3)="STS",IF(ISNUMBER(SEARCH("316",$F7)),"STS316","STS304"),"SPPS")&"|"&$J7),배관단중표!$B$6:$W$6,0))),"DB확인")) -> 1.31 | P7: =IF($G7="","",IFERROR(IF(O7<>"",O7,L7*IF(G7="PIPE",M7,N7)),0)) -> 2.40647 | Q7: =IF($G7="","",IF(G7="PIPE","P","F")) -> P | R7: =IF($G7<>"PIPE","",IFERROR(IF(O7<>"",O7/M7,IF(K7="M",L7,"")),"")) -> 1.837 | S7: =IF($G7<>"PIPE","",IF(AND($AA7="○",OR($W7<>"○",배관기준!$AG$17="N"),$C7<>"매설",LEFT($F7,3)<>"STS",LEFT($F7,3)<>"SUS"),"Y","N")) -> N | U7: STPG370S | W7: =IF($G7="","",IFERROR(INDEX(배관집계!$AC$7:$AC$32,MATCH($AC7,배관집계!$AJ$7:$AJ$32,0))&"","")) -> ○ | X7: =IF($G7="","",IFERROR(INDEX(배관집계!$AD$7:$AD$32,MATCH($AC7,배관집계!$AJ$7:$AJ$32,0))&"","")) -> ○ | Y7: =IF($G7="","",IFERROR(INDEX(배관집계!$AE$7:$AE$32,MATCH($AC7,배관집계!$AJ$7:$AJ$32,0))&"","")) -> × | Z7: =IF($G7="","",IFERROR(INDEX(배관집계!$AF$7:$AF$32,MATCH($AC7,배관집계!$AJ$7:$AJ$32,0))&"","")) -> ○ | AA7: =IF($G7="","",IFERROR(INDEX(배관집계!$AG$7:$AG$32,MATCH($AC7,배관집계!$AJ$7:$AJ$32,0))&"","")) -> × | AB7: =IF($G7="","",IFERROR(INDEX(배관집계!$AH$7:$AH$32,MATCH($AC7,배관집계!$AJ$7:$AJ$32,0))&"","")) -> C/C | AC7: =IF($G7="","",$B7&"|"&$C7&"|"&$E7&"|"&$U7&"|"&$I7) -> 설치|옥외|5kg/cm2이상|STPG370S|15 | AD7: =IF($G7="","",IF($B7<>"설치","",IF($G7="PIPE","PIPE",IF($G7="VALVE",IF(ISNUMBER(SEARCH("GLOBE",$H7)),"GLOBE",IF(ISNUMBER(SEARCH("GATE",$H7)),"GATE",IF(ISNUMBER(SEARCH("BUTTER",$H7)),"BFLY","VALVE기타"))),IF($G7="FITTING",IF(LEFT($H7,5)="ELBOW",IF($AE7=90,"90EL",IF($AE7=45,"45EL","비규격EL")),IF(LEFT($H7,6)="FLANGE","FLANGE",IF(ISNUMBER(SEARCH("TEE",$H7)),"TEE",""))),""))))) -> PIPE | AE7: =IF(AND($G7="FITTING",LEFT($H7,5)="ELBOW"),IFERROR(VALUE(LEFT(MID($H7,7,12),MIN(IFERROR(FIND("L",MID($H7,7,12)),99),IFERROR(FIND("S",MID($H7,7,12)),99),IFERROR(FIND(" ",MID($H7,7,12)),99))-1)),""),"") | AF7: =IF($AD7="비규격EL",N($L7)*RADIANS(N($AE7))*보온기준!$F$15*N($I7)*보온기준!$F$16/1000,0) -> 0 | AG7: =IF($G7="","",IF(OR($AA7<>"○",LEFT($F7,3)="STS",LEFT($F7,3)="SUS",$C7="매설"),"Y","N")) -> Y
A8: 2 | B8: 설치 | C8: 옥외 | D8: WATER | E8: 5kg/cm2이상 | F8: STPG370S | G8: PIPE | H8: PIPE | I8: 50 | J8: SCH40 | K8: M | L8: 17.658 | M8: =IF($G8<>"PIPE","",IFERROR(1/(1/INDEX(배관단중표!$B$7:$W$41,MATCH($I8,배관단중표!$A$7:$A$41,0),MATCH(IF($J8="SPP","SPP",IF(LEFT($F8,3)="STS",IF(ISNUMBER(SEARCH("316",$F8)),"STS316","STS304"),"SPPS")&"|"&$J8),배관단중표!$B$6:$W$6,0))),"DB확인")) -> 5.44 | P8: =IF($G8="","",IFERROR(IF(O8<>"",O8,L8*IF(G8="PIPE",M8,N8)),0)) -> 96.05952 | Q8: =IF($G8="","",IF(G8="PIPE","P","F")) -> P | R8: =IF($G8<>"PIPE","",IFERROR(IF(O8<>"",O8/M8,IF(K8="M",L8,"")),"")) -> 17.658 | S8: =IF($G8<>"PIPE","",IF(AND($AA8="○",OR($W8<>"○",배관기준!$AG$17="N"),$C8<>"매설",LEFT($F8,3)<>"STS",LEFT($F8,3)<>"SUS"),"Y","N")) -> N | U8: STPG370S | W8: =IF($G8="","",IFERROR(INDEX(배관집계!$AC$7:$AC$32,MATCH($AC8,배관집계!$AJ$7:$AJ$32,0))&"","")) -> ○ | X8: =IF($G8="","",IFERROR(INDEX(배관집계!$AD$7:$AD$32,MATCH($AC8,배관집계!$AJ$7:$AJ$32,0))&"","")) -> ○ | Y8: =IF($G8="","",IFERROR(INDEX(배관집계!$AE$7:$AE$32,MATCH($AC8,배관집계!$AJ$7:$AJ$32,0))&"","")) -> × | Z8: =IF($G8="","",IFERROR(INDEX(배관집계!$AF$7:$AF$32,MATCH($AC8,배관집계!$AJ$7:$AJ$32,0))&"","")) -> ○ | AA8: =IF($G8="","",IFERROR(INDEX(배관집계!$AG$7:$AG$32,MATCH($AC8,배관집계!$AJ$7:$AJ$32,0))&"","")) -> × | AB8: =IF($G8="","",IFERROR(INDEX(배관집계!$AH$7:$AH$32,MATCH($AC8,배관집계!$AJ$7:$AJ$32,0))&"","")) -> C/C | AC8: =IF($G8="","",$B8&"|"&$C8&"|"&$E8&"|"&$U8&"|"&$I8) -> 설치|옥외|5kg/cm2이상|STPG370S|50 | AD8: =IF($G8="","",IF($B8<>"설치","",IF($G8="PIPE","PIPE",IF($G8="VALVE",IF(ISNUMBER(SEARCH("GLOBE",$H8)),"GLOBE",IF(ISNUMBER(SEARCH("GATE",$H8)),"GATE",IF(ISNUMBER(SEARCH("BUTTER",$H8)),"BFLY","VALVE기타"))),IF($G8="FITTING",IF(LEFT($H8,5)="ELBOW",IF($AE8=90,"90EL",IF($AE8=45,"45EL","비규격EL")),IF(LEFT($H8,6)="FLANGE","FLANGE",IF(ISNUMBER(SEARCH("TEE",$H8)),"TEE",""))),""))))) -> PIPE | AE8: =IF(AND($G8="FITTING",LEFT($H8,5)="ELBOW"),IFERROR(VALUE(LEFT(MID($H8,7,12),MIN(IFERROR(FIND("L",MID($H8,7,12)),99),IFERROR(FIND("S",MID($H8,7,12)),99),IFERROR(FIND(" ",MID($H8,7,12)),99))-1)),""),"") | AF8: =IF($AD8="비규격EL",N($L8)*RADIANS(N($AE8))*보온기준!$F$15*N($I8)*보온기준!$F$16/1000,0) -> 0 | AG8: =IF($G8="","",IF(OR($AA8<>"○",LEFT($F8,3)="STS",LEFT($F8,3)="SUS",$C8="매설"),"Y","N")) -> Y
A9: 3 | B9: 설치 | C9: 옥외 | D9: WATER | E9: 5kg/cm2이상 | F9: STPG370S | G9: PIPE | H9: PIPE | I9: 80 | J9: SCH40 | K9: M | L9: 6.18 | M9: =IF($G9<>"PIPE","",IFERROR(1/(1/INDEX(배관단중표!$B$7:$W$41,MATCH($I9,배관단중표!$A$7:$A$41,0),MATCH(IF($J9="SPP","SPP",IF(LEFT($F9,3)="STS",IF(ISNUMBER(SEARCH("316",$F9)),"STS316","STS304"),"SPPS")&"|"&$J9),배관단중표!$B$6:$W$6,0))),"DB확인")) -> 11.3 | P9: =IF($G9="","",IFERROR(IF(O9<>"",O9,L9*IF(G9="PIPE",M9,N9)),0)) -> 69.834 | Q9: =IF($G9="","",IF(G9="PIPE","P","F")) -> P | R9: =IF($G9<>"PIPE","",IFERROR(IF(O9<>"",O9/M9,IF(K9="M",L9,"")),"")) -> 6.18 | S9: =IF($G9<>"PIPE","",IF(AND($AA9="○",OR($W9<>"○",배관기준!$AG$17="N"),$C9<>"매설",LEFT($F9,3)<>"STS",LEFT($F9,3)<>"SUS"),"Y","N")) -> N | U9: STPG370S | W9: =IF($G9="","",IFERROR(INDEX(배관집계!$AC$7:$AC$32,MATCH($AC9,배관집계!$AJ$7:$AJ$32,0))&"","")) -> ○ | X9: =IF($G9="","",IFERROR(INDEX(배관집계!$AD$7:$AD$32,MATCH($AC9,배관집계!$AJ$7:$AJ$32,0))&"","")) -> ○ | Y9: =IF($G9="","",IFERROR(INDEX(배관집계!$AE$7:$AE$32,MATCH($AC9,배관집계!$AJ$7:$AJ$32,0))&"","")) -> × | Z9: =IF($G9="","",IFERROR(INDEX(배관집계!$AF$7:$AF$32,MATCH($AC9,배관집계!$AJ$7:$AJ$32,0))&"","")) -> ○ | AA9: =IF($G9="","",IFERROR(INDEX(배관집계!$AG$7:$AG$32,MATCH($AC9,배관집계!$AJ$7:$AJ$32,0))&"","")) -> × | AB9: =IF($G9="","",IFERROR(INDEX(배관집계!$AH$7:$AH$32,MATCH($AC9,배관집계!$AJ$7:$AJ$32,0))&"","")) -> C/C | AC9: =IF($G9="","",$B9&"|"&$C9&"|"&$E9&"|"&$U9&"|"&$I9) -> 설치|옥외|5kg/cm2이상|STPG370S|80 | AD9: =IF($G9="","",IF($B9<>"설치","",IF($G9="PIPE","PIPE",IF($G9="VALVE",IF(ISNUMBER(SEARCH("GLOBE",$H9)),"GLOBE",IF(ISNUMBER(SEARCH("GATE",$H9)),"GATE",IF(ISNUMBER(SEARCH("BUTTER",$H9)),"BFLY","VALVE기타"))),IF($G9="FITTING",IF(LEFT($H9,5)="ELBOW",IF($AE9=90,"90EL",IF($AE9=45,"45EL","비규격EL")),IF(LEFT($H9,6)="FLANGE","FLANGE",IF(ISNUMBER(SEARCH("TEE",$H9)),"TEE",""))),""))))) -> PIPE | AE9: =IF(AND($G9="FITTING",LEFT($H9,5)="ELBOW"),IFERROR(VALUE(LEFT(MID($H9,7,12),MIN(IFERROR(FIND("L",MID($H9,7,12)),99),IFERROR(FIND("S",MID($H9,7,12)),99),IFERROR(FIND(" ",MID($H9,7,12)),99))-1)),""),"") | AF9: =IF($AD9="비규격EL",N($L9)*RADIANS(N($AE9))*보온기준!$F$15*N($I9)*보온기준!$F$16/1000,0) -> 0 | AG9: =IF($G9="","",IF(OR($AA9<>"○",LEFT($F9,3)="STS",LEFT($F9,3)="SUS",$C9="매설"),"Y","N")) -> Y
A10: 4 | B10: 설치 | C10: 옥외 | D10: WATER | E10: 5kg/cm2이상 | F10: STPG370S | G10: PIPE | H10: PIPE | I10: 150 | J10: SCH40 | K10: M | L10: 20.701 | M10: =IF($G10<>"PIPE","",IFERROR(1/(1/INDEX(배관단중표!$B$7:$W$41,MATCH($I10,배관단중표!$A$7:$A$41,0),MATCH(IF($J10="SPP","SPP",IF(LEFT($F10,3)="STS",IF(ISNUMBER(SEARCH("316",$F10)),"STS316","STS304"),"SPPS")&"|"&$J10),배관단중표!$B$6:$W$6,0))),"DB확인")) -> 27.7 | P10: =IF($G10="","",IFERROR(IF(O10<>"",O10,L10*IF(G10="PIPE",M10,N10)),0)) -> 573.4177 | Q10: =IF($G10="","",IF(G10="PIPE","P","F")) -> P | R10: =IF($G10<>"PIPE","",IFERROR(IF(O10<>"",O10/M10,IF(K10="M",L10,"")),"")) -> 20.701 | S10: =IF($G10<>"PIPE","",IF(AND($AA10="○",OR($W10<>"○",배관기준!$AG$17="N"),$C10<>"매설",LEFT($F10,3)<>"STS",LEFT($F10,3)<>"SUS"),"Y","N")) -> N | U10: STPG370S | W10: =IF($G10="","",IFERROR(INDEX(배관집계!$AC$7:$AC$32,MATCH($AC10,배관집계!$AJ$7:$AJ$32,0))&"","")) -> ○ | X10: =IF($G10="","",IFERROR(INDEX(배관집계!$AD$7:$AD$32,MATCH($AC10,배관집계!$AJ$7:$AJ$32,0))&"","")) -> ○ | Y10: =IF($G10="","",IFERROR(INDEX(배관집계!$AE$7:$AE$32,MATCH($AC10,배관집계!$AJ$7:$AJ$32,0))&"","")) -> × | Z10: =IF($G10="","",IFERROR(INDEX(배관집계!$AF$7:$AF$32,MATCH($AC10,배관집계!$AJ$7:$AJ$32,0))&"","")) -> ○ | AA10: =IF($G10="","",IFERROR(INDEX(배관집계!$AG$7:$AG$32,MATCH($AC10,배관집계!$AJ$7:$AJ$32,0))&"","")) -> × | AB10: =IF($G10="","",IFERROR(INDEX(배관집계!$AH$7:$AH$32,MATCH($AC10,배관집계!$AJ$7:$AJ$32,0))&"","")) -> C/C | AC10: =IF($G10="","",$B10&"|"&$C10&"|"&$E10&"|"&$U10&"|"&$I10) -> 설치|옥외|5kg/cm2이상|STPG370S|150 | AD10: =IF($G10="","",IF($B10<>"설치","",IF($G10="PIPE","PIPE",IF($G10="VALVE",IF(ISNUMBER(SEARCH("GLOBE",$H10)),"GLOBE",IF(ISNUMBER(SEARCH("GATE",$H10)),"GATE",IF(ISNUMBER(SEARCH("BUTTER",$H10)),"BFLY","VALVE기타"))),IF($G10="FITTING",IF(LEFT($H10,5)="ELBOW",IF($AE10=90,"90EL",IF($AE10=45,"45EL","비규격EL")),IF(LEFT($H10,6)="FLANGE","FLANGE",IF(ISNUMBER(SEARCH("TEE",$H10)),"TEE",""))),""))))) -> PIPE | AE10: =IF(AND($G10="FITTING",LEFT($H10,5)="ELBOW"),IFERROR(VALUE(LEFT(MID($H10,7,12),MIN(IFERROR(FIND("L",MID($H10,7,12)),99),IFERROR(FIND("S",MID($H10,7,12)),99),IFERROR(FIND(" ",MID($H10,7,12)),99))-1)),""),"") | AF10: =IF($AD10="비규격EL",N($L10)*RADIANS(N($AE10))*보온기준!$F$15*N($I10)*보온기준!$F$16/1000,0) -> 0 | AG10: =IF($G10="","",IF(OR($AA10<>"○",LEFT($F10,3)="STS",LEFT($F10,3)="SUS",$C10="매설"),"Y","N")) -> Y
A11: 5 | B11: 설치 | C11: 옥외 | D11: WATER | E11: 5kg/cm2이상 | F11: STPG370S | G11: PIPE | H11: PIPE | I11: 200 | J11: SCH40 | K11: M | L11: 9.1142 | M11: =IF($G11<>"PIPE","",IFERROR(1/(1/INDEX(배관단중표!$B$7:$W$41,MATCH($I11,배관단중표!$A$7:$A$41,0),MATCH(IF($J11="SPP","SPP",IF(LEFT($F11,3)="STS",IF(ISNUMBER(SEARCH("316",$F11)),"STS316","STS304"),"SPPS")&"|"&$J11),배관단중표!$B$6:$W$6,0))),"DB확인")) -> 42.1 | P11: =IF($G11="","",IFERROR(IF(O11<>"",O11,L11*IF(G11="PIPE",M11,N11)),0)) -> 383.70782 | Q11: =IF($G11="","",IF(G11="PIPE","P","F")) -> P | R11: =IF($G11<>"PIPE","",IFERROR(IF(O11<>"",O11/M11,IF(K11="M",L11,"")),"")) -> 9.1142 | S11: =IF($G11<>"PIPE","",IF(AND($AA11="○",OR($W11<>"○",배관기준!$AG$17="N"),$C11<>"매설",LEFT($F11,3)<>"STS",LEFT($F11,3)<>"SUS"),"Y","N")) -> N | U11: STPG370S | W11: =IF($G11="","",IFERROR(INDEX(배관집계!$AC$7:$AC$32,MATCH($AC11,배관집계!$AJ$7:$AJ$32,0))&"","")) -> ○ | X11: =IF($G11="","",IFERROR(INDEX(배관집계!$AD$7:$AD$32,MATCH($AC11,배관집계!$AJ$7:$AJ$32,0))&"","")) -> ○ | Y11: =IF($G11="","",IFERROR(INDEX(배관집계!$AE$7:$AE$32,MATCH($AC11,배관집계!$AJ$7:$AJ$32,0))&"","")) -> × | Z11: =IF($G11="","",IFERROR(INDEX(배관집계!$AF$7:$AF$32,MATCH($AC11,배관집계!$AJ$7:$AJ$32,0))&"","")) -> ○ | AA11: =IF($G11="","",IFERROR(INDEX(배관집계!$AG$7:$AG$32,MATCH($AC11,배관집계!$AJ$7:$AJ$32,0))&"","")) -> × | AB11: =IF($G11="","",IFERROR(INDEX(배관집계!$AH$7:$AH$32,MATCH($AC11,배관집계!$AJ$7:$AJ$32,0))&"","")) -> C/C | AC11: =IF($G11="","",$B11&"|"&$C11&"|"&$E11&"|"&$U11&"|"&$I11) -> 설치|옥외|5kg/cm2이상|STPG370S|200 | AD11: =IF($G11="","",IF($B11<>"설치","",IF($G11="PIPE","PIPE",IF($G11="VALVE",IF(ISNUMBER(SEARCH("GLOBE",$H11)),"GLOBE",IF(ISNUMBER(SEARCH("GATE",$H11)),"GATE",IF(ISNUMBER(SEARCH("BUTTER",$H11)),"BFLY","VALVE기타"))),IF($G11="FITTING",IF(LEFT($H11,5)="ELBOW",IF($AE11=90,"90EL",IF($AE11=45,"45EL","비규격EL")),IF(LEFT($H11,6)="FLANGE","FLANGE",IF(ISNUMBER(SEARCH("TEE",$H11)),"TEE",""))),""))))) -> PIPE | AE11: =IF(AND($G11="FITTING",LEFT($H11,5)="ELBOW"),IFERROR(VALUE(LEFT(MID($H11,7,12),MIN(IFERROR(FIND("L",MID($H11,7,12)),99),IFERROR(FIND("S",MID($H11,7,12)),99),IFERROR(FIND(" ",MID($H11,7,12)),99))-1)),""),"") | AF11: =IF($AD11="비규격EL",N($L11)*RADIANS(N($AE11))*보온기준!$F$15*N($I11)*보온기준!$F$16/1000,0) -> 0 | AG11: =IF($G11="","",IF(OR($AA11<>"○",LEFT($F11,3)="STS",LEFT($F11,3)="SUS",$C11="매설"),"Y","N")) -> Y
A12: 6 | B12: 설치 | C12: 옥외 | D12: WATER | E12: 5kg/cm2이상 | F12: STPG370S | G12: PIPE | H12: PIPE | I12: 250 | J12: SCH40 | K12: M | L12: 8.666 | M12: =IF($G12<>"PIPE","",IFERROR(1/(1/INDEX(배관단중표!$B$7:$W$41,MATCH($I12,배관단중표!$A$7:$A$41,0),MATCH(IF($J12="SPP","SPP",IF(LEFT($F12,3)="STS",IF(ISNUMBER(SEARCH("316",$F12)),"STS316","STS304"),"SPPS")&"|"&$J12),배관단중표!$B$6:$W$6,0))),"DB확인")) -> 59.2 | P12: =IF($G12="","",IFERROR(IF(O12<>"",O12,L12*IF(G12="PIPE",M12,N12)),0)) -> 513.0272 | Q12: =IF($G12="","",IF(G12="PIPE","P","F")) -> P | R12: =IF($G12<>"PIPE","",IFERROR(IF(O12<>"",O12/M12,IF(K12="M",L12,"")),"")) -> 8.666 | S12: =IF($G12<>"PIPE","",IF(AND($AA12="○",OR($W12<>"○",배관기준!$AG$17="N"),$C12<>"매설",LEFT($F12,3)<>"STS",LEFT($F12,3)<>"SUS"),"Y","N")) -> N | U12: STPG370S | W12: =IF($G12="","",IFERROR(INDEX(배관집계!$AC$7:$AC$32,MATCH($AC12,배관집계!$AJ$7:$AJ$32,0))&"","")) -> ○ | X12: =IF($G12="","",IFERROR(INDEX(배관집계!$AD$7:$AD$32,MATCH($AC12,배관집계!$AJ$7:$AJ$32,0))&"","")) -> ○ | Y12: =IF($G12="","",IFERROR(INDEX(배관집계!$AE$7:$AE$32,MATCH($AC12,배관집계!$AJ$7:$AJ$32,0))&"","")) -> × | Z12: =IF($G12="","",IFERROR(INDEX(배관집계!$AF$7:$AF$32,MATCH($AC12,배관집계!$AJ$7:$AJ$32,0))&"","")) -> ○ | AA12: =IF($G12="","",IFERROR(INDEX(배관집계!$AG$7:$AG$32,MATCH($AC12,배관집계!$AJ$7:$AJ$32,0))&"","")) -> × | AB12: =IF($G12="","",IFERROR(INDEX(배관집계!$AH$7:$AH$32,MATCH($AC12,배관집계!$AJ$7:$AJ$32,0))&"","")) -> C/C | AC12: =IF($G12="","",$B12&"|"&$C12&"|"&$E12&"|"&$U12&"|"&$I12) -> 설치|옥외|5kg/cm2이상|STPG370S|250 | AD12: =IF($G12="","",IF($B12<>"설치","",IF($G12="PIPE","PIPE",IF($G12="VALVE",IF(ISNUMBER(SEARCH("GLOBE",$H12)),"GLOBE",IF(ISNUMBER(SEARCH("GATE",$H12)),"GATE",IF(ISNUMBER(SEARCH("BUTTER",$H12)),"BFLY","VALVE기타"))),IF($G12="FITTING",IF(LEFT($H12,5)="ELBOW",IF($AE12=90,"90EL",IF($AE12=45,"45EL","비규격EL")),IF(LEFT($H12,6)="FLANGE","FLANGE",IF(ISNUMBER(SEARCH("TEE",$H12)),"TEE",""))),""))))) -> PIPE | AE12: =IF(AND($G12="FITTING",LEFT($H12,5)="ELBOW"),IFERROR(VALUE(LEFT(MID($H12,7,12),MIN(IFERROR(FIND("L",MID($H12,7,12)),99),IFERROR(FIND("S",MID($H12,7,12)),99),IFERROR(FIND(" ",MID($H12,7,12)),99))-1)),""),"") | AF12: =IF($AD12="비규격EL",N($L12)*RADIANS(N($AE12))*보온기준!$F$15*N($I12)*보온기준!$F$16/1000,0) -> 0 | AG12: =IF($G12="","",IF(OR($AA12<>"○",LEFT($F12,3)="STS",LEFT($F12,3)="SUS",$C12="매설"),"Y","N")) -> Y
